Workbook
Name kappaP1: 'M7_24 Gurobi Solution'!$B$44
Name kappaP1: 'M7_24 Gams Solution '!$B$44
Name kappaP2: 'M7_24 Gurobi Solution'!$B$45
Name kappaP2: 'M7_24 Gams Solution '!$B$45
Name kappaP3: 'M7_24 Gurobi Solution'!$B$46
Name kappaP3: 'M7_24 Gams Solution '!$B$46
Name kappaP4: 'M7_24 Gurobi Solution'!$B$47
Name kappaP4: 'M7_24 Gams Solution '!$B$47
Name kappaP5: 'M7_24 Gurobi Solution'!$B$48
Name kappaP5: 'M7_24 Gams Solution '!$B$48
Name kappaP6: 'M7_24 Gurobi Solution'!$B$49
Name kappaP6: 'M7_24 Gams Solution '!$B$49

Sheet M7_24 Gurobi Solution
AC11: I1_Profit =e= EP1+E1+IndustryProfitnoCDS_BESS_PV1;
AC12: I1_Profit | AD12: =AB19+AD19+AG19 -> 92808.661
AC13: I2_Profit | AD13: =AC19+AE19+AH19 -> 132701.97
AC14: I1+I2_Profit | AD14: =AD13+AD12 -> 225510.63 | AE14: =[1]IndustryProfit!$A$2 -> 225455.32 | AF14: =AE14-AD14 -> -55.303834
B15: Violación? | E15: =E16-E17 -> 261.94485 | F15: =F16-F17 -> 241.4426 | G15: =G16-G17 -> 0 | H15: =H16-H17 -> 0 | I15: =I16-I17 -> 0 | J15: =J16-J17 -> 0 | K15: =K16-K17 -> 13.319463 | L15: =L16-L17 -> 0 | AC15: VPN | AD15: =AD14/B53-B61-B62 -> 792860.88 | AE15: =[1]npv!$A$2 -> 792171.67 | AF15: =AE15-AD15 -> -689.20801
D16: LIM | E16: =B30 -> 600 | F16: =E16 -> 600 | G16: =B59 -> 400 | H16: =G16 -> 400 | I16: =B41 -> 650 | J16: =I16 -> 650 | K16: =B60 -> 840 | L16: =K16 -> 840 | X16: =B56 -> 400 | Y16: =X16 -> 400
D17: MAX | E17: =MAX(E21:E44) -> 338.05515 | F17: =MAX(F21:F44) -> 358.5574 | G17: =MAX(G21:G44) -> 400 | H17: =MAX(H21:H44) -> 400 | I17: =MAX(I21:I44) -> 650 | J17: =MAX(J21:J44) -> 650 | K17: =MAX(K21:K44) -> 826.68054 | L17: =MAX(L21:L44) -> 840 | X17: =MAX(X21:X44) -> 103.7963 | Y17: =MAX(Y21:Y44) -> 90.705259 | AB17: =AB18-AB19 -> -4.1472958e-09 | AC17: =AC18-AC19 -> -55.303834 | AD17: =AD18-AD19 -> -22.760235 | AE17: =AE18-AE19 -> 22.760235 | AF17: =AF18-AF19 -> 0 | AG17: =AG18-AG19 -> 0 | AH17: =AH18-AH19 -> 0
E18: =[1]Wimport1!$A$2 -> 550369.21 | P18: =SUM(P21:P44) -> 8.0433438e-12 | R18: =SUM(R21:R44) -> 2.6005864e-11 | Z18: =SUM(Z21:Z44) -> 3.5349501e-13 | AA18: =SUM(AA21:AA44) -> -4.1087134e-12 | AB18: =[1]Benefit1!$A$2 -> -27251.643 | AC18: =[1]Benefit2!$A$2 -> -50874.331 | AD18: =[1]E1!$A$2 -> 5935.8951 | AE18: =[1]E2!$A$2 -> -6748.9913 | AF18: =[1]APA!$A$2 -> 813.09623 | AG18: =[1]IndustryProfitnoCDS_BESS_PV1!$A$2 -> 114101.65 | AH18: =[1]IndustryProfitnoCDS_BESS_PV2!$A$2 -> 190292.74
D19: sum | E19: =SUM(E21:E44) -> 1507.8608 | F19: =SUM(F21:F44) -> 1054.2355 | G19: =SUM(G21:G44) -> 1935.4839 | H19: =SUM(H21:H44) -> 1746 | I19: =SUM(I21:I44) -> 3488.398 | J19: =SUM(J21:J44) -> 1950 | K19: =SUM(K21:K44) -> 3071.6997 | L19: =SUM(L21:L44) -> 2684.6656 | X19: =SUM(X21:X44) -> 354.82692 | Y19: =SUM(Y21:Y44) -> 90.705259 | AB19: =SUM(AB21:AB44)*365-B63 -> -27251.643 | AC19: =SUM(AC21:AC44)*365-B64 -> -50819.027 | AD19: =SUM(AD21:AD44)*365-D63 -> 5958.6553 | AE19: =SUM(AE21:AE44)*365-D64 -> -6771.7516 | AF19: =365*SUM(AF21:AF44)+2*$B$65 -> 813.09623 | AG19: =365*SUM(AG21:AG44)-B31 -> 114101.65 | AH19: =365*SUM(AH21:AH44)-B42 -> 190292.74
E20: Pb1 | F20: Ps1 | G20: Pc1 | H20: Pd1 | I20: Pb2 | J20: Ps2 | K20: Pc2 | L20: Pd2 | M20: SOC1 | N20: SOC2 | U20: epsilon | X20: P12CDS | Y20: P21CDS | Z20: BALANCES | AB20: Benefit1 | AC20: Benefit2 | AD20: E1 | AE20: E2 | AF20: APA | AG20: BASE1 | AH20: BASE2 | AI20: lambda | AJ20: pbmax1 | AK20: pbmax2 | AL20: Plu1 | AM20: Plu2 | AN20: Ppvu | AO20: psi
A21: Ppvmax1 / 569/ | B21: =[1]Ppvmax1!$A$1 -> 569 | D21: 1 | E21: =[2]solution!B2 -> 31.307452 | F21: =[2]solution!C2 -> 0 | G21: =[2]solution!D2 -> 0 | H21: =[2]solution!E2 -> 0 | I21: =[2]solution!F2 -> 165.79382 | J21: =[2]solution!G2 -> 0 | K21: =[2]solution!H2 -> 0 | L21: =[2]solution!I2 -> 0 | ... N21: =[2]solution!K2 -> 140 | O21: =B23+G21*$B$25-H21/$B$26 -> 100 | P21: =O21-M21 -> 0 | Q21: =B34+K21*$B$36-L21/$B$37 -> 140 | R21: =Q21-N21 -> 0 | S21: =U21-T21 -> 0 | T21: =AI21 -> 0.068746795 | U21: =[2]solution!L2 -> 0.068746795 | V21: =T21+AO21 -> 0.0915673 | W21: =V21-U21 -> 0.022820505 | X21: =[2]solution!M2 -> 0 | Y21: =[2]solution!N2 -> 0 | Z21: =H21+E21+$B$21*AN21-G21-F21-$B$22*AL21+Y21-X21 -> -1.0658141e-14 | AA21: =L21+I21+$B$32*AN21-K21-J21-$B$33*AM21-Y21+X21 -> -4.8316906e-13 | AB21: =F21*AI21-(AI21+AO21)*E21 -> -2.8667388 | AC21: =J21*AI21-(AI21+AO21)*I21 -> -15.181292 | AD21: =(U21-$B$55)*X21-(U21+$B$54)*Y21 -> 0 | AE21: =(U21-$B$55)*Y21-(U21+$B$54)*X21 -> 0 | AF21: =($B$54+$B$55)*(X21+Y21) -> 0 | AG21: =$B$22*AL21*(AI21+AO21) -> 2.8667388 | AH21: =$B$33*AM21*(AI21+AO21) -> 15.181292 | AI21: =[1]data!C1 -> 0.068746795 | AJ21: =[1]data!C25 -> 564.3 | AK21: =[1]data!C49 -> 553.8896 | AL21: =[1]data!C73 -> 0.13538863 | AM21: =[1]data!C97 -> 0.53006129 | AO21: =[1]data!C133 -> 0.022820505 | AP21: P6 | AQ21: =kappaP6*AJ21 -> 516.94959 | AR21: =kappaP6*AK21 -> 507.41272
A22: Plmax1 / 231.241369863014 / | B22: =[1]Plmax1!$A$1 -> 231.24137 | D22: 2 | E22: =[2]solution!B3 -> 20.898959 | F22: =[2]solution!C3 -> 0 | G22: =[2]solution!D3 -> 0 | H22: =[2]solution!E3 -> 0 | I22: =[2]solution!F3 -> 166.29426 | J22: =[2]solution!G3 -> 0 | K22: =[2]solution!H3 -> 0 | L22: =[2]solution!I3 -> 0 | ... N22: =[2]solution!K3 -> 140 | O22: =O21+G22*$B$25-H22/$B$26 -> 100 | P22: =O22-M22 -> 0 | Q22: =Q21+K22*$B$36-L22/$B$37 -> 140 | R22: =Q22-N22 -> 0 | S22: =U22-T22 -> 0 | T22: =AI22 -> 0.064382932 | U22: =[2]solution!L3 -> 0.064382932 | V22: =T22+AO22 -> 0.087203437 | W22: =V22-U22 -> 0.022820505 | X22: =[2]solution!M3 -> 0 | Y22: =[2]solution!N3 -> 0 | Z22: =H22+E22+$B$21*AN22-G22-F22-$B$22*AL22+Y22-X22 -> -7.8159701e-14 | AA22: =L22+I22+$B$32*AN22-K22-J22-$B$33*AM22-Y22+X22 -> -3.6948222e-13 | AB22: =F22*AI22-(AI22+AO22)*E22 -> -1.822461 | AC22: =J22*AI22-(AI22+AO22)*I22 -> -14.501431 | AD22: =(U22-$B$55)*X22-(U22+$B$54)*Y22 -> 0 | AE22: =(U22-$B$55)*Y22-(U22+$B$54)*X22 -> 0 | AF22: =($B$54+$B$55)*(X22+Y22) -> 0 | AG22: =$B$22*AL22*(AI22+AO22) -> 1.822461 | AH22: =$B$33*AM22*(AI22+AO22) -> 14.501431 | AI22: =[1]data!C2 -> 0.064382932 | AJ22: =[1]data!C26 -> 564.3 | AK22: =[1]data!C50 -> 553.8896 | AL22: =[1]data!C74 -> 0.090377249 | AM22: =[1]data!C98 -> 0.53166123 | AO22: =[1]data!C134 -> 0.022820505 | AP22: P6
A23: SOC01 / 100 / | B23: =[1]SOC01!$A$1 -> 100 | D23: 3 | E23: =[2]solution!B4 -> 17.653808 | F23: =[2]solution!C4 -> 0 | G23: =[2]solution!D4 -> 0 | H23: =[2]solution!E4 -> 0 | I23: =[2]solution!F4 -> 167.08084 | J23: =[2]solution!G4 -> 0 | K23: =[2]solution!H4 -> 0 | L23: =[2]solution!I4 -> 0 | ... N23: =[2]solution!K4 -> 140 | O23: =O22+G23*$B$25-H23/$B$26 -> 100 | P23: =O23-M23 -> 0 | Q23: =Q22+K23*$B$36-L23/$B$37 -> 140 | R23: =Q23-N23 -> 0 | S23: =U23-T23 -> 0 | T23: =AI23 -> 0.062238411 | U23: =[2]solution!L4 -> 0.062238411 | V23: =T23+AO23 -> 0.085058916 | W23: =V23-U23 -> 0.022820505 | X23: =[2]solution!M4 -> 0 | Y23: =[2]solution!N4 -> 0 | Z23: =H23+E23+$B$21*AN23-G23-F23-$B$22*AL23+Y23-X23 -> -3.5527137e-15 | AA23: =L23+I23+$B$32*AN23-K23-J23-$B$33*AM23-Y23+X23 -> -3.4106051e-13 | AB23: =F23*AI23-(AI23+AO23)*E23 -> -1.5016138 | AC23: =J23*AI23-(AI23+AO23)*I23 -> -14.211715 | AD23: =(U23-$B$55)*X23-(U23+$B$54)*Y23 -> 0 | AE23: =(U23-$B$55)*Y23-(U23+$B$54)*X23 -> 0 | AF23: =($B$54+$B$55)*(X23+Y23) -> 0 | AG23: =$B$22*AL23*(AI23+AO23) -> 1.5016138 | AH23: =$B$33*AM23*(AI23+AO23) -> 14.211715 | AI23: =[1]data!C3 -> 0.062238411 | AJ23: =[1]data!C27 -> 564.3 | AK23: =[1]data!C51 -> 553.8896 | AL23: =[1]data!C75 -> 0.076343641 | AM23: =[1]data!C99 -> 0.53417603 | AO23: =[1]data!C135 -> 0.022820505 | AP23: P6
A24: C1 / 2000 / | B24: =[1]C1!$A$1 -> 2000 | D24: 4 | E24: =[2]solution!B5 -> 17.394959 | F24: =[2]solution!C5 -> 0 | G24: =[2]solution!D5 -> 0 | H24: =[2]solution!E5 -> 0 | I24: =[2]solution!F5 -> 505.64267 | J24: =[2]solution!G5 -> 0 | K24: =[2]solution!H5 -> 332.56931 | L24: =[2]solution!I5 -> 0 | ... N24: =[2]solution!K5 -> 445.96377 | O24: =O23+G24*$B$25-H24/$B$26 -> 100 | P24: =O24-M24 -> 0 | Q24: =Q23+K24*$B$36-L24/$B$37 -> 445.96377 | R24: =Q24-N24 -> 4.5474735e-13 | S24: =U24-T24 -> 0 | T24: =AI24 -> 0.060464137 | U24: =[2]solution!L5 -> 0.060464137 | V24: =T24+AO24 -> 0.083284642 | W24: =V24-U24 -> 0.022820505 | X24: =[2]solution!M5 -> 0 | Y24: =[2]solution!N5 -> 0 | Z24: =H24+E24+$B$21*AN24-G24-F24-$B$22*AL24+Y24-X24 -> -6.750156e-14 | AA24: =L24+I24+$B$32*AN24-K24-J24-$B$33*AM24-Y24+X24 -> -4.5474735e-13 | AB24: =F24*AI24-(AI24+AO24)*E24 -> -1.4487329 | AC24: =J24*AI24-(AI24+AO24)*I24 -> -42.112269 | AD24: =(U24-$B$55)*X24-(U24+$B$54)*Y24 -> 0 | AE24: =(U24-$B$55)*Y24-(U24+$B$54)*X24 -> 0 | AF24: =($B$54+$B$55)*(X24+Y24) -> 0 | AG24: =$B$22*AL24*(AI24+AO24) -> 1.4487329 | AH24: =$B$33*AM24*(AI24+AO24) -> 14.414353 | AI24: =[1]data!C4 -> 0.060464137 | AJ24: =[1]data!C28 -> 564.3 | AK24: =[1]data!C52 -> 553.8896 | AL24: =[1]data!C76 -> 0.075224251 | AM24: =[1]data!C100 -> 0.55333478 | AO24: =[1]data!C136 -> 0.022820505 | AP24: P6
A25: eff_c1 / 0.93 / | B25: =[1]eff_c1!$A$1 -> 0.93 | D25: 5 | E25: =[2]solution!B6 -> 17.182986 | F25: =[2]solution!C6 -> 0 | G25: =[2]solution!D6 -> 0 | H25: =[2]solution!E6 -> 0 | I25: =[2]solution!F6 -> 193.604 | J25: =[2]solution!G6 -> 0 | K25: =[2]solution!H6 -> 0 | L25: =[2]solution!I6 -> 0 | ... N25: =[2]solution!K6 -> 445.96377 | O25: =O24+G25*$B$25-H25/$B$26 -> 100 | P25: =O25-M25 -> 0 | Q25: =Q24+K25*$B$36-L25/$B$37 -> 445.96377 | R25: =Q25-N25 -> 4.5474735e-13 | S25: =U25-T25 -> 0 | T25: =AI25 -> 0.060655534 | U25: =[2]solution!L6 -> 0.060655534 | V25: =T25+AO25 -> 0.08347604 | W25: =V25-U25 -> 0.022820505 | X25: =[2]solution!M6 -> 0 | Y25: =[2]solution!N6 -> 0 | Z25: =H25+E25+$B$21*AN25-G25-F25-$B$22*AL25+Y25-X25 -> -7.8159701e-14 | AA25: =L25+I25+$B$32*AN25-K25-J25-$B$33*AM25-Y25+X25 -> -3.126388e-13 | AB25: =F25*AI25-(AI25+AO25)*E25 -> -1.4343676 | AC25: =J25*AI25-(AI25+AO25)*I25 -> -16.161295 | AD25: =(U25-$B$55)*X25-(U25+$B$54)*Y25 -> 0 | AE25: =(U25-$B$55)*Y25-(U25+$B$54)*X25 -> 0 | AF25: =($B$54+$B$55)*(X25+Y25) -> 0 | AG25: =$B$22*AL25*(AI25+AO25) -> 1.4343676 | AH25: =$B$33*AM25*(AI25+AO25) -> 16.161295 | AI25: =[1]data!C5 -> 0.060655534 | AJ25: =[1]data!C29 -> 564.3 | AK25: =[1]data!C53 -> 553.8896 | AL25: =[1]data!C77 -> 0.074307579 | AM25: =[1]data!C101 -> 0.61897352 | AO25: =[1]data!C137 -> 0.022820505 | AP25: P6
A26: eff_d1 / 0.97 / | B26: =[1]eff_d1!$A$1 -> 0.97 | D26: 6 | E26: =[2]solution!B7 -> 16.905041 | F26: =[2]solution!C7 -> 0 | G26: =[2]solution!D7 -> 0 | H26: =[2]solution!E7 -> 0 | I26: =[2]solution!F7 -> 229.17505 | J26: =[2]solution!G7 -> 0 | K26: =[2]solution!H7 -> 0 | L26: =[2]solution!I7 -> 0 | ... N26: =[2]solution!K7 -> 445.96377 | O26: =O25+G26*$B$25-H26/$B$26 -> 100 | P26: =O26-M26 -> 0 | Q26: =Q25+K26*$B$36-L26/$B$37 -> 445.96377 | R26: =Q26-N26 -> 4.5474735e-13 | S26: =U26-T26 -> 0 | T26: =AI26 -> 0.065132137 | U26: =[2]solution!L7 -> 0.065132137 | V26: =T26+AO26 -> 0.087952642 | W26: =V26-U26 -> 0.022820505 | X26: =[2]solution!M7 -> 0 | Y26: =[2]solution!N7 -> 0 | Z26: =H26+E26+$B$21*AN26-G26-F26-$B$22*AL26+Y26-X26 -> -5.6843419e-14 | AA26: =L26+I26+$B$32*AN26-K26-J26-$B$33*AM26-Y26+X26 -> -6.8212103e-13 | AB26: =F26*AI26-(AI26+AO26)*E26 -> -1.486843 | AC26: =J26*AI26-(AI26+AO26)*I26 -> -20.156552 | AD26: =(U26-$B$55)*X26-(U26+$B$54)*Y26 -> 0 | AE26: =(U26-$B$55)*Y26-(U26+$B$54)*X26 -> 0 | AF26: =($B$54+$B$55)*(X26+Y26) -> 0 | AG26: =$B$22*AL26*(AI26+AO26) -> 1.486843 | AH26: =$B$33*AM26*(AI26+AO26) -> 20.156552 | AI26: =[1]data!C6 -> 0.065132137 | AJ26: =[1]data!C30 -> 564.3 | AK26: =[1]data!C54 -> 553.8896 | AL26: =[1]data!C78 -> 0.073105609 | AM26: =[1]data!C102 -> 0.73269814 | AO26: =[1]data!C138 -> 0.022820505 | AP26: P6
A27: R_c1 / 0.2/ | B27: =[1]R_c1!$A$1 -> 0.2 | D27: 7 | E27: =[2]solution!B8 -> 0 | F27: =[2]solution!C8 -> 0 | G27: =[2]solution!D8 -> 0 | H27: =[2]solution!E8 -> 0 | I27: =[2]solution!F8 -> 0 | J27: =[2]solution!G8 -> 0 | K27: =[2]solution!H8 -> 0 | L27: =[2]solution!I8 -> 235.15339 | ... N27: =[2]solution!K8 -> 198.43388 | O27: =O26+G27*$B$25-H27/$B$26 -> 100 | P27: =O27-M27 -> 0 | Q27: =Q26+K27*$B$36-L27/$B$37 -> 198.43388 | R27: =Q27-N27 -> 1.1084467e-12 | S27: =U27-T27 -> 0 | T27: =AI27 -> 0.073826082 | U27: =[2]solution!L8 -> 0.073826082 | V27: =T27+AO27 -> 0.096646587 | W27: =V27-U27 -> 0.022820505 | X27: =[2]solution!M8 -> 10.048827 | Y27: =[2]solution!N8 -> 0 | Z27: =H27+E27+$B$21*AN27-G27-F27-$B$22*AL27+Y27-X27 -> 6.2172489e-14 | AA27: =L27+I27+$B$32*AN27-K27-J27-$B$33*AM27-Y27+X27 -> -7.8337337e-13 | AB27: =F27*AI27-(AI27+AO27)*E27 -> 0 | AC27: =J27*AI27-(AI27+AO27)*I27 -> 0 | AD27: =(U27-$B$55)*X27-(U27+$B$54)*Y27 -> 0.72930448 | AE27: =(U27-$B$55)*Y27-(U27+$B$54)*X27 -> -0.77954861 | AF27: =($B$54+$B$55)*(X27+Y27) -> 0.050244134 | AG27: =$B$22*AL27*(AI27+AO27) -> 1.6405321 | AH27: =$B$33*AM27*(AI27+AO27) -> 27.369967 | AI27: =[1]data!C7 -> 0.073826082 | AJ27: =[1]data!C31 -> 564.3 | AK27: =[1]data!C55 -> 553.8896 | AL27: =[1]data!C79 -> 0.07340619 | AM27: =[1]data!C103 -> 0.90541045 | AN27: =[1]data!C121 -> 0.04749275 | AO27: =[1]data!C139 -> 0.022820505 | AP27: P6
A28: R_d1 / 0.2/ | B28: =[1]R_d1!$A$1 -> 0.2 | D28: 8 | E28: =[2]solution!B9 -> 0 | F28: =[2]solution!C9 -> 0 | G28: =[2]solution!D9 -> 0 | H28: =[2]solution!E9 -> 0 | I28: =[2]solution!F9 -> 0 | J28: =[2]solution!G9 -> 0 | K28: =[2]solution!H9 -> 0 | L28: =[2]solution!I9 -> 55.512187 | ... N28: =[2]solution!K9 -> 140 | O28: =O27+G28*$B$25-H28/$B$26 -> 100 | P28: =O28-M28 -> 0 | Q28: =Q27+K28*$B$36-L28/$B$37 -> 140 | R28: =Q28-N28 -> 6.8212103e-13 | S28: =U28-T28 -> 0 | T28: =AI28 -> 0.076148795 | U28: =[2]solution!L9 -> 0.076148795 | V28: =T28+AO28 -> 0.0989693 | W28: =V28-U28 -> 0.022820505 | X28: =[2]solution!M9 -> 94.044604 | Y28: =[2]solution!N9 -> 0 | Z28: =H28+E28+$B$21*AN28-G28-F28-$B$22*AL28+Y28-X28 -> 0 | AA28: =L28+I28+$B$32*AN28-K28-J28-$B$33*AM28-Y28+X28 -> 0 | AB28: =F28*AI28-(AI28+AO28)*E28 -> 0 | AC28: =J28*AI28-(AI28+AO28)*I28 -> 0 | AD28: =(U28-$B$55)*X28-(U28+$B$54)*Y28 -> 7.0438275 | AE28: =(U28-$B$55)*Y28-(U28+$B$54)*X28 -> -7.5140505 | AF28: =($B$54+$B$55)*(X28+Y28) -> 0.47022302 | AG28: =$B$22*AL28*(AI28+AO28) -> 1.9571111 | AH28: =$B$33*AM28*(AI28+AO28) -> 30.639337 | AI28: =[1]data!C8 -> 0.076148795 | AJ28: =[1]data!C32 -> 564.3 | AK28: =[1]data!C56 -> 553.8896 | AL28: =[1]data!C80 -> 0.085516409 | AM28: =[1]data!C104 -> 0.98977531 | AN28: =[1]data!C122 -> 0.20003433 | AO28: =[1]data!C140 -> 0.022820505 | AP28: P6
A29: DoD1 / 0.9/ | B29: =[1]DoD1!$A$1 -> 0.9 | D29: 9 | E29: =[2]solution!B10 -> 0 | F29: =[2]solution!C10 -> 0 | G29: =[2]solution!D10 -> 0 | H29: =[2]solution!E10 -> 0 | I29: =[2]solution!F10 -> 7.9322603 | J29: =[2]solution!G10 -> 0 | K29: =[2]solution!H10 -> 0 | L29: =[2]solution!I10 -> 0 | ... N29: =[2]solution!K10 -> 140 | O29: =O28+G29*$B$25-H29/$B$26 -> 100 | P29: =O29-M29 -> 0 | Q29: =Q28+K29*$B$36-L29/$B$37 -> 140 | R29: =Q29-N29 -> 6.8212103e-13 | S29: =U29-T29 -> 0 | T29: =AI29 -> 0.069382712 | U29: =[2]solution!L10 -> 0.069382712 | V29: =T29+AO29 -> 0.090457084 | W29: =V29-U29 -> 0.021074371 | X29: =[2]solution!M10 -> 7.2957662 | Y29: =[2]solution!N10 -> 0 | Z29: =H29+E29+$B$21*AN29-G29-F29-$B$22*AL29+Y29-X29 -> 0 | AA29: =L29+I29+$B$32*AN29-K29-J29-$B$33*AM29-Y29+X29 -> 0 | AB29: =F29*AI29-(AI29+AO29)*E29 -> 0 | AC29: =J29*AI29-(AI29+AO29)*I29 -> -0.71752913 | AD29: =(U29-$B$55)*X29-(U29+$B$54)*Y29 -> 0.49708034 | AE29: =(U29-$B$55)*Y29-(U29+$B$54)*X29 -> -0.53355917 | AF29: =($B$54+$B$55)*(X29+Y29) -> 0.036478831 | AG29: =$B$22*AL29*(AI29+AO29) -> 18.483978 | AH29: =$B$33*AM29*(AI29+AO29) -> 28.29338 | AI29: =[1]data!C9 -> 0.069382712 | AJ29: =[1]data!C33 -> 338.05515 | AK29: =[1]data!C57 -> 379.4978 | AL29: =[1]data!C81 -> 0.88366434 | AM29: =[1]data!C105 -> 1 | AN29: =[1]data!C123 -> 0.37194292 | AO29: =[1]data!C141 -> 0.021074371 | AP29: P5 | AQ29: =kappaP5*AJ29 -> 653.39638 | AR29: =kappaP5*AK29 -> 733.49714
A30: Pmax1 / 600/ | B30: =[1]Pmax1!$A$1 -> 600 | D30: 10 | E30: =[2]solution!B11 -> 0 | F30: =[2]solution!C11 -> 0 | G30: =[2]solution!D11 -> 60.192606 | H30: =[2]solution!E11 -> 0 | I30: =[2]solution!F11 -> 0 | J30: =[2]solution!G11 -> 0 | K30: =[2]solution!H11 -> 103.18097 | L30: =[2]solution!I11 -> 0 | ... N30: =[2]solution!K11 -> 234.9265 | O30: =O29+G30*$B$25-H30/$B$26 -> 155.97912 | P30: =O30-M30 -> 0 | Q30: =Q29+K30*$B$36-L30/$B$37 -> 234.9265 | R30: =Q30-N30 -> 3.4106051e-13 | S30: =U30-T30 -> 0 | T30: =AI30 -> 0.056760082 | U30: =[2]solution!L11 -> 0.056760082 | V30: =T30+AO30 -> 0.08874843 | W30: =V30-U30 -> 0.031988348 | X30: =[2]solution!M11 -> 0 | Y30: =[2]solution!N11 -> 0 | Z30: =H30+E30+$B$21*AN30-G30-F30-$B$22*AL30+Y30-X30 -> 0 | AA30: =L30+I30+$B$32*AN30-K30-J30-$B$33*AM30-Y30+X30 -> 9.094947e-13 | AB30: =F30*AI30-(AI30+AO30)*E30 -> 0 | AC30: =J30*AI30-(AI30+AO30)*I30 -> 0 | AD30: =(U30-$B$55)*X30-(U30+$B$54)*Y30 -> 0 | AE30: =(U30-$B$55)*Y30-(U30+$B$54)*X30 -> 0 | AF30: =($B$54+$B$55)*(X30+Y30) -> 0 | AG30: =$B$22*AL30*(AI30+AO30) -> 20.522309 | AH30: =$B$33*AM30*(AI30+AO30) -> 27.207431 | AI30: =[1]data!C10 -> 0.056760082 | AJ30: =[1]data!C34 -> 404.47 | AK30: =[1]data!C58 -> 494.172 | AL30: =[1]data!C82 -> 1 | AM30: =[1]data!C106 -> 0.98013208 | AN30: =[1]data!C124 -> 0.51218625 | AO30: =[1]data!C142 -> 0.031988348 | AP30: P3 | AQ30: =kappaP3*AJ30 -> 2652.9875 | AR30: =kappaP3*AK30 -> 3241.3582
A31: Capacity01 /-31713.9/ | B31: =[1]Capacity01!$A$1 -> -31713.9 | D31: 11 | E31: =[2]solution!B12 -> 0 | F31: =[2]solution!C12 -> 0 | G31: =[2]solution!D12 -> 120.64991 | H31: =[2]solution!E12 -> 0 | I31: =[2]solution!F12 -> 0 | J31: =[2]solution!G12 -> 0 | K31: =[2]solution!H12 -> 184.54189 | L31: =[2]solution!I12 -> 0 | ... N31: =[2]solution!K12 -> 404.70504 | O31: =O30+G31*$B$25-H31/$B$26 -> 268.18354 | P31: =O31-M31 -> 5.1159077e-13 | Q31: =Q30+K31*$B$36-L31/$B$37 -> 404.70504 | R31: =Q31-N31 -> 0 | S31: =U31-T31 -> 0 | T31: =AI31 -> 0.04694937 | U31: =[2]solution!L12 -> 0.04694937 | V31: =T31+AO31 -> 0.069140017 | W31: =V31-U31 -> 0.022190647 | X31: =[2]solution!M12 -> 0 | Y31: =[2]solution!N12 -> 0 | Z31: =H31+E31+$B$21*AN31-G31-F31-$B$22*AL31+Y31-X31 -> 4.5474735e-13 | AA31: =L31+I31+$B$32*AN31-K31-J31-$B$33*AM31-Y31+X31 -> 5.6843419e-14 | AB31: =F31*AI31-(AI31+AO31)*E31 -> 0 | AC31: =J31*AI31-(AI31+AO31)*I31 -> 0 | AD31: =(U31-$B$55)*X31-(U31+$B$54)*Y31 -> 0 | AE31: =(U31-$B$55)*Y31-(U31+$B$54)*X31 -> 0 | AF31: =($B$54+$B$55)*(X31+Y31) -> 0 | AG31: =$B$22*AL31*(AI31+AO31) -> 15.464358 | AH31: =$B$33*AM31*(AI31+AO31) -> 20.711554 | AI31: =[1]data!C11 -> 0.04694937 | AJ31: =[1]data!C35 -> 442.91 | AK31: =[1]data!C59 -> 561.3209 | AL31: =[1]data!C83 -> 0.96724587 | AM31: =[1]data!C107 -> 0.95772528 | AN31: =[1]data!C125 -> 0.60512683 | AO31: =[1]data!C143 -> 0.022190647 | AP31: P4 | AQ31: =kappaP4*AJ31 -> 2290.7704 | AR31: =kappaP4*AK31 -> 2903.2022
A32: Ppvmax2 / 800/ | B32: =[1]Ppvmax2!$A$1 -> 800 | D32: 12 | E32: =[2]solution!B13 -> 119.57085 | F32: =[2]solution!C13 -> 0 | G32: =[2]solution!D13 -> 263.27812 | H32: =[2]solution!E13 -> 0 | I32: =[2]solution!F13 -> 0 | J32: =[2]solution!G13 -> 0 | K32: =[2]solution!H13 -> 221.50565 | L32: =[2]solution!I13 -> 0 | ... N32: =[2]solution!K13 -> 608.49024 | O32: =O31+G32*$B$25-H32/$B$26 -> 513.03219 | P32: =O32-M32 -> -1.0231815e-12 | Q32: =Q31+K32*$B$36-L32/$B$37 -> 608.49024 | R32: =Q32-N32 -> 0 | S32: =U32-T32 -> 0 | T32: =AI32 -> 0.04184674 | U32: =[2]solution!L13 -> 0.04184674 | V32: =T32+AO32 -> 0.064037387 | W32: =V32-U32 -> 0.022190647 | X32: =[2]solution!M13 -> 0 | Y32: =[2]solution!N13 -> 0 | Z32: =H32+E32+$B$21*AN32-G32-F32-$B$22*AL32+Y32-X32 -> 4.2632564e-13 | AA32: =L32+I32+$B$32*AN32-K32-J32-$B$33*AM32-Y32+X32 -> 5.6843419e-14 | AB32: =F32*AI32-(AI32+AO32)*E32 -> -7.6570047 | AC32: =J32*AI32-(AI32+AO32)*I32 -> 0 | AD32: =(U32-$B$55)*X32-(U32+$B$54)*Y32 -> 0 | AE32: =(U32-$B$55)*Y32-(U32+$B$54)*X32 -> 0 | AF32: =($B$54+$B$55)*(X32+Y32) -> 0 | AG32: =$B$22*AL32*(AI32+AO32) -> 14.310693 | AH32: =$B$33*AM32*(AI32+AO32) -> 18.874521 | AI32: =[1]data!C12 -> 0.04184674 | AJ32: =[1]data!C36 -> 442.91 | AK32: =[1]data!C60 -> 561.3209 | AL32: =[1]data!C84 -> 0.96641024 | AM32: =[1]data!C108 -> 0.94232366 | AN32: =[1]data!C126 -> 0.64530983 | AO32: =[1]data!C144 -> 0.022190647 | AP32: P4
A33: Plmax2 / 312.78235978049 / | B33: =[1]Plmax2!$A$1 -> 312.78236 | D33: 13 | E33: =[2]solution!B14 -> 71.497785 | F33: =[2]solution!C14 -> 0 | G33: =[2]solution!D14 -> 400 | H33: =[2]solution!E14 -> 0 | I33: =[2]solution!F14 -> 340.47859 | J33: =[2]solution!G14 -> 0 | K33: =[2]solution!H14 -> 556.5656 | L33: =[2]solution!I14 -> 0 | ... N33: =[2]solution!K14 -> 1120.5306 | O33: =O32+G33*$B$25-H33/$B$26 -> 885.03219 | P33: =O33-M33 -> -1.0231815e-12 | Q33: =Q32+K33*$B$36-L33/$B$37 -> 1120.5306 | R33: =Q33-N33 -> 6.1390892e-12 | S33: =U33-T33 -> 0 | T33: =AI33 -> 0.039593726 | U33: =[2]solution!L14 -> 0.039593726 | V33: =T33+AO33 -> 0.061784373 | W33: =V33-U33 -> 0.022190647 | X33: =[2]solution!M14 -> 0 | Y33: =[2]solution!N14 -> 0 | Z33: =H33+E33+$B$21*AN33-G33-F33-$B$22*AL33+Y33-X33 -> -6.0396133e-14 | AA33: =L33+I33+$B$32*AN33-K33-J33-$B$33*AM33-Y33+X33 -> -6.8212103e-13 | AB33: =F33*AI33-(AI33+AO33)*E33 -> -4.4174458 | AC33: =J33*AI33-(AI33+AO33)*I33 -> -21.036256 | AD33: =(U33-$B$55)*X33-(U33+$B$54)*Y33 -> 0 | AE33: =(U33-$B$55)*Y33-(U33+$B$54)*X33 -> 0 | AF33: =($B$54+$B$55)*(X33+Y33) -> 0 | AG33: =$B$22*AL33*(AI33+AO33) -> 1.7551332 | AH33: =$B$33*AM33*(AI33+AO33) -> 17.652977 | AI33: =[1]data!C13 -> 0.039593726 | AJ33: =[1]data!C37 -> 442.91 | AK33: =[1]data!C61 -> 561.3209 | AL33: =[1]data!C85 -> 0.12284738 | AM33: =[1]data!C109 -> 0.91347581 | AN33: =[1]data!C127 -> 0.62725767 | AO33: =[1]data!C145 -> 0.022190647 | AP33: P4
A34: SOC02 / 140 / | B34: =[1]SOC02!$A$1 -> 140 | D34: 14 | E34: =[2]solution!B15 -> 282.66161 | F34: =[2]solution!C15 -> 0 | G34: =[2]solution!D15 -> 400 | H34: =[2]solution!E15 -> 0 | I34: =[2]solution!F15 -> 650 | J34: =[2]solution!G15 -> 0 | K34: =[2]solution!H15 -> 826.68054 | L34: =[2]solution!I15 -> 0 | ... N34: =[2]solution!K15 -> 1881.0767 | O34: =O33+G34*$B$25-H34/$B$26 -> 1257.0322 | P34: =O34-M34 -> 6.1390892e-12 | Q34: =Q33+K34*$B$36-L34/$B$37 -> 1881.0767 | R34: =Q34-N34 -> 4.7748472e-12 | S34: =U34-T34 -> 0 | T34: =AI34 -> 0.037885123 | U34: =[2]solution!L15 -> 0.037885123 | V34: =T34+AO34 -> 0.060075771 | W34: =V34-U34 -> 0.022190647 | X34: =[2]solution!M15 -> 0 | Y34: =[2]solution!N15 -> 0 | Z34: =H34+E34+$B$21*AN34-G34-F34-$B$22*AL34+Y34-X34 -> -5.4001248e-13 | AA34: =L34+I34+$B$32*AN34-K34-J34-$B$33*AM34-Y34+X34 -> 5.6843419e-14 | AB34: =F34*AI34-(AI34+AO34)*E34 -> -16.981114 | AC34: =J34*AI34-(AI34+AO34)*I34 -> -39.049251 | AD34: =(U34-$B$55)*X34-(U34+$B$54)*Y34 -> 0 | AE34: =(U34-$B$55)*Y34-(U34+$B$54)*X34 -> 0 | AF34: =($B$54+$B$55)*(X34+Y34) -> 0 | AG34: =$B$22*AL34*(AI34+AO34) -> 12.394158 | AH34: =$B$33*AM34*(AI34+AO34) -> 16.722655 | AI34: =[1]data!C14 -> 0.037885123 | AJ34: =[1]data!C38 -> 442.91 | AK34: =[1]data!C62 -> 561.3209 | AL34: =[1]data!C86 -> 0.89217932 | AM34: =[1]data!C110 -> 0.88994596 | AN34: =[1]data!C128 -> 0.56879992 | AO34: =[1]data!C146 -> 0.022190647 | AP34: P4
A35: C2 / 2800 / | B35: =[1]C2!$A$1 -> 2800 | D35: 15 | E35: =[2]solution!B16 -> 338.05515 | F35: =[2]solution!C16 -> 0 | G35: =[2]solution!D16 -> 383.26716 | H35: =[2]solution!E16 -> 0 | I35: =[2]solution!F16 -> 379.4978 | J35: =[2]solution!G16 -> 0 | K35: =[2]solution!H16 -> 480.70216 | L35: =[2]solution!I16 -> 0 | ... N35: =[2]solution!K16 -> 2323.3227 | O35: =O34+G35*$B$25-H35/$B$26 -> 1613.4706 | P35: =O35-M35 -> 2.5011104e-12 | Q35: =Q34+K35*$B$36-L35/$B$37 -> 2323.3227 | R35: =Q35-N35 -> 4.0927262e-12 | S35: =U35-T35 -> 0 | T35: =AI35 -> 0.036840932 | U35: =[2]solution!L16 -> 0.036840932 | V35: =T35+AO35 -> 0.057915303 | W35: =V35-U35 -> 0.021074371 | X35: =[2]solution!M16 -> 0 | Y35: =[2]solution!N16 -> 0 | Z35: =H35+E35+$B$21*AN35-G35-F35-$B$22*AL35+Y35-X35 -> 5.6843419e-14 | AA35: =L35+I35+$B$32*AN35-K35-J35-$B$33*AM35-Y35+X35 -> 6.2527761e-13 | AB35: =F35*AI35-(AI35+AO35)*E35 -> -19.578567 | AC35: =J35*AI35-(AI35+AO35)*I35 -> -21.97873 | AD35: =(U35-$B$55)*X35-(U35+$B$54)*Y35 -> 0 | AE35: =(U35-$B$55)*Y35-(U35+$B$54)*X35 -> 0 | AF35: =($B$54+$B$55)*(X35+Y35) -> 0 | AG35: =$B$22*AL35*(AI35+AO35) -> 12.975448 | AH35: =$B$33*AM35*(AI35+AO35) -> 16.063379 | AI35: =[1]data!C15 -> 0.036840932 | AJ35: =[1]data!C39 -> 338.05515 | AK35: =[1]data!C63 -> 379.4978 | AL35: =[1]data!C87 -> 0.96886548 | AM35: =[1]data!C111 -> 0.88675027 | AN35: =[1]data!C129 -> 0.47320525 | AO35: =[1]data!C147 -> 0.021074371 | AP35: P5
A36: eff_c2 / 0.92 / | B36: =[1]eff_c2!$A$1 -> 0.92 | D36: 16 | E36: =[2]solution!B17 -> 338.05515 | F36: =[2]solution!C17 -> 0 | G36: =[2]solution!D17 -> 308.09608 | H36: =[2]solution!E17 -> 0 | I36: =[2]solution!F17 -> 379.4978 | J36: =[2]solution!G17 -> 0 | K36: =[2]solution!H17 -> 365.95362 | L36: =[2]solution!I17 -> 0 | ... N36: =[2]solution!K17 -> 2660 | O36: =O35+G36*$B$25-H36/$B$26 -> 1900 | P36: =O36-M36 -> 0 | Q36: =Q35+K36*$B$36-L36/$B$37 -> 2660 | R36: =Q36-N36 -> 0 | S36: =U36-T36 -> 0 | T36: =AI36 -> 0.038253699 | U36: =[2]solution!L17 -> 0.038253699 | V36: =T36+AO36 -> 0.05932807 | W36: =V36-U36 -> 0.021074371 | X36: =[2]solution!M17 -> 0 | Y36: =[2]solution!N17 -> 0 | Z36: =H36+E36+$B$21*AN36-G36-F36-$B$22*AL36+Y36-X36 -> 5.968559e-13 | AA36: =L36+I36+$B$32*AN36-K36-J36-$B$33*AM36-Y36+X36 -> 3.4106051e-13 | AB36: =F36*AI36-(AI36+AO36)*E36 -> -20.05616 | AC36: =J36*AI36-(AI36+AO36)*I36 -> -22.514872 | AD36: =(U36-$B$55)*X36-(U36+$B$54)*Y36 -> 0 | AE36: =(U36-$B$55)*Y36-(U36+$B$54)*X36 -> 0 | AF36: =($B$54+$B$55)*(X36+Y36) -> 0 | AG36: =$B$22*AL36*(AI36+AO36) -> 13.159198 | AH36: =$B$33*AM36*(AI36+AO36) -> 16.806059 | AI36: =[1]data!C16 -> 0.038253699 | AJ36: =[1]data!C40 -> 338.05515 | AK36: =[1]data!C64 -> 379.4978 | AL36: =[1]data!C88 -> 0.95918787 | AM36: =[1]data!C112 -> 0.9056563 | AN36: =[1]data!C130 -> 0.33716142 | AO36: =[1]data!C148 -> 0.021074371 | AP36: P5
A37: eff_d2 / 0.95 / | B37: =[1]eff_d2!$A$1 -> 0.95 | D37: 17 | E37: =[2]solution!B18 -> 111.75631 | F37: =[2]solution!C18 -> 0 | G37: =[2]solution!D18 -> 0 | H37: =[2]solution!E18 -> 0 | I37: =[2]solution!F18 -> 118.72797 | J37: =[2]solution!G18 -> 0 | K37: =[2]solution!H18 -> 0 | L37: =[2]solution!I18 -> 0 | ... N37: =[2]solution!K18 -> 2660 | O37: =O36+G37*$B$25-H37/$B$26 -> 1900 | P37: =O37-M37 -> 0 | Q37: =Q36+K37*$B$36-L37/$B$37 -> 2660 | R37: =Q37-N37 -> 0 | S37: =U37-T37 -> 0 | T37: =AI37 -> 0.046423205 | U37: =[2]solution!L18 -> 0.046423205 | V37: =T37+AO37 -> 0.067497577 | W37: =V37-U37 -> 0.021074371 | X37: =[2]solution!M18 -> 0 | Y37: =[2]solution!N18 -> 0 | Z37: =H37+E37+$B$21*AN37-G37-F37-$B$22*AL37+Y37-X37 -> -5.968559e-13 | AA37: =L37+I37+$B$32*AN37-K37-J37-$B$33*AM37-Y37+X37 -> -9.094947e-13 | AB37: =F37*AI37-(AI37+AO37)*E37 -> -7.5432799 | AC37: =J37*AI37-(AI37+AO37)*I37 -> -8.0138505 | AD37: =(U37-$B$55)*X37-(U37+$B$54)*Y37 -> 0 | AE37: =(U37-$B$55)*Y37-(U37+$B$54)*X37 -> 0 | AF37: =($B$54+$B$55)*(X37+Y37) -> 0 | AG37: =$B$22*AL37*(AI37+AO37) -> 14.785525 | AH37: =$B$33*AM37*(AI37+AO37) -> 18.196269 | AI37: =[1]data!C17 -> 0.046423205 | AJ37: =[1]data!C41 -> 338.05515 | AK37: =[1]data!C65 -> 379.4978 | AL37: =[1]data!C89 -> 0.94729021 | AM37: =[1]data!C113 -> 0.86189017 | AN37: =[1]data!C131 -> 0.18857008 | AO37: =[1]data!C149 -> 0.021074371 | AP37: P5
A38: R_c2 / 0.3/ | B38: =[1]R_c2!$A$1 -> 0.3 | D38: 18 | E38: =[2]solution!B19 -> 124.92077 | F38: =[2]solution!C19 -> 0 | G38: =[2]solution!D19 -> 0 | H38: =[2]solution!E19 -> 0 | I38: =[2]solution!F19 -> 184.67296 | J38: =[2]solution!G19 -> 0 | K38: =[2]solution!H19 -> 0 | L38: =[2]solution!I19 -> 0 | ... N38: =[2]solution!K19 -> 2660 | O38: =O37+G38*$B$25-H38/$B$26 -> 1900 | P38: =O38-M38 -> 0 | Q38: =Q37+K38*$B$36-L38/$B$37 -> 2660 | R38: =Q38-N38 -> 0 | S38: =U38-T38 -> 0 | T38: =AI38 -> 0.059484767 | U38: =[2]solution!L19 -> 0.059484767 | V38: =T38+AO38 -> 0.080559138 | W38: =V38-U38 -> 0.021074371 | X38: =[2]solution!M19 -> 0 | Y38: =[2]solution!N19 -> 0 | Z38: =H38+E38+$B$21*AN38-G38-F38-$B$22*AL38+Y38-X38 -> -4.2632564e-13 | AA38: =L38+I38+$B$32*AN38-K38-J38-$B$33*AM38-Y38+X38 -> -5.4001248e-13 | AB38: =F38*AI38-(AI38+AO38)*E38 -> -10.06351 | AC38: =J38*AI38-(AI38+AO38)*I38 -> -14.877094 | AD38: =(U38-$B$55)*X38-(U38+$B$54)*Y38 -> 0 | AE38: =(U38-$B$55)*Y38-(U38+$B$54)*X38 -> 0 | AF38: =($B$54+$B$55)*(X38+Y38) -> 0 | AG38: =$B$22*AL38*(AI38+AO38) -> 12.058092 | AH38: =$B$33*AM38*(AI38+AO38) -> 17.681428 | AI38: =[1]data!C18 -> 0.059484767 | AJ38: =[1]data!C42 -> 338.05515 | AK38: =[1]data!C66 -> 379.4978 | AL38: =[1]data!C90 -> 0.64728902 | AM38: =[1]data!C114 -> 0.7017142 | AN38: =[1]data!C132 -> 0.043513583 | AO38: =[1]data!C150 -> 0.021074371 | AP38: P5
A39: R_d2 / 0.3/ | B39: =[1]R_d2!$A$1 -> 0.3 | D39: 19 | E39: =[2]solution!B20 -> 0 | F39: =[2]solution!C20 -> 0 | G39: =[2]solution!D20 -> 0 | H39: =[2]solution!E20 -> 198.91109 | I39: =[2]solution!F20 -> 0 | J39: =[2]solution!G20 -> 0 | K39: =[2]solution!H20 -> 0 | L39: =[2]solution!I20 -> 56.16991 | ... N39: =[2]solution!K20 -> 2600.8738 | O39: =O38+G39*$B$25-H39/$B$26 -> 1694.937 | P39: =O39-M39 -> 0 | Q39: =Q38+K39*$B$36-L39/$B$37 -> 2600.8738 | R39: =Q39-N39 -> 6.3664629e-12 | S39: =U39-T39 -> 0 | T39: =AI39 -> 0.076155178 | U39: =[2]solution!L20 -> 0.076155178 | V39: =T39+AO39 -> 0.14818966 | W39: =V39-U39 -> 0.072034485 | X39: =[2]solution!M20 -> 53.698761 | Y39: =[2]solution!N20 -> 0 | Z39: =H39+E39+$B$21*AN39-G39-F39-$B$22*AL39+Y39-X39 -> -3.907985e-13 | AA39: =L39+I39+$B$32*AN39-K39-J39-$B$33*AM39-Y39+X39 -> -8.5265128e-14 | AB39: =F39*AI39-(AI39+AO39)*E39 -> 0 | AC39: =J39*AI39-(AI39+AO39)*I39 -> 0 | AD39: =(U39-$B$55)*X39-(U39+$B$54)*Y39 -> 4.0223153 | AE39: =(U39-$B$55)*Y39-(U39+$B$54)*X39 -> -4.2908091 | AF39: =($B$54+$B$55)*(X39+Y39) -> 0.26849381 | AG39: =$B$22*AL39*(AI39+AO39) -> 21.518966 | AH39: =$B$33*AM39*(AI39+AO39) -> 16.281401 | AI39: =[1]data!C19 -> 0.076155178 | AJ39: =[1]data!C43 -> 504.43 | AK39: =[1]data!C67 -> 408.1543 | AL39: =[1]data!C91 -> 0.62796864 | AM39: =[1]data!C115 -> 0.35126236 | AO39: =[1]data!C151 -> 0.072034485 | AP39: P1 | AQ39: =kappaP1*AJ39 -> 14523.483 | AR39: =kappaP1*AK39 -> 11751.526
A40: DoD2 / 0.9/ | B40: =[1]DoD2!$A$1 -> 0.9 | D40: 20 | E40: =[2]solution!B21 -> 0 | F40: =[2]solution!C21 -> 247.53433 | G40: =[2]solution!D21 -> 0 | H40: =[2]solution!E21 -> 400 | I40: =[2]solution!F21 -> 0 | J40: =[2]solution!G21 -> 650 | K40: =[2]solution!H21 -> 0 | L40: =[2]solution!I21 -> 755.98332 | ... N40: =[2]solution!K21 -> 1805.1019 | O40: =O39+G40*$B$25-H40/$B$26 -> 1282.5659 | P40: =O40-M40 -> 1.8189894e-12 | Q40: =Q39+K40*$B$36-L40/$B$37 -> 1805.1019 | R40: =Q40-N40 -> 5.2295945e-12 | S40: =U40-T40 -> 0 | T40: =AI40 -> 0.090286438 | U40: =[2]solution!L21 -> 0.090286438 | V40: =T40+AO40 -> 0.14150468 | W40: =V40-U40 -> 0.051218244 | X40: =[2]solution!M21 -> 0 | Y40: =[2]solution!N21 -> 0 | Z40: =H40+E40+$B$21*AN40-G40-F40-$B$22*AL40+Y40-X40 -> 9.3791641e-13 | AA40: =L40+I40+$B$32*AN40-K40-J40-$B$33*AM40-Y40+X40 -> -9.9475983e-14 | AB40: =F40*AI40-(AI40+AO40)*E40 -> 22.348993 | AC40: =J40*AI40-(AI40+AO40)*I40 -> 58.686185 | AD40: =(U40-$B$55)*X40-(U40+$B$54)*Y40 -> 0 | AE40: =(U40-$B$55)*Y40-(U40+$B$54)*X40 -> 0 | AF40: =($B$54+$B$55)*(X40+Y40) -> 0 | AG40: =$B$22*AL40*(AI40+AO40) -> 21.574606 | AH40: =$B$33*AM40*(AI40+AO40) -> 14.997136 | AI40: =[1]data!C20 -> 0.090286438 | AJ40: =[1]data!C44 -> 453.96687 | AK40: =[1]data!C68 -> 437.7123 | AL40: =[1]data!C92 -> 0.65933562 | AM40: =[1]data!C116 -> 0.33884045 | AO40: =[1]data!C152 -> 0.051218244 | AP40: P2 | AQ40: =kappaP2*AJ40 -> 6844.749 | AR40: =kappaP2*AK40 -> 6599.6685
A41: Pmax2 / 650/ | B41: =[1]Pmax2!$A$1 -> 650 | D41: 21 | E41: =[2]solution!B22 -> 0 | F41: =[2]solution!C22 -> 356.21759 | G41: =[2]solution!D22 -> 0 | H41: =[2]solution!E22 -> 400 | I41: =[2]solution!F22 -> 0 | J41: =[2]solution!G22 -> 650 | K41: =[2]solution!H22 -> 0 | L41: =[2]solution!I22 -> 840 | ... N41: =[2]solution!K22 -> 920.89134 | O41: =O40+G41*$B$25-H41/$B$26 -> 870.19475 | P41: =O41-M41 -> 0 | Q41: =Q40+K41*$B$36-L41/$B$37 -> 920.89134 | R41: =Q41-N41 -> -1.3642421e-12 | S41: =U41-T41 -> 0.012637817 | T41: =AI41 -> 0.099023507 | U41: =[2]solution!L22 -> 0.11166132 | V41: =T41+AO41 -> 0.15024175 | W41: =V41-U41 -> 0.038580428 | X41: =[2]solution!M22 -> 0 | Y41: =[2]solution!N22 -> 90.705259 | Z41: =H41+E41+$B$21*AN41-G41-F41-$B$22*AL41+Y41-X41 -> 3.5527137e-13 | AA41: =L41+I41+$B$32*AN41-K41-J41-$B$33*AM41-Y41+X41 -> 8.5265128e-14 | AB41: =F41*AI41-(AI41+AO41)*E41 -> 35.273915 | AC41: =J41*AI41-(AI41+AO41)*I41 -> 64.365279 | AD41: =(U41-$B$55)*X41-(U41+$B$54)*Y41 -> -10.468414 | AE41: =(U41-$B$55)*Y41-(U41+$B$54)*X41 -> 10.014888 | AF41: =($B$54+$B$55)*(X41+Y41) -> 0.45352629 | AG41: =$B$22*AL41*(AI41+AO41) -> 20.205663 | AH41: =$B$33*AM41*(AI41+AO41) -> 14.918216 | AI41: =[1]data!C21 -> 0.099023507 | AJ41: =[1]data!C45 -> 453.96687 | AK41: =[1]data!C69 -> 437.7123 | AL41: =[1]data!C93 -> 0.58159001 | AM41: =[1]data!C117 -> 0.31745633 | AO41: =[1]data!C153 -> 0.051218244 | AP41: P2
A42: Capacity02 /-33786.68/ | B42: =[1]Capacity02!$A$1 -> -33786.68 | D42: 22 | E42: =[2]solution!B23 -> 0 | F42: =[2]solution!C23 -> 358.5574 | G42: =[2]solution!D23 -> 0 | H42: =[2]solution!E23 -> 400 | I42: =[2]solution!F23 -> 0 | J42: =[2]solution!G23 -> 650 | K42: =[2]solution!H23 -> 0 | L42: =[2]solution!I23 -> 741.84677 | ... N42: =[2]solution!K23 -> 140 | O42: =O41+G42*$B$25-H42/$B$26 -> 457.82362 | P42: =O42-M42 -> 0 | Q42: =Q41+K42*$B$36-L42/$B$37 -> 140 | R42: =Q42-N42 -> -1.1368684e-12 | S42: =U42-T42 -> 0 | T42: =AI42 -> 0.09037211 | U42: =[2]solution!L23 -> 0.09037211 | V42: =T42+AO42 -> 0.14159035 | W42: =V42-U42 -> 0.051218244 | X42: =[2]solution!M23 -> 0 | Y42: =[2]solution!N23 -> 0 | Z42: =H42+E42+$B$21*AN42-G42-F42-$B$22*AL42+Y42-X42 -> -2.8421709e-14 | AA42: =L42+I42+$B$32*AN42-K42-J42-$B$33*AM42-Y42+X42 -> -4.9737992e-13 | AB42: =F42*AI42-(AI42+AO42)*E42 -> 32.403588 | AC42: =J42*AI42-(AI42+AO42)*I42 -> 58.741871 | AD42: =(U42-$B$55)*X42-(U42+$B$54)*Y42 -> 0 | AE42: =(U42-$B$55)*Y42-(U42+$B$54)*X42 -> 0 | AF42: =($B$54+$B$55)*(X42+Y42) -> 0 | AG42: =$B$22*AL42*(AI42+AO42) -> 5.8678728 | AH42: =$B$33*AM42*(AI42+AO42) -> 13.004617 | AI42: =[1]data!C22 -> 0.09037211 | AJ42: =[1]data!C46 -> 453.96687 | AK42: =[1]data!C70 -> 437.7123 | AL42: =[1]data!C94 -> 0.17921794 | AM42: =[1]data!C118 -> 0.29364435 | AO42: =[1]data!C154 -> 0.051218244 | AP42: P2
D43: 23 | E43: =[2]solution!B24 -> 0 | F43: =[2]solution!C24 -> 91.926195 | G43: =[2]solution!D24 -> 0 | H43: =[2]solution!E24 -> 211.37181 | I43: =[2]solution!F24 -> 0 | J43: =[2]solution!G24 -> 0 | K43: =[2]solution!H24 -> 0 | L43: =[2]solution!I24 -> 0 | ... N43: =[2]solution!K24 -> 140 | O43: =O42+G43*$B$25-H43/$B$26 -> 239.91453 | P43: =O43-M43 -> -4.5474735e-13 | Q43: =Q42+K43*$B$36-L43/$B$37 -> 140 | R43: =Q43-N43 -> -1.1368684e-12 | S43: =U43-T43 -> 0 | T43: =AI43 -> 0.081188795 | U43: =[2]solution!L24 -> 0.081188795 | V43: =T43+AO43 -> 0.10226317 | W43: =V43-U43 -> 0.021074371 | X43: =[2]solution!M24 -> 85.94266 | Y43: =[2]solution!N24 -> 0 | Z43: =H43+E43+$B$21*AN43-G43-F43-$B$22*AL43+Y43-X43 -> -1.9895197e-13 | AA43: =L43+I43+$B$32*AN43-K43-J43-$B$33*AM43-Y43+X43 -> 0 | AB43: =F43*AI43-(AI43+AO43)*E43 -> 7.4633769 | AC43: =J43*AI43-(AI43+AO43)*I43 -> 0 | AD43: =(U43-$B$55)*X43-(U43+$B$54)*Y43 -> 6.8701526 | AE43: =(U43-$B$55)*Y43-(U43+$B$54)*X43 -> -7.2998659 | AF43: =($B$54+$B$55)*(X43+Y43) -> 0.4297133 | AG43: =$B$22*AL43*(AI43+AO43) -> 3.4261186 | AH43: =$B$33*AM43*(AI43+AO43) -> 8.7887685 | AI43: =[1]data!C23 -> 0.081188795 | AJ43: =[1]data!C47 -> 338.05515 | AK43: =[1]data!C71 -> 379.4978 | AL43: =[1]data!C95 -> 0.14488307 | AM43: =[1]data!C119 -> 0.27476824 | AO43: =[1]data!C155 -> 0.021074371 | AP43: P5
A44: kappaP1 / 28.79187 / | B44: =[1]kappaP1!$A$1 -> 28.79187 | D44: 24 | E44: =[2]solution!B25 -> 0 | F44: =[2]solution!C25 -> 0 | G44: =[2]solution!D25 -> 0 | H44: =[2]solution!E25 -> 135.7171 | I44: =[2]solution!F25 -> 0 | J44: =[2]solution!G25 -> 0 | K44: =[2]solution!H25 -> 0 | L44: =[2]solution!I25 -> 0 | ... N44: =[2]solution!K25 -> 140 | O44: =O43+G44*$B$25-H44/$B$26 -> 100 | P44: =O44-M44 -> -4.2632564e-13 | Q44: =Q43+K44*$B$36-L44/$B$37 -> 140 | R44: =Q44-N44 -> -1.1368684e-12 | S44: =U44-T44 -> 0 | T44: =AI44 -> 0.074767233 | U44: =[2]solution!L25 -> 0.074767233 | V44: =T44+AO44 -> 0.095841604 | W44: =V44-U44 -> 0.021074371 | X44: =[2]solution!M25 -> 103.7963 | Y44: =[2]solution!N25 -> 0 | Z44: =H44+E44+$B$21*AN44-G44-F44-$B$22*AL44+Y44-X44 -> 0 | AA44: =L44+I44+$B$32*AN44-K44-J44-$B$33*AM44-Y44+X44 -> 0 | AB44: =F44*AI44-(AI44+AO44)*E44 -> 0 | AC44: =J44*AI44-(AI44+AO44)*I44 -> 0 | AD44: =(U44-$B$55)*X44-(U44+$B$54)*Y44 -> 7.6308169 | AE44: =(U44-$B$55)*Y44-(U44+$B$54)*X44 -> -8.1497984 | AF44: =($B$54+$B$55)*(X44+Y44) -> 0.51898151 | AG44: =$B$22*AL44*(AI44+AO44) -> 3.0593402 | AH44: =$B$33*AM44*(AI44+AO44) -> 9.9480041 | AI44: =[1]data!C24 -> 0.074767233 | AJ44: =[1]data!C48 -> 338.05515 | AK44: =[1]data!C72 -> 379.4978 | AL44: =[1]data!C96 -> 0.13804102 | AM44: =[1]data!C120 -> 0.33184832 | AO44: =[1]data!C156 -> 0.021074371 | AP44: P5
A45: kappaP2 / 15.07764 / | B45: =[1]kappaP2!$A$1 -> 15.07764
A46: kappaP3 / 6.55917 / | B46: =[1]kappaP3!$A$1 -> 6.55917
A47: kappaP4 / 5.17209 / | B47: =[1]kappaP4!$A$1 -> 5.17209
A48: kappaP5 / 1.93281 / | B48: =[1]kappaP5!$A$1 -> 1.93281
A49: kappaP6 / 0.91609 / | B49: =[1]kappaP6!$A$1 -> 0.91609
A50: CAPEXpv /700/ | B50: =[1]CAPEXpv!$A$1 -> 700
...

Sheet M7_24 Gams Solution 
AC11: I1_Profit =e= EP1+E1+IndustryProfitnoCDS_BESS_PV1;
AC12: I1_Profit | AD12: =AB19+AD19+AG19 -> 92785.901
AC13: I2_Profit | AD13: =AC19+AE19+AH19 -> 132669.42
AC14: I1+I2_Profit | AD14: =AD13+AD12 -> 225455.32 | AE14: =[1]IndustryProfit!$A$2 -> 225455.32 | AF14: =AE14-AD14 -> 7.5495336e-08
E15: =E19*365 -> 550369.21 | AC15: VPN | AD15: =AD14/B53-B61-B62 -> 792171.67 | AE15: =[1]npv!$A$2 -> 792171.67 | AF15: =AE15-AD15 -> 9.406358e-07
D16: LIM | E16: =B30 -> 600 | F16: =E16 -> 600 | G16: =B59 -> 400 | H16: =G16 -> 400 | I16: =B41 -> 650 | J16: =I16 -> 650 | K16: =B60 -> 840 | L16: =K16 -> 840 | X16: =B56 -> 400 | Y16: =X16 -> 400
D17: MAX | E17: =MAX(E21:E44) -> 338.05515 | F17: =MAX(F21:F44) -> 358.5574 | G17: =MAX(G21:G44) -> 400 | H17: =MAX(H21:H44) -> 400 | I17: =MAX(I21:I44) -> 561.3209 | J17: =MAX(J21:J44) -> 650 | K17: =MAX(K21:K44) -> 738.00144 | L17: =MAX(L21:L44) -> 840 | X17: =MAX(X21:X44) -> 103.7963 | Y17: =MAX(Y21:Y44) -> 90.705259 | AB17: =AB18-AB19 -> 7.5775461e-08 | AC17: =AC18-AC19 -> 0 | AD17: =AD18-AD19 -> 0 | AE17: =AE18-AE19 -> 0 | AF17: =AF18-AF19 -> 0 | AG17: =AG18-AG19 -> 0 | AH17: =AH18-AH19 -> 0
E18: =[1]Wimport1!$A$2 -> 550369.21 | P18: =SUM(P21:P44) -> 3.2400749e-12 | R18: =SUM(R21:R44) -> 2.1000801e-10 | Z18: =SUM(Z21:Z44) -> 2.613266e-09 | AA18: =SUM(AA21:AA44) -> -1.7887913e-12 | AB18: =[1]Benefit1!$A$2 -> -27251.643 | AC18: =[1]Benefit2!$A$2 -> -50874.331 | AD18: =[1]E1!$A$2 -> 5935.8951 | AE18: =[1]E2!$A$2 -> -6748.9913 | AF18: =[1]APA!$A$2 -> 813.09623 | AG18: =[1]IndustryProfitnoCDS_BESS_PV1!$A$2 -> 114101.65 | AH18: =[1]IndustryProfitnoCDS_BESS_PV2!$A$2 -> 190292.74
D19: sum | E19: =SUM(E21:E44) -> 1507.8608 | F19: =SUM(F21:F44) -> 1054.2355 | G19: =SUM(G21:G44) -> 1935.4839 | H19: =SUM(H21:H44) -> 1746 | I19: =SUM(I21:I44) -> 3488.398 | J19: =SUM(J21:J44) -> 1950 | K19: =SUM(K21:K44) -> 3071.6997 | L19: =SUM(L21:L44) -> 2684.6656 | X19: =SUM(X21:X44) -> 354.82692 | Y19: =SUM(Y21:Y44) -> 90.705259 | AB19: =SUM(AB21:AB44)*365-B63 -> -27251.643 | AC19: =SUM(AC21:AC44)*365-B64 -> -50874.331 | AD19: =SUM(AD21:AD44)*365-D63 -> 5935.8951 | AE19: =SUM(AE21:AE44)*365-D64 -> -6748.9913 | AF19: =365*SUM(AF21:AF44)+2*$B$65 -> 813.09623 | AG19: =365*SUM(AG21:AG44)-B31 -> 114101.65 | AH19: =365*SUM(AH21:AH44)-B42 -> 190292.74
E20: Pb1 | F20: Ps1 | G20: Pc1 | H20: Pd1 | I20: Pb2 | J20: Ps2 | K20: Pc2 | L20: Pd2 | M20: SOC1 | N20: SOC2 | U20: epsilon | X20: P12CDS | Y20: P21CDS | Z20: BALANCES | AB20: Benefit1 | AC20: Benefit2 | AD20: E1 | AE20: E2 | AF20: APA | AG20: BASE1 | AH20: BASE2 | AI20: lambda | AJ20: pbmax1 | AK20: pbmax2 | AL20: Plu1 | AM20: Plu2 | AN20: Ppvu | AO20: psi
A21: Ppvmax1 / 569/ | B21: =[1]Ppvmax1!$A$1 -> 569 | D21: 1 | E21: 31.307452 | F21: =[1]Ps1!B2 -> 0 | G21: =[1]Pc1!B2 -> 1.6276045e-10 | H21: =[1]Pd1!B2 -> 0 | I21: =[1]Pb2!B2 -> 165.79382 | J21: =[1]Ps2!B2 -> 0 | K21: =[1]Pc2!B2 -> 7.0144779e-11 | L21: =[1]Pd2!B2 -> 0 | M21: =[1]SOC1!B2 -> 100 | N21: =[1]SOC2!B2 -> 140 | O21: =B23+G21*$B$25-H21/$B$26 -> 100 | P21: =O21-M21 -> 0 | Q21: =B34+K21*$B$36-L21/$B$37 -> 140 | R21: =Q21-N21 -> 0 | S21: =U21-T21 -> 0 | T21: =AI21 -> 0.068746795 | U21: =[1]epsilon!B2 -> 0.068746795 | V21: =T21+AO21 -> 0.0915673 | W21: =V21-U21 -> 0.022820505 | X21: =[1]P12CDS!B2 -> 0 | Y21: =[1]P21CDS!B2 -> 0 | Z21: =H21+E21+$B$21*AN21-G21-F21-$B$22*AL21+Y21-X21 -> -1.6317259e-10 | AA21: =L21+I21+$B$32*AN21-K21-J21-$B$33*AM21-Y21+X21 -> -2.8421709e-14 | AB21: =F21*AI21-(AI21+AO21)*E21 -> -2.8667388 | AC21: =J21*AI21-(AI21+AO21)*I21 -> -15.181292 | AD21: =(U21-$B$55)*X21-(U21+$B$54)*Y21 -> 0 | AE21: =(U21-$B$55)*Y21-(U21+$B$54)*X21 -> 0 | AF21: =($B$54+$B$55)*(X21+Y21) -> 0 | AG21: =$B$22*AL21*(AI21+AO21) -> 2.8667388 | AH21: =$B$33*AM21*(AI21+AO21) -> 15.181292 | AI21: =[1]data!C1 -> 0.068746795 | AJ21: =[1]data!C25 -> 564.3 | AK21: =[1]data!C49 -> 553.8896 | AL21: =[1]data!C73 -> 0.13538863 | AM21: =[1]data!C97 -> 0.53006129 | AO21: =[1]data!C133 -> 0.022820505 | AP21: P6 | AQ21: =kappaP6*AJ21 -> 516.94959 | AR21: =kappaP6*AK21 -> 507.41272 | AU21: 1 | AV21: : {'lambda': | AW21: 0.068746795 | AX21: =AW21-AI21 -> 0 | AY21: 0.13538863 | AZ21: =AY21-AL21 -> 0 | BA21: 0.022820505 | BB21: =BA21-AO21 -> 0 | BC21: 0 | BD21: =BC21-AN21 -> 0 | BF21: 1 | BG21: : {'lambda': | BH21: 0.068746795 | BI21: , 'Plu': | BJ21: 0.53006129 | BK21: =BJ21-AM21 -> 0 | BL21: 0.022820505 | BM21: , 'Ppvu': | BN21: 0 | BO21: },
A22: Plmax1 / 231.241369863014 / | B22: =[1]Plmax1!$A$1 -> 231.24137 | D22: 2 | E22: 20.898959 | F22: =[1]Ps1!B3 -> 0 | G22: =[1]Pc1!B3 -> 0 | H22: =[1]Pd1!B3 -> 2.8630356e-11 | I22: =[1]Pb2!B3 -> 166.29426 | J22: =[1]Ps2!B3 -> 0 | K22: =[1]Pc2!B3 -> 0 | L22: =[1]Pd2!B3 -> 1.6345406e-11 | M22: =[1]SOC1!B3 -> 100 | N22: =[1]SOC2!B3 -> 140 | O22: =O21+G22*$B$25-H22/$B$26 -> 100 | P22: =O22-M22 -> 0 | Q22: =Q21+K22*$B$36-L22/$B$37 -> 140 | R22: =Q22-N22 -> 0 | S22: =U22-T22 -> 0 | T22: =AI22 -> 0.064382932 | U22: =[1]epsilon!B3 -> 0.064382932 | V22: =T22+AO22 -> 0.087203437 | W22: =V22-U22 -> 0.022820505 | X22: =[1]P12CDS!B3 -> 0 | Y22: =[1]P21CDS!B3 -> 0 | Z22: =H22+E22+$B$21*AN22-G22-F22-$B$22*AL22+Y22-X22 -> 2.8951064e-11 | AA22: =L22+I22+$B$32*AN22-K22-J22-$B$33*AM22-Y22+X22 -> -1.1368684e-13 | AB22: =F22*AI22-(AI22+AO22)*E22 -> -1.822461 | AC22: =J22*AI22-(AI22+AO22)*I22 -> -14.501431 | AD22: =(U22-$B$55)*X22-(U22+$B$54)*Y22 -> 0 | AE22: =(U22-$B$55)*Y22-(U22+$B$54)*X22 -> 0 | AF22: =($B$54+$B$55)*(X22+Y22) -> 0 | AG22: =$B$22*AL22*(AI22+AO22) -> 1.822461 | AH22: =$B$33*AM22*(AI22+AO22) -> 14.501431 | AI22: =[1]data!C2 -> 0.064382932 | AJ22: =[1]data!C26 -> 564.3 | AK22: =[1]data!C50 -> 553.8896 | AL22: =[1]data!C74 -> 0.090377249 | AM22: =[1]data!C98 -> 0.53166123 | AO22: =[1]data!C134 -> 0.022820505 | AP22: P6 | AU22: 2 | AV22: : {'lambda': | AW22: 0.064382932 | AX22: =AW22-AI22 -> 0 | AY22: 0.090377249 | AZ22: =AY22-AL22 -> 0 | BA22: 0.022820505 | BB22: =BA22-AO22 -> 0 | BC22: 0 | BD22: =BC22-AN22 -> 0 | BF22: 2 | BG22: : {'lambda': | BH22: 0.064382932 | BI22: , 'Plu': | BJ22: 0.53166123 | BK22: =BJ22-AM22 -> 0 | BL22: 0.022820505 | BM22: , 'Ppvu': | BN22: 0 | BO22: },
A23: SOC01 / 100 / | B23: =[1]SOC01!$A$1 -> 100 | D23: 3 | E23: 17.653808 | F23: =[1]Ps1!B4 -> 0 | G23: =[1]Pc1!B4 -> 0 | H23: =[1]Pd1!B4 -> 2.1238037e-11 | I23: =[1]Pb2!B4 -> 167.08084 | J23: =[1]Ps2!B4 -> 0 | K23: =[1]Pc2!B4 -> 0 | L23: =[1]Pd2!B4 -> 1.4317361e-11 | M23: =[1]SOC1!B4 -> 100 | N23: =[1]SOC2!B4 -> 140 | O23: =O22+G23*$B$25-H23/$B$26 -> 100 | P23: =O23-M23 -> 0 | Q23: =Q22+K23*$B$36-L23/$B$37 -> 140 | R23: =Q23-N23 -> 0 | S23: =U23-T23 -> 0 | T23: =AI23 -> 0.062238411 | U23: =[1]epsilon!B4 -> 0.062238411 | V23: =T23+AO23 -> 0.085058916 | W23: =V23-U23 -> 0.022820505 | X23: =[1]P12CDS!B4 -> 0 | Y23: =[1]P21CDS!B4 -> 0 | Z23: =H23+E23+$B$21*AN23-G23-F23-$B$22*AL23+Y23-X23 -> 2.1135094e-11 | AA23: =L23+I23+$B$32*AN23-K23-J23-$B$33*AM23-Y23+X23 -> -2.2737368e-13 | AB23: =F23*AI23-(AI23+AO23)*E23 -> -1.5016138 | AC23: =J23*AI23-(AI23+AO23)*I23 -> -14.211715 | AD23: =(U23-$B$55)*X23-(U23+$B$54)*Y23 -> 0 | AE23: =(U23-$B$55)*Y23-(U23+$B$54)*X23 -> 0 | AF23: =($B$54+$B$55)*(X23+Y23) -> 0 | AG23: =$B$22*AL23*(AI23+AO23) -> 1.5016138 | AH23: =$B$33*AM23*(AI23+AO23) -> 14.211715 | AI23: =[1]data!C3 -> 0.062238411 | AJ23: =[1]data!C27 -> 564.3 | AK23: =[1]data!C51 -> 553.8896 | AL23: =[1]data!C75 -> 0.076343641 | AM23: =[1]data!C99 -> 0.53417603 | AO23: =[1]data!C135 -> 0.022820505 | AP23: P6 | AU23: 3 | AV23: : {'lambda': | AW23: 0.062238411 | AX23: =AW23-AI23 -> 0 | AY23: 0.076343641 | AZ23: =AY23-AL23 -> 0 | BA23: 0.022820505 | BB23: =BA23-AO23 -> 0 | BC23: 0 | BD23: =BC23-AN23 -> 0 | BF23: 3 | BG23: : {'lambda': | BH23: 0.062238411 | BI23: , 'Plu': | BJ23: 0.53417603 | BK23: =BJ23-AM23 -> 0 | BL23: 0.022820505 | BM23: , 'Ppvu': | BN23: 0 | BO23: },
A24: C1 / 2000 / | B24: =[1]C1!$A$1 -> 2000 | D24: 4 | E24: 17.394959 | F24: =[1]Ps1!B5 -> 0 | G24: =[1]Pc1!B5 -> 0 | H24: =[1]Pd1!B5 -> 1.7654442e-11 | I24: =[1]Pb2!B5 -> 505.64267 | J24: =[1]Ps2!B5 -> 0 | K24: =[1]Pc2!B5 -> 332.56931 | L24: =[1]Pd2!B5 -> 0 | M24: =[1]SOC1!B5 -> 100 | N24: =[1]SOC2!B5 -> 445.96377 | O24: =O23+G24*$B$25-H24/$B$26 -> 100 | P24: =O24-M24 -> 0 | Q24: =Q23+K24*$B$36-L24/$B$37 -> 445.96377 | R24: =Q24-N24 -> 6.2527761e-13 | S24: =U24-T24 -> 0 | T24: =AI24 -> 0.060464137 | U24: =[1]epsilon!B5 -> 0.060464137 | V24: =T24+AO24 -> 0.083284642 | W24: =V24-U24 -> 0.022820505 | X24: =[1]P12CDS!B5 -> 0 | Y24: =[1]P21CDS!B5 -> 0 | Z24: =H24+E24+$B$21*AN24-G24-F24-$B$22*AL24+Y24-X24 -> 1.7983837e-11 | AA24: =L24+I24+$B$32*AN24-K24-J24-$B$33*AM24-Y24+X24 -> 3.9790393e-13 | AB24: =F24*AI24-(AI24+AO24)*E24 -> -1.4487329 | AC24: =J24*AI24-(AI24+AO24)*I24 -> -42.112269 | AD24: =(U24-$B$55)*X24-(U24+$B$54)*Y24 -> 0 | AE24: =(U24-$B$55)*Y24-(U24+$B$54)*X24 -> 0 | AF24: =($B$54+$B$55)*(X24+Y24) -> 0 | AG24: =$B$22*AL24*(AI24+AO24) -> 1.4487329 | AH24: =$B$33*AM24*(AI24+AO24) -> 14.414353 | AI24: =[1]data!C4 -> 0.060464137 | AJ24: =[1]data!C28 -> 564.3 | AK24: =[1]data!C52 -> 553.8896 | AL24: =[1]data!C76 -> 0.075224251 | AM24: =[1]data!C100 -> 0.55333478 | AO24: =[1]data!C136 -> 0.022820505 | AP24: P6 | AU24: 4 | AV24: : {'lambda': | AW24: 0.060464137 | AX24: =AW24-AI24 -> 0 | AY24: 0.075224251 | AZ24: =AY24-AL24 -> 0 | BA24: 0.022820505 | BB24: =BA24-AO24 -> 0 | BC24: 0 | BD24: =BC24-AN24 -> 0 | BF24: 4 | BG24: : {'lambda': | BH24: 0.060464137 | BI24: , 'Plu': | BJ24: 0.55333478 | BK24: =BJ24-AM24 -> 0 | BL24: 0.022820505 | BM24: , 'Ppvu': | BN24: 0 | BO24: },
A25: eff_c1 / 0.93 / | B25: =[1]eff_c1!$A$1 -> 0.93 | D25: 5 | E25: 17.182986 | F25: =[1]Ps1!B6 -> 0 | G25: =[1]Pc1!B6 -> 0 | H25: =[1]Pd1!B6 -> 1.7974723e-11 | I25: =[1]Pb2!B6 -> 193.604 | J25: =[1]Ps2!B6 -> 0 | K25: =[1]Pc2!B6 -> 0 | L25: =[1]Pd2!B6 -> 4.7277013e-11 | M25: =[1]SOC1!B6 -> 100 | N25: =[1]SOC2!B6 -> 445.96377 | O25: =O24+G25*$B$25-H25/$B$26 -> 100 | P25: =O25-M25 -> 0 | Q25: =Q24+K25*$B$36-L25/$B$37 -> 445.96377 | R25: =Q25-N25 -> 6.8212103e-13 | S25: =U25-T25 -> 0 | T25: =AI25 -> 0.060655534 | U25: =[1]epsilon!B6 -> 0.060655534 | V25: =T25+AO25 -> 0.08347604 | W25: =V25-U25 -> 0.022820505 | X25: =[1]P12CDS!B6 -> 0 | Y25: =[1]P21CDS!B6 -> 0 | Z25: =H25+E25+$B$21*AN25-G25-F25-$B$22*AL25+Y25-X25 -> 1.7994495e-11 | AA25: =L25+I25+$B$32*AN25-K25-J25-$B$33*AM25-Y25+X25 -> -5.6843419e-14 | AB25: =F25*AI25-(AI25+AO25)*E25 -> -1.4343676 | AC25: =J25*AI25-(AI25+AO25)*I25 -> -16.161295 | AD25: =(U25-$B$55)*X25-(U25+$B$54)*Y25 -> 0 | AE25: =(U25-$B$55)*Y25-(U25+$B$54)*X25 -> 0 | AF25: =($B$54+$B$55)*(X25+Y25) -> 0 | AG25: =$B$22*AL25*(AI25+AO25) -> 1.4343676 | AH25: =$B$33*AM25*(AI25+AO25) -> 16.161295 | AI25: =[1]data!C5 -> 0.060655534 | AJ25: =[1]data!C29 -> 564.3 | AK25: =[1]data!C53 -> 553.8896 | AL25: =[1]data!C77 -> 0.074307579 | AM25: =[1]data!C101 -> 0.61897352 | AO25: =[1]data!C137 -> 0.022820505 | AP25: P6 | AU25: 5 | AV25: : {'lambda': | AW25: 0.060655534 | AX25: =AW25-AI25 -> 0 | AY25: 0.074307579 | AZ25: =AY25-AL25 -> 0 | BA25: 0.022820505 | BB25: =BA25-AO25 -> 0 | BC25: 0 | BD25: =BC25-AN25 -> 0 | BF25: 5 | BG25: : {'lambda': | BH25: 0.060655534 | BI25: , 'Plu': | BJ25: 0.61897352 | BK25: =BJ25-AM25 -> 0 | BL25: 0.022820505 | BM25: , 'Ppvu': | BN25: 0 | BO25: },
A26: eff_d1 / 0.97 / | B26: =[1]eff_d1!$A$1 -> 0.97 | D26: 6 | E26: 16.905041 | F26: =[1]Ps1!B7 -> 0 | G26: =[1]Pc1!B7 -> 0 | H26: =[1]Pd1!B7 -> 3.6054858e-11 | I26: =[1]Pb2!B7 -> 229.17505 | J26: =[1]Ps2!B7 -> 0 | K26: =[1]Pc2!B7 -> 0 | L26: =[1]Pd2!B7 -> 1.1091361e-10 | M26: =[1]SOC1!B7 -> 100 | N26: =[1]SOC2!B7 -> 445.96377 | O26: =O25+G26*$B$25-H26/$B$26 -> 100 | P26: =O26-M26 -> 0 | Q26: =Q25+K26*$B$36-L26/$B$37 -> 445.96377 | R26: =Q26-N26 -> 0 | S26: =U26-T26 -> 0 | T26: =AI26 -> 0.065132137 | U26: =[1]epsilon!B7 -> 0.065132137 | V26: =T26+AO26 -> 0.087952642 | W26: =V26-U26 -> 0.022820505 | X26: =[1]P12CDS!B7 -> 0 | Y26: =[1]P21CDS!B7 -> 0 | Z26: =H26+E26+$B$21*AN26-G26-F26-$B$22*AL26+Y26-X26 -> 3.5598191e-11 | AA26: =L26+I26+$B$32*AN26-K26-J26-$B$33*AM26-Y26+X26 -> 2.8421709e-14 | AB26: =F26*AI26-(AI26+AO26)*E26 -> -1.486843 | AC26: =J26*AI26-(AI26+AO26)*I26 -> -20.156552 | AD26: =(U26-$B$55)*X26-(U26+$B$54)*Y26 -> 0 | AE26: =(U26-$B$55)*Y26-(U26+$B$54)*X26 -> 0 | AF26: =($B$54+$B$55)*(X26+Y26) -> 0 | AG26: =$B$22*AL26*(AI26+AO26) -> 1.486843 | AH26: =$B$33*AM26*(AI26+AO26) -> 20.156552 | AI26: =[1]data!C6 -> 0.065132137 | AJ26: =[1]data!C30 -> 564.3 | AK26: =[1]data!C54 -> 553.8896 | AL26: =[1]data!C78 -> 0.073105609 | AM26: =[1]data!C102 -> 0.73269814 | AO26: =[1]data!C138 -> 0.022820505 | AP26: P6 | AU26: 6 | AV26: : {'lambda': | AW26: 0.065132137 | AX26: =AW26-AI26 -> 0 | AY26: 0.073105609 | AZ26: =AY26-AL26 -> 0 | BA26: 0.022820505 | BB26: =BA26-AO26 -> 0 | BC26: 0 | BD26: =BC26-AN26 -> 0 | BF26: 6 | BG26: : {'lambda': | BH26: 0.065132137 | BI26: , 'Plu': | BJ26: 0.73269814 | BK26: =BJ26-AM26 -> 0 | BL26: 0.022820505 | BM26: , 'Ppvu': | BN26: 0 | BO26: },
A27: R_c1 / 0.2/ | B27: =[1]R_c1!$A$1 -> 0.2 | D27: 7 | E27: 0 | F27: =[1]Ps1!B8 -> 5.6889932e-12 | G27: =[1]Pc1!B8 -> 0 | H27: =[1]Pd1!B8 -> 5.6889932e-12 | I27: =[1]Pb2!B8 -> 0 | J27: =[1]Ps2!B8 -> 2.6745625e-11 | K27: =[1]Pc2!B8 -> 0 | L27: =[1]Pd2!B8 -> 235.15339 | M27: =[1]SOC1!B8 -> 100 | N27: =[1]SOC2!B8 -> 198.43388 | O27: =O26+G27*$B$25-H27/$B$26 -> 100 | P27: =O27-M27 -> 0 | Q27: =Q26+K27*$B$36-L27/$B$37 -> 198.43388 | R27: =Q27-N27 -> 0 | S27: =U27-T27 -> 0.0019201398 | T27: =AI27 -> 0.073826082 | U27: =[1]epsilon!B8 -> 0.075746222 | V27: =T27+AO27 -> 0.096646587 | W27: =V27-U27 -> 0.020900366 | X27: =[1]P12CDS!B8 -> 10.048827 | Y27: =[1]P21CDS!B8 -> 0 | Z27: =H27+E27+$B$21*AN27-G27-F27-$B$22*AL27+Y27-X27 -> 0 | AA27: =L27+I27+$B$32*AN27-K27-J27-$B$33*AM27-Y27+X27 -> 6.9810824e-13 | AB27: =F27*AI27-(AI27+AO27)*E27 -> 4.1999608e-13 | AC27: =J27*AI27-(AI27+AO27)*I27 -> 1.9745247e-12 | AD27: =(U27-$B$55)*X27-(U27+$B$54)*Y27 -> 0.74859963 | AE27: =(U27-$B$55)*Y27-(U27+$B$54)*X27 -> -0.79884377 | AF27: =($B$54+$B$55)*(X27+Y27) -> 0.050244134 | AG27: =$B$22*AL27*(AI27+AO27) -> 1.6405321 | AH27: =$B$33*AM27*(AI27+AO27) -> 27.369967 | AI27: =[1]data!C7 -> 0.073826082 | AJ27: =[1]data!C31 -> 564.3 | AK27: =[1]data!C55 -> 553.8896 | AL27: =[1]data!C79 -> 0.07340619 | AM27: =[1]data!C103 -> 0.90541045 | AN27: =[1]data!C121 -> 0.04749275 | AO27: =[1]data!C139 -> 0.022820505 | AP27: P6 | AU27: 7 | AV27: : {'lambda': | AW27: 0.073826082 | AX27: =AW27-AI27 -> 0 | AY27: 0.07340619 | AZ27: =AY27-AL27 -> 0 | BA27: 0.022820505 | BB27: =BA27-AO27 -> 0 | BC27: 0.04749275 | BD27: =BC27-AN27 -> 0 | BF27: 7 | BG27: : {'lambda': | BH27: 0.073826082 | BI27: , 'Plu': | BJ27: 0.90541045 | BK27: =BJ27-AM27 -> 0 | BL27: 0.022820505 | BM27: , 'Ppvu': | BN27: 0.04749275 | BO27: },
A28: R_d1 / 0.2/ | B28: =[1]R_d1!$A$1 -> 0.2 | D28: 8 | E28: 0 | F28: =[1]Ps1!B9 -> 7.4506794e-12 | G28: =[1]Pc1!B9 -> 0 | H28: =[1]Pd1!B9 -> 7.4506794e-12 | I28: =[1]Pb2!B9 -> 0 | J28: =[1]Ps2!B9 -> 3.787959e-11 | K28: =[1]Pc2!B9 -> 0 | L28: =[1]Pd2!B9 -> 55.512187 | M28: =[1]SOC1!B9 -> 100 | N28: =[1]SOC2!B9 -> 140 | O28: =O27+G28*$B$25-H28/$B$26 -> 100 | P28: =O28-M28 -> 0 | Q28: =Q27+K28*$B$36-L28/$B$37 -> 140 | R28: =Q28-N28 -> 0 | S28: =U28-T28 -> 0.0060285282 | T28: =AI28 -> 0.076148795 | U28: =[1]epsilon!B9 -> 0.082177323 | V28: =T28+AO28 -> 0.0989693 | W28: =V28-U28 -> 0.016791977 | X28: =[1]P12CDS!B9 -> 94.044604 | Y28: =[1]P21CDS!B9 -> 0 | Z28: =H28+E28+$B$21*AN28-G28-F28-$B$22*AL28+Y28-X28 -> 0 | AA28: =L28+I28+$B$32*AN28-K28-J28-$B$33*AM28-Y28+X28 -> 0 | AB28: =F28*AI28-(AI28+AO28)*E28 -> 5.6736025e-13 | AC28: =J28*AI28-(AI28+AO28)*I28 -> 2.8844851e-12 | AD28: =(U28-$B$55)*X28-(U28+$B$54)*Y28 -> 7.610778 | AE28: =(U28-$B$55)*Y28-(U28+$B$54)*X28 -> -8.081001 | AF28: =($B$54+$B$55)*(X28+Y28) -> 0.47022302 | AG28: =$B$22*AL28*(AI28+AO28) -> 1.9571111 | AH28: =$B$33*AM28*(AI28+AO28) -> 30.639337 | AI28: =[1]data!C8 -> 0.076148795 | AJ28: =[1]data!C32 -> 564.3 | AK28: =[1]data!C56 -> 553.8896 | AL28: =[1]data!C80 -> 0.085516409 | AM28: =[1]data!C104 -> 0.98977531 | AN28: =[1]data!C122 -> 0.20003433 | AO28: =[1]data!C140 -> 0.022820505 | AP28: P6 | AU28: 8 | AV28: : {'lambda': | AW28: 0.076148795 | AX28: =AW28-AI28 -> 0 | AY28: 0.085516409 | AZ28: =AY28-AL28 -> 0 | BA28: 0.022820505 | BB28: =BA28-AO28 -> 0 | BC28: 0.20003433 | BD28: =BC28-AN28 -> 0 | BF28: 8 | BG28: : {'lambda': | BH28: 0.076148795 | BI28: , 'Plu': | BJ28: 0.98977531 | BK28: =BJ28-AM28 -> 0 | BL28: 0.022820505 | BM28: , 'Ppvu': | BN28: 0.20003433 | BO28: },
A29: DoD1 / 0.9/ | B29: =[1]DoD1!$A$1 -> 0.9 | D29: 9 | E29: 0 | F29: =[1]Ps1!B10 -> 4.6729527e-12 | G29: =[1]Pc1!B10 -> 0 | H29: =[1]Pd1!B10 -> 4.6729527e-12 | I29: =[1]Pb2!B10 -> 7.9322603 | J29: =[1]Ps2!B10 -> 0 | K29: =[1]Pc2!B10 -> 0 | L29: =[1]Pd2!B10 -> 8.7419565e-11 | M29: =[1]SOC1!B10 -> 100 | N29: =[1]SOC2!B10 -> 140 | O29: =O28+G29*$B$25-H29/$B$26 -> 100 | P29: =O29-M29 -> 0 | Q29: =Q28+K29*$B$36-L29/$B$37 -> 140 | R29: =Q29-N29 -> 0 | S29: =U29-T29 -> 0.0034144786 | T29: =AI29 -> 0.069382712 | U29: =[1]epsilon!B10 -> 0.072797191 | V29: =T29+AO29 -> 0.090457084 | W29: =V29-U29 -> 0.017659893 | X29: =[1]P12CDS!B10 -> 7.2957662 | Y29: =[1]P21CDS!B10 -> 0 | Z29: =H29+E29+$B$21*AN29-G29-F29-$B$22*AL29+Y29-X29 -> 0 | AA29: =L29+I29+$B$32*AN29-K29-J29-$B$33*AM29-Y29+X29 -> 0 | AB29: =F29*AI29-(AI29+AO29)*E29 -> 3.2422214e-13 | AC29: =J29*AI29-(AI29+AO29)*I29 -> -0.71752913 | AD29: =(U29-$B$55)*X29-(U29+$B$54)*Y29 -> 0.52199157 | AE29: =(U29-$B$55)*Y29-(U29+$B$54)*X29 -> -0.5584704 | AF29: =($B$54+$B$55)*(X29+Y29) -> 0.036478831 | AG29: =$B$22*AL29*(AI29+AO29) -> 18.483978 | AH29: =$B$33*AM29*(AI29+AO29) -> 28.29338 | AI29: =[1]data!C9 -> 0.069382712 | AJ29: =[1]data!C33 -> 338.05515 | AK29: =[1]data!C57 -> 379.4978 | AL29: =[1]data!C81 -> 0.88366434 | AM29: =[1]data!C105 -> 1 | AN29: =[1]data!C123 -> 0.37194292 | AO29: =[1]data!C141 -> 0.021074371 | AP29: P5 | AQ29: =kappaP5*AJ29 -> 653.39638 | AR29: =kappaP5*AK29 -> 733.49714 | AU29: 9 | AV29: : {'lambda': | AW29: 0.069382712 | AX29: =AW29-AI29 -> 0 | AY29: 0.88366434 | AZ29: =AY29-AL29 -> 0 | BA29: 0.021074371 | BB29: =BA29-AO29 -> 0 | BC29: 0.37194292 | BD29: =BC29-AN29 -> 0 | BF29: 9 | BG29: : {'lambda': | BH29: 0.069382712 | BI29: , 'Plu': | BJ29: 1 | BK29: =BJ29-AM29 -> 0 | BL29: 0.021074371 | BM29: , 'Ppvu': | BN29: 0.37194292 | BO29: },
A30: Pmax1 / 600/ | B30: =[1]Pmax1!$A$1 -> 600 | D30: 10 | E30: 0 | F30: =[1]Ps1!B11 -> 6.2370997e-11 | G30: =[1]Pc1!B11 -> 60.192606 | H30: =[1]Pd1!B11 -> 0 | I30: =[1]Pb2!B11 -> 0 | J30: =[1]Ps2!B11 -> 2.4385773e-10 | K30: =[1]Pc2!B11 -> 103.18097 | L30: =[1]Pd2!B11 -> 0 | M30: =[1]SOC1!B11 -> 155.97912 | N30: =[1]SOC2!B11 -> 234.9265 | O30: =O29+G30*$B$25-H30/$B$26 -> 155.97912 | P30: =O30-M30 -> 0 | Q30: =Q29+K30*$B$36-L30/$B$37 -> 234.9265 | R30: =Q30-N30 -> 0 | S30: =U30-T30 -> 0 | T30: =AI30 -> 0.056760082 | U30: =[1]epsilon!B11 -> 0.056760082 | V30: =T30+AO30 -> 0.08874843 | W30: =V30-U30 -> 0.031988348 | X30: =[1]P12CDS!B11 -> 0 | Y30: =[1]P21CDS!B11 -> 0 | Z30: =H30+E30+$B$21*AN30-G30-F30-$B$22*AL30+Y30-X30 -> 2.8421709e-14 | AA30: =L30+I30+$B$32*AN30-K30-J30-$B$33*AM30-Y30+X30 -> 8.5265128e-13 | AB30: =F30*AI30-(AI30+AO30)*E30 -> 3.5401829e-12 | AC30: =J30*AI30-(AI30+AO30)*I30 -> 1.3841385e-11 | AD30: =(U30-$B$55)*X30-(U30+$B$54)*Y30 -> 0 | AE30: =(U30-$B$55)*Y30-(U30+$B$54)*X30 -> 0 | AF30: =($B$54+$B$55)*(X30+Y30) -> 0 | AG30: =$B$22*AL30*(AI30+AO30) -> 20.522309 | AH30: =$B$33*AM30*(AI30+AO30) -> 27.207431 | AI30: =[1]data!C10 -> 0.056760082 | AJ30: =[1]data!C34 -> 404.47 | AK30: =[1]data!C58 -> 494.172 | AL30: =[1]data!C82 -> 1 | AM30: =[1]data!C106 -> 0.98013208 | AN30: =[1]data!C124 -> 0.51218625 | AO30: =[1]data!C142 -> 0.031988348 | AP30: P3 | AQ30: =kappaP3*AJ30 -> 2652.9875 | AR30: =kappaP3*AK30 -> 3241.3582 | AU30: 10 | AV30: : {'lambda': | AW30: 0.056760082 | AX30: =AW30-AI30 -> 0 | AY30: 1 | AZ30: =AY30-AL30 -> 0 | BA30: 0.031988348 | BB30: =BA30-AO30 -> 0 | BC30: 0.51218625 | BD30: =BC30-AN30 -> 0 | BF30: 10 | BG30: : {'lambda': | BH30: 0.056760082 | BI30: , 'Plu': | BJ30: 0.98013208 | BK30: =BJ30-AM30 -> 0 | BL30: 0.031988348 | BM30: , 'Ppvu': | BN30: 0.51218625 | BO30: },
A31: Capacity01 /-31713.9/ | B31: =[1]Capacity01!$A$1 -> -31713.9 | D31: 11 | E31: 0 | F31: =[1]Ps1!B12 -> 4.1836731e-11 | G31: =[1]Pc1!B12 -> 120.64991 | H31: =[1]Pd1!B12 -> 0 | I31: =[1]Pb2!B12 -> 0 | J31: =[1]Ps2!B12 -> 6.8423084e-11 | K31: =[1]Pc2!B12 -> 184.54189 | L31: =[1]Pd2!B12 -> 0 | M31: =[1]SOC1!B12 -> 268.18354 | N31: =[1]SOC2!B12 -> 404.70504 | O31: =O30+G31*$B$25-H31/$B$26 -> 268.18354 | P31: =O31-M31 -> 0 | Q31: =Q30+K31*$B$36-L31/$B$37 -> 404.70504 | R31: =Q31-N31 -> 1.4438228e-11 | S31: =U31-T31 -> 0 | T31: =AI31 -> 0.04694937 | U31: =[1]epsilon!B12 -> 0.04694937 | V31: =T31+AO31 -> 0.069140017 | W31: =V31-U31 -> 0.022190647 | X31: =[1]P12CDS!B12 -> 0 | Y31: =[1]P21CDS!B12 -> 0 | Z31: =H31+E31+$B$21*AN31-G31-F31-$B$22*AL31+Y31-X31 -> -2.8421709e-13 | AA31: =L31+I31+$B$32*AN31-K31-J31-$B$33*AM31-Y31+X31 -> 3.1832315e-12 | AB31: =F31*AI31-(AI31+AO31)*E31 -> 1.9642082e-12 | AC31: =J31*AI31-(AI31+AO31)*I31 -> 3.2124207e-12 | AD31: =(U31-$B$55)*X31-(U31+$B$54)*Y31 -> 0 | AE31: =(U31-$B$55)*Y31-(U31+$B$54)*X31 -> 0 | AF31: =($B$54+$B$55)*(X31+Y31) -> 0 | AG31: =$B$22*AL31*(AI31+AO31) -> 15.464358 | AH31: =$B$33*AM31*(AI31+AO31) -> 20.711554 | AI31: =[1]data!C11 -> 0.04694937 | AJ31: =[1]data!C35 -> 442.91 | AK31: =[1]data!C59 -> 561.3209 | AL31: =[1]data!C83 -> 0.96724587 | AM31: =[1]data!C107 -> 0.95772528 | AN31: =[1]data!C125 -> 0.60512683 | AO31: =[1]data!C143 -> 0.022190647 | AP31: P4 | AQ31: =kappaP4*AJ31 -> 2290.7704 | AR31: =kappaP4*AK31 -> 2903.2022 | AU31: 11 | AV31: : {'lambda': | AW31: 0.04694937 | AX31: =AW31-AI31 -> 0 | AY31: 0.96724587 | AZ31: =AY31-AL31 -> 0 | BA31: 0.022190647 | BB31: =BA31-AO31 -> 0 | BC31: 0.60512683 | BD31: =BC31-AN31 -> 0 | BF31: 11 | BG31: : {'lambda': | BH31: 0.04694937 | BI31: , 'Plu': | BJ31: 0.95772528 | BK31: =BJ31-AM31 -> 0 | BL31: 0.022190647 | BM31: , 'Ppvu': | BN31: 0.60512683 | BO31: },
