Workbook

Sheet Industria_solar
A1: % | B1: Periodo | C1: P KW | D1: P KW | E1: PVsolar | F1: Q kVARr | G1: horames | H1: mes | I1: horadia | J1: DIA
A2: DBP=[ | B2: 6 | C2: =D2-E2*Solar!$C$31 -> 13.72 | D2: 13.72 | E2: =Solar!C35 -> 0 | F2: 14.25 | G2: 1 | H2: 1 | I2: 1 | J2: 1 | K2: ; | U2: Pl | V2: Ppv | W2: Pneto
B3: 6 | C3: =D3-E3*Solar!$C$31 -> 14.3 | D3: 14.3 | E3: =Solar!C36 -> 0 | F3: 16.48 | G3: =G2+1 -> 2 | H3: =H2 -> 1 | I3: 2 | J3: 1 | K3: ; | U3: =Industria!T3 -> 31.307452 | V3: =Solar!Q35 -> 0 | W3: =U3-V3 -> 31.307452
B4: 6 | C4: =D4-E4*Solar!$C$31 -> 13.76 | D4: 13.76 | E4: =Solar!C37 -> 0 | F4: 16.03 | G4: =G3+1 -> 3 | H4: =H3 -> 1 | I4: 3 | J4: 1 | K4: ; | U4: =Industria!T4 -> 20.898959 | V4: =Solar!Q36 -> 0 | W4: =U4-V4 -> 20.898959
B5: 6 | C5: =D5-E5*Solar!$C$31 -> 14.47 | D5: 14.47 | E5: =Solar!C38 -> 0 | F5: 17.56 | G5: =G4+1 -> 4 | H5: =H4 -> 1 | I5: 4 | J5: 1 | K5: ; | U5: =Industria!T5 -> 17.653808 | V5: =Solar!Q37 -> 0 | W5: =U5-V5 -> 17.653808
B6: 6 | C6: =D6-E6*Solar!$C$31 -> 13.89 | D6: 13.89 | E6: =Solar!C39 -> 0 | F6: 16.24 | G6: =G5+1 -> 5 | H6: =H5 -> 1 | I6: 5 | J6: 1 | K6: ; | U6: =Industria!T6 -> 17.394959 | V6: =Solar!Q38 -> 0 | W6: =U6-V6 -> 17.394959
B7: 6 | C7: =D7-E7*Solar!$C$31 -> 14.18 | D7: 14.18 | E7: =Solar!C40 -> 0 | F7: 15.98 | G7: =G6+1 -> 6 | H7: =H6 -> 1 | I7: 6 | J7: 1 | K7: ; | U7: =Industria!T7 -> 17.182986 | V7: =Solar!Q39 -> 0 | W7: =U7-V7 -> 17.182986
B8: 6 | C8: =D8-E8*Solar!$C$31 -> 2.206867 | D8: 13.79 | E8: =Solar!C41 -> 0.020357 | F8: 14.98 | G8: =G7+1 -> 7 | H8: =H7 -> 1 | I8: 7 | J8: 1 | K8: ; | U8: =Industria!T8 -> 16.905041 | V8: =Solar!Q40 -> 0 | W8: =U8-V8 -> 16.905041
B9: 6 | C9: =D9-E9*Solar!$C$31 -> -95.032172 | D9: 13.64 | E9: =Solar!C42 -> 0.190988 | F9: 15.62 | G9: =G8+1 -> 8 | H9: =H8 -> 1 | I9: 8 | J9: 1 | K9: ; | U9: =Industria!T9 -> 16.974548 | V9: =Solar!Q41 -> 27.023375 | W9: =U9-V9 -> -10.048827
B10: 6 | C10: =D10-E10*Solar!$C$31 -> -212.45615 | D10: 14.44 | E10: =Solar!C43 -> 0.398763 | F10: 12.95 | G10: =G9+1 -> 9 | H10: =H9 -> 1 | I10: 9 | J10: 1 | K10: ; | U10: =Industria!T10 -> 19.774932 | V10: =Solar!Q42 -> 113.81954 | W10: =U10-V10 -> -94.044604
B11: 6 | C11: =D11-E11*Solar!$C$31 -> -308.59945 | D11: 15.19 | E11: =Solar!C44 -> 0.56905 | F11: 0 | G11: =G10+1 -> 10 | H11: =H10 -> 1 | I11: 10 | J11: 1 | K11: ; | U11: =Industria!T11 -> 204.33975 | V11: =Solar!Q43 -> 211.63552 | W11: =U11-V11 -> -7.2957662
B12: 6 | C12: =D12-E12*Solar!$C$31 -> -372.99433 | D12: 15.59 | E12: =Solar!C45 -> 0.682925 | F12: 0 | G12: =G11+1 -> 11 | H12: =H11 -> 1 | I12: 11 | J12: 1 | K12: ; | U12: =Industria!T12 -> 231.24137 | V12: =Solar!Q44 -> 291.43398 | W12: =U12-V12 -> -60.192606
B13: 6 | C13: =D13-E13*Solar!$C$31 -> -411.16005 | D13: 14.44 | E13: =Solar!C46 -> 0.747979 | F13: 0 | G13: =G12+1 -> 12 | H13: =H12 -> 1 | I13: 12 | J13: 1 | K13: ; | U13: =Industria!T13 -> 223.66726 | V13: =Solar!Q45 -> 344.31717 | W13: =U13-V13 -> -120.64991
B14: 6 | C14: =D14-E14*Solar!$C$31 -> -416.68385 | D14: 15.19 | E14: =Solar!C47 -> 0.759005 | F14: 0 | G14: =G13+1 -> 13 | H14: =H13 -> 1 | I14: 13 | J14: 1 | K14: ; | U14: =Industria!T14 -> 223.47403 | V14: =Solar!Q46 -> 367.1813 | W14: =U14-V14 -> -143.70727
... B16: 6 | C16: =D16-E16*Solar!$C$31 -> -333.32974 | D16: 15.16 | E16: =Solar!C49 -> 0.61246 | F16: 0 | G16: =G15+1 -> 15 | H16: =H15 -> 1 | I16: 15 | J16: 1 | K16: ; | U16: =Industria!T16 -> 206.30877 | V16: =Solar!Q48 -> 323.64715 | W16: =U16-V16 -> -117.33839
B17: 6 | C17: =D17-E17*Solar!$C$31 -> -242.53092 | D17: 15.58 | E17: =Solar!C50 -> 0.453622 | F17: 0 | G17: =G16+1 -> 16 | H17: =H16 -> 1 | I17: 16 | J17: 1 | K17: ; | N17: Eactiva | O17: =SUM(C2:C8761) -> 4135.6146 | P17: kWh | U17: =Industria!T17 -> 224.04178 | V17: =Solar!Q49 -> 269.25379 | W17: =U17-V17 -> -45.212006
B18: 6 | C18: =D18-E18*Solar!$C$31 -> -129.10087 | D18: 15.49 | E18: =Solar!C51 -> 0.254114 | F18: 0 | G18: =G17+1 -> 17 | H18: =H17 -> 1 | I18: 17 | J18: 1 | K18: ; | N18: Ereactiva | O18: =SUM(F2:F8761) -> 456759.84 | P18: kWh | U18: =Industria!T18 -> 221.80392 | V18: =Solar!Q50 -> 191.84485 | W18: =U18-V18 -> 29.959072
B19: 6 | C19: =D19-E19*Solar!$C$31 -> -14.502107 | D19: 14.86 | E19: =Solar!C52 -> 0.051603 | F19: 0 | G19: =G18+1 -> 18 | H19: =H18 -> 1 | I19: 18 | J19: 1 | K19: ; | N19: cosf | O19: =COS(ATAN(O18/O17)) -> 0.009053872 | P19: kWh | U19: =Industria!T19 -> 219.05268 | V19: =Solar!Q51 -> 107.29638 | W19: =U19-V19 -> 111.75631
B20: 6 | C20: =D20-E20*Solar!$C$31 -> 15.16 | D20: 15.16 | E20: =Solar!C53 -> 0 | F20: 0 | G20: =G19+1 -> 19 | H20: =H19 -> 1 | I20: 19 | J20: 1 | K20: ; | N20: maxP | O20: =MAX(C2:C8761) -> 564.3 | P20: kWh | U20: =Industria!T20 -> 149.68 | V20: =Solar!Q52 -> 24.759229 | W20: =U20-V20 -> 124.92077
B21: 6 | C21: =D21-E21*Solar!$C$31 -> 14.9 | D21: 14.9 | E21: =Solar!C54 -> 0 | F21: 0 | G21: =G20+1 -> 20 | H21: =H20 -> 1 | I21: 20 | J21: 1 | K21: ; | N21: FC | O21: =O17/8760/O20 -> 0.0008366155 | R21: P6 | S21: =MAX(C2:C8745) -> 564.3 | U21: =Industria!T21 -> 145.21233 | V21: =Solar!Q53 -> 0 | W21: =U21-V21 -> 145.21233
B22: 6 | C22: =D22-E22*Solar!$C$31 -> 15.54 | D22: 15.54 | E22: =Solar!C55 -> 0 | F22: 0 | G22: =G21+1 -> 21 | H22: =H21 -> 1 | I22: 21 | J22: 1 | K22: ; | U22: =Industria!T22 -> 152.46567 | V22: =Solar!Q54 -> 0 | W22: =U22-V22 -> 152.46567
B23: 6 | C23: =D23-E23*Solar!$C$31 -> 14.87 | D23: 14.87 | E23: =Solar!C56 -> 0 | F23: 0 | G23: =G22+1 -> 22 | H23: =H22 -> 1 | I23: 22 | J23: 1 | K23: ; | U23: =Industria!T23 -> 134.48767 | V23: =Solar!Q55 -> 0 | W23: =U23-V23 -> 134.48767
B24: 6 | C24: =D24-E24*Solar!$C$31 -> 14 | D24: 14 | E24: =Solar!C57 -> 0 | F24: 12.74 | G24: =G23+1 -> 23 | H24: =H23 -> 1 | I24: 23 | J24: 1 | K24: ; | U24: =Industria!T24 -> 41.442603 | V24: =Solar!Q56 -> 0 | W24: =U24-V24 -> 41.442603
B25: 6 | C25: =D25-E25*Solar!$C$31 -> 13.86 | D25: 13.86 | E25: =Solar!C58 -> 0 | F25: 13.79 | G25: =G24+1 -> 24 | H25: =H24 -> 1 | I25: 24 | J25: 1 | K25: ; | U25: =Industria!T25 -> 33.502959 | V25: =Solar!Q57 -> 0 | W25: =U25-V25 -> 33.502959
B26: 6 | C26: =D26-E26*Solar!$C$31 -> 13.68 | D26: 13.68 | E26: =Solar!C59 -> 0 | F26: 14.98 | G26: =G25+1 -> 25 | H26: =H25 -> 1 | I26: =I2 -> 1 | J26: =J2+1 -> 2 | K26: ; | U26: =Industria!T26 -> 31.920795 | V26: =Solar!Q58 -> 0 | W26: =U26-V26 -> 31.920795
B27: 6 | C27: =D27-E27*Solar!$C$31 -> 14.41 | D27: 14.41 | E27: =E2 -> 0 | F27: 17.03 | G27: =G26+1 -> 26 | H27: =H26 -> 1 | I27: =I3 -> 2 | J27: =J3+1 -> 2 | K27: ; | U27: =SUM(U3:U26) -> 2629.1417 | V27: =SUM(V3:V26) -> 2629.1219 | W27: =SUM(W3:W26) -> 0.019797066
B28: 6 | C28: =D28-E28*Solar!$C$31 -> 13.83 | D28: 13.83 | E28: =E3 -> 0 | F28: 15.99 | G28: =G27+1 -> 27 | H28: =H27 -> 1 | I28: =I4 -> 3 | J28: =J4+1 -> 2 | K28: ; | U28: =Industria!$T$28 -> kWh/dia | V28: =Industria!$T$28 -> kWh/dia | W28: =Industria!$T$28 -> kWh/dia | Y28: Exc1 | Z28: =SUM(W9:W17) -> -926.99159
B29: 6 | C29: =D29-E29*Solar!$C$31 -> 14.4 | D29: 14.4 | E29: =E4 -> 0 | F29: 16.73 | G29: =G28+1 -> 28 | H29: =H28 -> 1 | I29: =I5 -> 4 | J29: =J5+1 -> 2 | K29: ; | U29: =U27*365 -> 959636.71 | V29: =V27*365 -> 959629.48 | W29: =W27*365 -> 7.2259292 | Y29: Imp | Z29: =SUM(W3:W8,W18:W26) -> 927.01138
B30: 6 | C30: =D30-E30*Solar!$C$31 -> 13.76 | D30: 13.76 | E30: =E5 -> 0 | F30: 15.01 | G30: =G29+1 -> 29 | H30: =H29 -> 1 | I30: =I6 -> 5 | J30: =J6+1 -> 2 | K30: ; | U30: =Industria!$T$30 -> kWh/año | V30: =Industria!$T$30 -> kWh/año | W30: =Industria!$T$30 -> kWh/año
B31: 6 | C31: =D31-E31*Solar!$C$31 -> 14.04 | D31: 14.04 | E31: =E6 -> 0 | F31: 15.23 | G31: =G30+1 -> 30 | H31: =H30 -> 1 | I31: =I7 -> 6 | J31: =J7+1 -> 2 | K31: ; | U31: share | V31: 0.76071027
B32: 6 | C32: =D32-E32*Solar!$C$31 -> 13.86 | D32: 13.86 | E32: =E7 -> 0 | F32: 14.44 | G32: =G31+1 -> 31 | H32: =H31 -> 1 | I32: =I8 -> 7 | J32: =J8+1 -> 2 | K32: ;
B33: 6 | C33: =D33-E33*Solar!$C$31 -> 11.026867 | D33: 22.61 | E33: =E8 -> 0.020357 | F33: 17.39 | G33: =G32+1 -> 32 | H33: =H32 -> 1 | I33: =I9 -> 8 | J33: =J9+1 -> 2 | K33: ; | U33: C-Rate | V33: 0.2 | W33: 1/h
B34: 2 | C34: =D34-E34*Solar!$C$31 -> 74.797828 | D34: 183.47 | E34: =E9 -> 0.190988 | F34: 95.34 | G34: =G33+1 -> 33 | H34: =H33 -> 1 | I34: =I10 -> 9 | J34: =J10+1 -> 2 | K34: ; | U34: BESS | V34: =V27*$V$31 -> 2000 | W34: kWh | X34: 200 | Y34: USD/kWh | AA34: =1.25*(U29/365-U12*Solar!O30) -> 1950.8345
B35: 1 | C35: =D35-E35*Solar!$C$31 -> -17.856147 | D35: 209.04 | E35: =E10 -> 0.398763 | F35: 22.26 | G35: =G34+1 -> 34 | H35: =H34 -> 1 | I35: =I11 -> 10 | J35: =J11+1 -> 2 | K35: ; | U35: Inversor | V35: =V34*V33 -> 400 | W35: kW | X35: 80 | Y35: USD/kWp
B36: 1 | C36: =D36-E36*Solar!$C$31 -> -57.99945 | D36: 265.79 | E36: =E11 -> 0.56905 | F36: 73.76 | G36: =G35+1 -> 35 | H36: =H35 -> 1 | I36: =I12 -> 11 | J36: =J12+1 -> 2 | K36: ; | U36: Capacitor | X36: 300 | Y36: USD/kvarh
B37: 1 | C37: =D37-E37*Solar!$C$31 -> 98.565675 | D37: 487.15 | E37: =E12 -> 0.682925 | F37: 269.68 | G37: =G36+1 -> 36 | H37: =H36 -> 1 | I37: =I13 -> 12 | J37: =J13+1 -> 2 | K37: ; | U37: n | V37: 20
B38: 1 | C38: =D38-E38*Solar!$C$31 -> -381.65005 | D38: 43.95 | E38: =E13 -> 0.747979 | F38: 5.54 | G38: =G37+1 -> 37 | H38: =H37 -> 1 | I38: =I14 -> 13 | J38: =J14+1 -> 2 | K38: ; | U38: discount rate | V38: 0.05
B39: 1 | C39: =D39-E39*Solar!$C$31 -> -21.293845 | D39: 410.58 | E39: =E14 -> 0.759005 | F39: 167.22 | G39: =G38+1 -> 38 | H39: =H38 -> 1 | I39: =I15 -> 14 | J39: =J15+1 -> 2 | K39: ; | U39: CRF | V39: =(V38*(1+V38)^V37)/((1+V38)^V37-1) -> 0.080242587
B40: 2 | C40: =D40-E40*Solar!$C$31 -> 71.522286 | D40: 478.19 | E40: =E15 -> 0.714706 | F40: 197.25 | G40: =G39+1 -> 39 | H40: =H39 -> 1 | I40: =I16 -> 15 | J40: =J16+1 -> 2 | K40: ;
B41: 2 | C41: =D41-E41*Solar!$C$31 -> 125.69026 | D41: 474.18 | E41: =E16 -> 0.61246 | F41: 210.88 | G41: =G40+1 -> 40 | H41: =H40 -> 1 | I41: =I17 -> 16 | J41: =J17+1 -> 2 | K41: ;
...

Sheet Solar
C1: Radiación Solar Barranquilla Colombia (W/m2) | Z1: Solar=[ | AA1: 0
B2: Hora | C2: Enero | D2: Febrero | E2: Marzo | F2: Abril | G2: Mayo | H2: Junio | I2: Julio | J2: Agosto | K2: Septiembre | L2: Octubre | M2: Noviembre | N2: Diciembre | O2: Anual | AA2: 0
B3: 0-1 | C3: 0 | D3: 0 | E3: 0 | F3: 0 | G3: 0 | H3: 0 | I3: 0 | J3: 0 | K3: 0 | L3: 0 | M3: 0 | N3: 0 | O3: =SUM(C3:N3)/12 -> 0 | AA3: 0
B4: 1-2 | C4: 0 | D4: 0 | E4: 0 | F4: 0 | G4: 0 | H4: 0 | I4: 0 | J4: 0 | K4: 0 | L4: 0 | M4: 0 | N4: 0 | O4: =SUM(C4:N4)/12 -> 0 | AA4: 0
B5: 2-3 | C5: 0 | D5: 0 | E5: 0 | F5: 0 | G5: 0 | H5: 0 | I5: 0 | J5: 0 | K5: 0 | L5: 0 | M5: 0 | N5: 0 | O5: =SUM(C5:N5)/12 -> 0 | AA5: 0
B6: 3-4 | C6: 0 | D6: 0 | E6: 0 | F6: 0 | G6: 0 | H6: 0 | I6: 0 | J6: 0 | K6: 0 | L6: 0 | M6: 0 | N6: 0 | O6: =SUM(C6:N6)/12 -> 0 | AA6: 0
B7: 4-5 | C7: 0 | D7: 0 | E7: 0 | F7: 0 | G7: 0 | H7: 0 | I7: 0 | J7: 0 | K7: 0 | L7: 0 | M7: 0 | N7: 0 | O7: =SUM(C7:N7)/12 -> 0 | AA7: 0.01868549
B8: 5-6 | C8: 0 | D8: 0 | E8: 0 | F8: 0 | G8: 0 | H8: 0 | I8: 0 | J8: 0 | K8: 0 | L8: 0 | M8: 0 | N8: 0 | O8: =SUM(C8:N8)/12 -> 0 | AA8: 0.20628495
B9: 6-7 | C9: 20.357 | D9: 20.543 | E9: 31.782 | F9: 55.481 | G9: 64.172 | H9: 58.89 | I9: 50.474 | J9: 48.843 | K9: 58.322 | L9: 66.269 | M9: 58.896 | N9: 35.884 | O9: =SUM(C9:N9)/12 -> 47.49275 | AA9: 0.38181646
B10: 7-8 | C10: 190.988 | D10: 184.02 | E10: 189.409 | F10: 206.054 | G10: 200.488 | H10: 186.504 | I10: 179.666 | J10: 187.467 | K10: 209.229 | L10: 221.332 | M10: 228.172 | N10: 217.083 | O10: =SUM(C10:N10)/12 -> 200.03433 | AA10: 0.64670496
B11: 8-9 | C11: 398.763 | D11: 390.336 | E11: 375.542 | F11: 373.465 | G11: 351.892 | H11: 333.701 | I11: 334.888 | J11: 349.864 | K11: 375.701 | L11: 380.665 | M11: 391.954 | N11: 406.544 | O11: =SUM(C11:N11)/12 -> 371.94292 | AA11: 0.60207818
B12: 9-10 | C12: 569.05 | D12: 566.527 | E12: 541.102 | F12: 512.12 | G12: 473.209 | H12: 455.262 | I12: 461.369 | J12: 481.927 | K12: 508.508 | L12: 507.907 | M12: 513.563 | N12: 555.691 | O12: =SUM(C12:N12)/12 -> 512.18625 | AA12: 0.81653296
B13: 10-11 | C13: 682.925 | D13: 691.05 | E13: 662.525 | F13: 616.135 | G13: 549.467 | H13: 529.646 | I13: 545.598 | J13: 571.244 | K13: 593.876 | L13: 580.992 | M13: 583.576 | N13: 654.488 | O13: =SUM(C13:N13)/12 -> 605.12683 | AA13: 0.79500341
B14: 11-12 | C14: 747.979 | D14: 763.145 | E14: 732.451 | F14: 659.94 | G14: 592.453 | H14: 572.882 | I14: 595.067 | J14: 600.116 | K14: 611.408 | L14: 583.116 | M14: 589.782 | N14: 695.379 | O14: =SUM(C14:N14)/12 -> 645.30983 | AA14: 0.72534318
... B26: 23-0 | C26: 0 | D26: 0 | E26: 0 | F26: 0 | G26: 0 | H26: 0 | I26: 0 | J26: 0 | K26: 0 | L26: 0 | M26: 0 | N26: 0 | O26: =SUM(C26:N26)/12 -> 0 | AA26: 0
AA27: 0
C28: Enero | D28: Febrero | E28: Marzo | F28: Abril | G28: Mayo | H28: Junio | I28: Julio | J28: Agosto | K28: Septiembre | L28: Octubre | M28: Noviembre | N28: Diciembre | O28: Anual | Q28: Radiación Maxima | T28: 1000 | U28: W/m2 | AA28: 0
B29: Wh/dia | C29: =SUM(C3:C26) -> 5455.572 | D29: =SUM(D3:D26) -> 5611.915 | E29: =SUM(E3:E26) -> 5318.778 | F29: =SUM(F3:F26) -> 4793.967 | G29: =SUM(G3:G26) -> 4121.627 | H29: =SUM(H3:H26) -> 4052.017 | I29: =SUM(I3:I26) -> 4270.764 | J29: =SUM(J3:J26) -> 4288.104 | ... O29: =SUM(O3:O26) -> 4620.6008 | Q29: Potencia Panel Monocristalino | T29: 0.55 | U29: kW | AA29: 0
B30: HPS horas | C30: =C29/1000 -> 5.455572 | D30: =D29/1000 -> 5.611915 | E30: =E29/1000 -> 5.318778 | F30: =F29/1000 -> 4.793967 | G30: =G29/1000 -> 4.121627 | H30: =H29/1000 -> 4.052017 | I30: =I29/1000 -> 4.270764 | J30: =J29/1000 -> 4.288104 | ... O30: =O29/1000 -> 4.6206008 | Q30: numero de paneles | T30: =C31/T29 -> 1034.5455 | AA30: 0
B31: Pot PV kW | C31: 569 | D31: 700 | E31: USD/kWp | AA31: 0.01972418
B32: Area m2 | C32: =2.278*1.134*ROUND(C31,1) -> 1469.8704 | AA32: 0.16014262
AA33: 0.42023741
B34: Hora | C34: Enero | D34: Febrero | E34: Marzo | F34: Abril | G34: Mayo | H34: Junio | I34: Julio | J34: Agosto | K34: Septiembre | L34: Octubre | M34: Noviembre | N34: Diciembre | P34: Equiv | Q34: Energía kWh/dia | AA34: 0.63114733
B35: 0-1 | C35: =C3/$T$28 -> 0 | D35: =D3/$T$28 -> 0 | E35: =E3/$T$28 -> 0 | F35: =F3/$T$28 -> 0 | G35: =G3/$T$28 -> 0 | H35: =H3/$T$28 -> 0 | I35: =I3/$T$28 -> 0 | J35: =J3/$T$28 -> 0 | ... N35: =N3/$T$28 -> 0 | P35: =AVERAGE(C35:N35) -> 0 | Q35: =P35*$C$31 -> 0 | AA35: 0.64098589
B36: 1-2 | C36: =C4/$T$28 -> 0 | D36: =D4/$T$28 -> 0 | E36: =E4/$T$28 -> 0 | F36: =F4/$T$28 -> 0 | G36: =G4/$T$28 -> 0 | H36: =H4/$T$28 -> 0 | I36: =I4/$T$28 -> 0 | J36: =J4/$T$28 -> 0 | ... N36: =N4/$T$28 -> 0 | P36: =AVERAGE(C36:N36) -> 0 | Q36: =P36*$C$31 -> 0 | AA36: 0.61823829
B37: 2-3 | C37: =C5/$T$28 -> 0 | D37: =D5/$T$28 -> 0 | E37: =E5/$T$28 -> 0 | F37: =F5/$T$28 -> 0 | G37: =G5/$T$28 -> 0 | H37: =H5/$T$28 -> 0 | I37: =I5/$T$28 -> 0 | J37: =J5/$T$28 -> 0 | ... N37: =N5/$T$28 -> 0 | P37: =AVERAGE(C37:N37) -> 0 | Q37: =P37*$C$31 -> 0 | AA37: 0.82144184
B38: 3-4 | C38: =C6/$T$28 -> 0 | D38: =D6/$T$28 -> 0 | E38: =E6/$T$28 -> 0 | F38: =F6/$T$28 -> 0 | G38: =G6/$T$28 -> 0 | H38: =H6/$T$28 -> 0 | I38: =I6/$T$28 -> 0 | J38: =J6/$T$28 -> 0 | ... N38: =N6/$T$28 -> 0 | P38: =AVERAGE(C38:N38) -> 0 | Q38: =P38*$C$31 -> 0 | AA38: 0.71681402
B39: 4-5 | C39: =C7/$T$28 -> 0 | D39: =D7/$T$28 -> 0 | E39: =E7/$T$28 -> 0 | F39: =F7/$T$28 -> 0 | G39: =G7/$T$28 -> 0 | H39: =H7/$T$28 -> 0 | I39: =I7/$T$28 -> 0 | J39: =J7/$T$28 -> 0 | ... N39: =N7/$T$28 -> 0 | P39: =AVERAGE(C39:N39) -> 0 | Q39: =P39*$C$31 -> 0 | AA39: 0.73501345
B40: 5-6 | C40: =C8/$T$28 -> 0 | D40: =D8/$T$28 -> 0 | E40: =E8/$T$28 -> 0 | F40: =F8/$T$28 -> 0 | G40: =G8/$T$28 -> 0 | H40: =H8/$T$28 -> 0 | I40: =I8/$T$28 -> 0 | J40: =J8/$T$28 -> 0 | ... N40: =N8/$T$28 -> 0 | P40: =AVERAGE(C40:N40) -> 0 | Q40: =P40*$C$31 -> 0 | AA40: 0.37952172
B41: 6-7 | C41: =C9/$T$28 -> 0.020357 | D41: =D9/$T$28 -> 0.020543 | E41: =E9/$T$28 -> 0.031782 | F41: =F9/$T$28 -> 0.055481 | G41: =G9/$T$28 -> 0.064172 | H41: =H9/$T$28 -> 0.05889 | I41: =I9/$T$28 -> 0.050474 | J41: =J9/$T$28 -> 0.048843 | ... N41: =N9/$T$28 -> 0.035884 | P41: =AVERAGE(C41:N41) -> 0.04749275 | Q41: =P41*$C$31 -> 27.023375 | AA41: 0.21848483
B42: 7-8 | C42: =C10/$T$28 -> 0.190988 | D42: =D10/$T$28 -> 0.18402 | E42: =E10/$T$28 -> 0.189409 | F42: =F10/$T$28 -> 0.206054 | G42: =G10/$T$28 -> 0.200488 | H42: =H10/$T$28 -> 0.186504 | I42: =I10/$T$28 -> 0.179666 | J42: =J10/$T$28 -> 0.187467 | ... N42: =N10/$T$28 -> 0.217083 | P42: =AVERAGE(C42:N42) -> 0.20003433 | Q42: =P42*$C$31 -> 113.81954 | AA42: 0.04411807
B43: 8-9 | C43: =C11/$T$28 -> 0.398763 | D43: =D11/$T$28 -> 0.390336 | E43: =E11/$T$28 -> 0.375542 | F43: =F11/$T$28 -> 0.373465 | G43: =G11/$T$28 -> 0.351892 | H43: =H11/$T$28 -> 0.333701 | I43: =I11/$T$28 -> 0.334888 | J43: =J11/$T$28 -> 0.349864 | ... N43: =N11/$T$28 -> 0.406544 | P43: =AVERAGE(C43:N43) -> 0.37194292 | Q43: =P43*$C$31 -> 211.63552 | AA43: 0
B44: 9-10 | C44: =C12/$T$28 -> 0.56905 | D44: =D12/$T$28 -> 0.566527 | E44: =E12/$T$28 -> 0.541102 | F44: =F12/$T$28 -> 0.51212 | G44: =G12/$T$28 -> 0.473209 | H44: =H12/$T$28 -> 0.455262 | I44: =I12/$T$28 -> 0.461369 | J44: =J12/$T$28 -> 0.481927 | ... N44: =N12/$T$28 -> 0.555691 | P44: =AVERAGE(C44:N44) -> 0.51218625 | Q44: =P44*$C$31 -> 291.43398 | AA44: 0
B45: 10-11 | C45: =C13/$T$28 -> 0.682925 | D45: =D13/$T$28 -> 0.69105 | E45: =E13/$T$28 -> 0.662525 | F45: =F13/$T$28 -> 0.616135 | G45: =G13/$T$28 -> 0.549467 | H45: =H13/$T$28 -> 0.529646 | I45: =I13/$T$28 -> 0.545598 | J45: =J13/$T$28 -> 0.571244 | ... N45: =N13/$T$28 -> 0.654488 | P45: =AVERAGE(C45:N45) -> 0.60512683 | Q45: =P45*$C$31 -> 344.31717 | AA45: 0
B46: 11-12 | C46: =C14/$T$28 -> 0.747979 | D46: =D14/$T$28 -> 0.763145 | E46: =E14/$T$28 -> 0.732451 | F46: =F14/$T$28 -> 0.65994 | G46: =G14/$T$28 -> 0.592453 | H46: =H14/$T$28 -> 0.572882 | I46: =I14/$T$28 -> 0.595067 | J46: =J14/$T$28 -> 0.600116 | ... N46: =N14/$T$28 -> 0.695379 | P46: =AVERAGE(C46:N46) -> 0.64530983 | Q46: =P46*$C$31 -> 367.1813 | AA46: 0
... B58: 23-0 | C58: =C26/$T$28 -> 0 | D58: =D26/$T$28 -> 0 | E58: =E26/$T$28 -> 0 | F58: =F26/$T$28 -> 0 | G58: =G26/$T$28 -> 0 | H58: =H26/$T$28 -> 0 | I58: =I26/$T$28 -> 0 | J58: =J26/$T$28 -> 0 | ... N58: =N26/$T$28 -> 0 | P58: =AVERAGE(C58:N58) -> 0 | Q58: =P58*$C$31 -> 0 | AA58: 0.62443246
P59: =AVERAGE(P35:P58) -> 0.19252503 | Q59: =P59*$C$31 -> 109.54674 | AA59: 0.62869028
O60: Energia kWh/dia | Q60: =SUM(Q35:Q59) -> 2738.6686 | R60: kWh | S60: =Q60*365 -> 999614.05 | AA60: 0.74361764
O61: Enrgia = Ppv*HPS = | Q61: =C31*AVERAGE(C30:N30) -> 2629.1219 | R61: kWh | AA61: 0.67877602
P62: HPS= | Q62: =AVERAGE(C30:N30) -> 4.6206008 | AA62: 0.63911123
...

Sheet Industria
A1: % | B1: Periodo | C1: P KW | D1: Q kVARr | E1: horames | F1: mes | G1: horadia | H1: DIA | T1: P | V1: ©
A2: DBP=[ | B2: 6 | C2: 13.72 | D2: 14.25 | E2: 1 | F2: 1 | G2: 1 | H2: 1 | I2: ; | T2: kWh | U2: Fc | V2: kVArh
B3: 6 | C3: 14.3 | D3: 16.48 | E3: =E2+1 -> 2 | F3: =F2 -> 1 | G3: 2 | H3: 1 | I3: ; | S3: 0 | T3: =$Q$17*U3 -> 31.307452 | U3: 0.13538863 | V3: 27.875151
B4: 6 | C4: 13.76 | D4: 16.03 | E4: =E3+1 -> 3 | F4: =F3 -> 1 | G4: 3 | H4: 1 | I4: ; | S4: 1 | T4: =$Q$17*U4 -> 20.898959 | U4: 0.090377249 | V4: 22.371534
B5: 6 | C5: 14.47 | D5: 17.56 | E5: =E4+1 -> 4 | F5: =F4 -> 1 | G5: 4 | H5: 1 | I5: ; | S5: 2 | T5: =$Q$17*U5 -> 17.653808 | U5: 0.076343641 | V5: 20.669616
B6: 6 | C6: 13.89 | D6: 16.24 | E6: =E5+1 -> 5 | F6: =F5 -> 1 | G6: 5 | H6: 1 | I6: ; | S6: 3 | T6: =$Q$17*U6 -> 17.394959 | U6: 0.075224251 | V6: 20.802712
B7: 6 | C7: 14.18 | D7: 15.98 | E7: =E6+1 -> 6 | F7: =F6 -> 1 | G7: 6 | H7: 1 | I7: ; | S7: 4 | T7: =$Q$17*U7 -> 17.182986 | U7: 0.074307579 | V7: 20.762822
B8: 6 | C8: 13.79 | D8: 14.98 | E8: =E7+1 -> 7 | F8: =F7 -> 1 | G8: 7 | H8: 1 | I8: ; | S8: 5 | T8: =$Q$17*U8 -> 16.905041 | U8: 0.073105609 | V8: 20.711205
B9: 6 | C9: 13.64 | D9: 15.62 | E9: =E8+1 -> 8 | F9: =F8 -> 1 | G9: 8 | H9: 1 | I9: ; | S9: 6 | T9: =$Q$17*U9 -> 16.974548 | U9: 0.07340619 | V9: 20.580986
B10: 6 | C10: 14.44 | D10: 12.95 | E10: =E9+1 -> 9 | F10: =F9 -> 1 | G10: 9 | H10: 1 | I10: ; | S10: 7 | T10: =$Q$17*U10 -> 19.774932 | U10: 0.085516409 | V10: 21.413726
B11: 6 | C11: 15.19 | D11: 0 | E11: =E10+1 -> 10 | F11: =F10 -> 1 | G11: 10 | H11: 1 | I11: ; | S11: 8 | T11: =$Q$17*U11 -> 204.33975 | U11: 0.88366434 | V11: 141.48904
B12: 6 | C12: 15.59 | D12: 0 | E12: =E11+1 -> 11 | F12: =F11 -> 1 | G12: 11 | H12: 1 | I12: ; | S12: 9 | T12: =$Q$17*U12 -> 231.24137 | U12: 1 | V12: 95.876274
B13: 6 | C13: 14.44 | D13: 0 | E13: =E12+1 -> 12 | F13: =F12 -> 1 | G13: 12 | H13: 1 | I13: ; | S13: 10 | T13: =$Q$17*U13 -> 223.66726 | U13: 0.96724587 | V13: 91.472521
B14: 6 | C14: 15.19 | D14: 0 | E14: =E13+1 -> 13 | F14: =F13 -> 1 | G14: 13 | H14: 1 | I14: ; | S14: 11 | T14: =$Q$17*U14 -> 223.47403 | U14: 0.96641024 | V14: 126.74858
... B16: 6 | C16: 15.16 | D16: 0 | E16: =E15+1 -> 15 | F16: =F15 -> 1 | G16: 15 | H16: 1 | I16: ; | S16: 13 | T16: =$Q$17*U16 -> 206.30877 | U16: 0.89217932 | V16: 84.879041
B17: 6 | C17: 15.58 | D17: 0 | E17: =E16+1 -> 16 | F17: =F16 -> 1 | G17: 16 | H17: 1 | I17: ; | L17: Eactiva | M17: =SUM(C2:C8761) -> 959636.71 | N17: kWh | P17: PLMAX | Q17: 231.24137 | R17: KW | S17: 14 | T17: =$Q$17*U17 -> 224.04178 | U17: 0.96886548 | V17: 91.807945
B18: 6 | C18: 15.49 | D18: 0 | E18: =E17+1 -> 17 | F18: =F17 -> 1 | G18: 17 | H18: 1 | I18: ; | L18: Ereactiva | M18: =SUM(D2:D8761) -> 456759.84 | N18: kWh | S18: 15 | T18: =$Q$17*U18 -> 221.80392 | U18: 0.95918787 | V18: 91.090274
B19: 6 | C19: 14.86 | D19: 0 | E19: =E18+1 -> 18 | F19: =F18 -> 1 | G19: 18 | H19: 1 | I19: ; | L19: cosf | M19: =COS(ATAN(M18/M17)) -> 0.90293721 | N19: kWh | S19: 16 | T19: =$Q$17*U19 -> 219.05268 | U19: 0.94729021 | V19: 89.880685
B20: 6 | C20: 15.16 | D20: 0 | E20: =E19+1 -> 19 | F20: =F19 -> 1 | G20: 19 | H20: 1 | I20: ; | L20: maxP | M20: =MAX(C2:C8761) -> 564.3 | N20: kWh | S20: 17 | T20: =$Q$17*U20 -> 149.68 | U20: 0.64728902 | V20: 43.575068
B21: 6 | C21: 14.9 | D21: 0 | E21: =E20+1 -> 20 | F21: =F20 -> 1 | G21: 20 | H21: 1 | I21: ; | L21: FC | M21: =M17/8760/M20 -> 0.19413002 | S21: 18 | T21: =$Q$17*U21 -> 145.21233 | U21: 0.62796864 | V21: 64.533123
B22: 6 | C22: 15.54 | D22: 0 | E22: =E21+1 -> 21 | F22: =F21 -> 1 | G22: 21 | H22: 1 | I22: ; | S22: 19 | T22: =$Q$17*U22 -> 152.46567 | U22: 0.65933562 | V22: 54.343753
B23: 6 | C23: 14.87 | D23: 0 | E23: =E22+1 -> 22 | F23: =F22 -> 1 | G23: 22 | H23: 1 | I23: ; | S23: 20 | T23: =$Q$17*U23 -> 134.48767 | U23: 0.58159001 | V23: 40.603753
B24: 6 | C24: 14 | D24: 12.74 | E24: =E23+1 -> 23 | F24: =F23 -> 1 | G24: 23 | H24: 1 | I24: ; | S24: 21 | T24: =$Q$17*U24 -> 41.442603 | U24: 0.17921794 | V24: 3.4742192
B25: 6 | C25: 13.86 | D25: 13.79 | E25: =E24+1 -> 24 | F25: =F24 -> 1 | G25: 24 | H25: 1 | I25: ; | S25: 22 | T25: =$Q$17*U25 -> 33.502959 | U25: 0.14488307 | V25: 26.909671
B26: 6 | C26: 13.68 | D26: 14.98 | E26: =E25+1 -> 25 | F26: =F25 -> 1 | G26: =G2 -> 1 | H26: =H2+1 -> 2 | I26: ; | S26: 23 | T26: =$Q$17*U26 -> 31.920795 | U26: 0.13804102 | V26: 27.457562
B27: 6 | C27: 14.41 | D27: 17.03 | E27: =E26+1 -> 26 | F27: =F26 -> 1 | G27: =G3 -> 2 | H27: =H3+1 -> 2 | I27: ; | T27: =SUM(T3:T26) -> 2629.1417 | V27: =SUM(V3:V26) -> 1251.3968
B28: 6 | C28: 13.83 | D28: 15.99 | E28: =E27+1 -> 27 | F28: =F27 -> 1 | G28: =G4 -> 3 | H28: =H4+1 -> 2 | I28: ; | T28: kWh/dia | V28: kVArh/dia
B29: 6 | C29: 14.4 | D29: 16.73 | E29: =E28+1 -> 28 | F29: =F28 -> 1 | G29: =G5 -> 4 | H29: =H5+1 -> 2 | I29: ; | T29: =T27*365 -> 959636.71 | V29: =V27*365 -> 456759.84
B30: 6 | C30: 13.76 | D30: 15.01 | E30: =E29+1 -> 29 | F30: =F29 -> 1 | G30: =G6 -> 5 | H30: =H6+1 -> 2 | I30: ; | T30: kWh/año | V30: kVArh/año
B31: 6 | C31: 14.04 | D31: 15.23 | E31: =E30+1 -> 30 | F31: =F30 -> 1 | G31: =G7 -> 6 | H31: =H7+1 -> 2 | I31: ;
B32: 6 | C32: 13.86 | D32: 14.44 | E32: =E31+1 -> 31 | F32: =F31 -> 1 | G32: =G8 -> 7 | H32: =H8+1 -> 2 | I32: ;
B33: 6 | C33: 22.61 | D33: 17.39 | E33: =E32+1 -> 32 | F33: =F32 -> 1 | G33: =G9 -> 8 | H33: =H9+1 -> 2 | I33: ;
B34: 2 | C34: 183.47 | D34: 95.34 | E34: =E33+1 -> 33 | F34: =F33 -> 1 | G34: =G10 -> 9 | H34: =H10+1 -> 2 | I34: ;
B35: 1 | C35: 209.04 | D35: 22.26 | E35: =E34+1 -> 34 | F35: =F34 -> 1 | G35: =G11 -> 10 | H35: =H11+1 -> 2 | I35: ;
B36: 1 | C36: 265.79 | D36: 73.76 | E36: =E35+1 -> 35 | F36: =F35 -> 1 | G36: =G12 -> 11 | H36: =H12+1 -> 2 | I36: ;
B37: 1 | C37: 487.15 | D37: 269.68 | E37: =E36+1 -> 36 | F37: =F36 -> 1 | G37: =G13 -> 12 | H37: =H13+1 -> 2 | I37: ;
B38: 1 | C38: 43.95 | D38: 5.54 | E38: =E37+1 -> 37 | F38: =F37 -> 1 | G38: =G14 -> 13 | H38: =H14+1 -> 2 | I38: ;
B39: 1 | C39: 410.58 | D39: 167.22 | E39: =E38+1 -> 38 | F39: =F38 -> 1 | G39: =G15 -> 14 | H39: =H15+1 -> 2 | I39: ;
B40: 2 | C40: 478.19 | D40: 197.25 | E40: =E39+1 -> 39 | F40: =F39 -> 1 | G40: =G16 -> 15 | H40: =H16+1 -> 2 | I40: ;
B41: 2 | C41: 474.18 | D41: 210.88 | E41: =E40+1 -> 40 | F41: =F40 -> 1 | G41: =G17 -> 16 | H41: =H17+1 -> 2 | I41: ;
...
