Workbook
Name kappaP1: '24h-Colombia'!$D$14
Name kappaP1: '24h-ESPAÑA'!$G$23
Name kappaP1: 'Tarifas España 2024'!$G$23
Name kappaP2: '24h-Colombia'!$D$15
Name kappaP2: '24h-ESPAÑA'!$G$24
Name kappaP2: 'Tarifas España 2024'!$G$24
Name kappaP3: '24h-Colombia'!$D$16
Name kappaP3: '24h-ESPAÑA'!$G$25
Name kappaP3: 'Tarifas España 2024'!$G$25

Sheet 24h-Colombia
G1: P | I1: Q | L1: Penalización por
D2: CU | F2: USD/MWh | G2: kW | H2: Fc | I2: kVAr | J2: fp | K2: Pago P | L2: Reactiva Q | U2: Gams Syntax
C3: 1 | D3: ='Tarifas Colombia 2024'!$Q$16 -> 0.19042896 | F3: =D3*1000 -> 190.42896 | G3: =Industria!T3 -> 31.307452 | H3: =Industria!U3 -> 0.13538863 | I3: =Industria!V3 -> 27.875151 | J3: =COS(ATAN(I3/G3)) -> 0.74686056 | K3: =G3*D3 -> 5.9618455 | L3: =IF((I3-G3/2)*15*106/4005>0,(I3-G3/2)*15*106/4005,0) -> 4.8519514 | V3: cu | W3: Plu | X3: Ppvu | Y3: lambda | AB3: lambda
C4: 2 | D4: 0.19042896 | F4: =D4*1000 -> 190.42896 | G4: =Industria!T4 -> 20.898959 | H4: =Industria!U4 -> 0.090377249 | I4: =Industria!V4 -> 22.371534 | J4: =COS(ATAN(I4/G4)) -> 0.68264743 | K4: =G4*D4 -> 3.979767 | L4: =IF((I4-G4/2)*15*106/4005>0,(I4-G4/2)*15*106/4005,0) -> 4.7331004 | U4: t1 | V4: =D3 -> 0.19042896 | W4: =H3 -> 0.13538863 | X4: =#REF! -> #REF! | Y4: {='Precios Bolsa Colombia 2024'!A3:A26} -> 0.15860415 | AB4: ='Precios Bolsa Colombia 2024'!Q$29 -> 0.15443928
C5: 3 | D5: 0.19042896 | F5: =D5*1000 -> 190.42896 | G5: =Industria!T5 -> 17.653808 | H5: =Industria!U5 -> 0.076343641 | I5: =Industria!V5 -> 20.669616 | J5: =COS(ATAN(I5/G5)) -> 0.64945418 | K5: =G5*D5 -> 3.3617963 | L5: =IF((I5-G5/2)*15*106/4005>0,(I5-G5/2)*15*106/4005,0) -> 4.7016011 | U5: t2 | V5: =D4 -> 0.19042896 | W5: =H4 -> 0.090377249 | X5: =#REF! -> #REF! | Y5: 0.12171982 | AB5: ='Precios Bolsa Colombia 2024'!Q$29 -> 0.15443928
C6: 4 | D6: 0.19042896 | F6: =D6*1000 -> 190.42896 | G6: =Industria!T6 -> 17.394959 | H6: =Industria!U6 -> 0.075224251 | I6: =Industria!V6 -> 20.802712 | J6: =COS(ATAN(I6/G6)) -> 0.64147549 | K6: =G6*D6 -> 3.3125039 | L6: =IF((I6-G6/2)*15*106/4005>0,(I6-G6/2)*15*106/4005,0) -> 4.8058228 | U6: t3 | V6: =D5 -> 0.19042896 | W6: =H5 -> 0.076343641 | X6: =#REF! -> #REF! | Y6: 0.11909825 | AB6: ='Precios Bolsa Colombia 2024'!Q$29 -> 0.15443928
C7: 5 | D7: 0.19042896 | F7: =D7*1000 -> 190.42896 | G7: =Industria!T7 -> 17.182986 | H7: =Industria!U7 -> 0.074307579 | I7: =Industria!V7 -> 20.762822 | J7: =COS(ATAN(I7/G7)) -> 0.63756686 | K7: =G7*D7 -> 3.2721382 | L7: =IF((I7-G7/2)*15*106/4005>0,(I7-G7/2)*15*106/4005,0) -> 4.8320631 | U7: t4 | V7: =D6 -> 0.19042896 | W7: =H6 -> 0.075224251 | X7: =#REF! -> #REF! | Y7: 0.1160119 | AB7: ='Precios Bolsa Colombia 2024'!Q$29 -> 0.15443928
C8: 6 | D8: 0.19042896 | F8: =D8*1000 -> 190.42896 | G8: =Industria!T8 -> 16.905041 | H8: =Industria!U8 -> 0.073105609 | I8: =Industria!V8 -> 20.711205 | J8: =COS(ATAN(I8/G8)) -> 0.63233013 | K8: =G8*D8 -> 3.2192094 | L8: =IF((I8-G8/2)*15*106/4005>0,(I8-G8/2)*15*106/4005,0) -> 4.8667438 | U8: t5 | V8: =D7 -> 0.19042896 | W8: =H7 -> 0.074307579 | X8: =#REF! -> #REF! | Y8: 0.1184893 | AB8: ='Precios Bolsa Colombia 2024'!Q$29 -> 0.15443928
C9: 7 | D9: 0.19042896 | F9: =D9*1000 -> 190.42896 | G9: =Industria!T9 -> 16.974548 | H9: =Industria!U9 -> 0.07340619 | I9: =Industria!V9 -> 20.580986 | J9: =COS(ATAN(I9/G9)) -> 0.63627665 | K9: =G9*D9 -> 3.2324455 | L9: =IF((I9-G9/2)*15*106/4005>0,(I9-G9/2)*15*106/4005,0) -> 4.8012491 | U9: t6 | V9: =D8 -> 0.19042896 | W9: =H8 -> 0.073105609 | X9: =#REF! -> #REF! | Y9: 0.12427995 | AB9: ='Precios Bolsa Colombia 2024'!Q$29 -> 0.15443928
C10: 8 | D10: 0.19042896 | F10: =D10*1000 -> 190.42896 | G10: =Industria!T10 -> 19.774932 | H10: =Industria!U10 -> 0.085516409 | I10: =Industria!V10 -> 21.413726 | J10: =COS(ATAN(I10/G10)) -> 0.67843597 | K10: =G10*D10 -> 3.7657196 | L10: =IF((I10-G10/2)*15*106/4005>0,(I10-G10/2)*15*106/4005,0) -> 4.5759685 | U10: t7 | V10: =D9 -> 0.19042896 | W10: =H9 -> 0.07340619 | X10: =#REF! -> #REF! | Y10: 0.12433783 | AB10: ='Precios Bolsa Colombia 2024'!Q$29 -> 0.15443928
C11: 9 | D11: 0.19042896 | F11: =D11*1000 -> 190.42896 | G11: =Industria!T11 -> 204.33975 | H11: =Industria!U11 -> 0.88366434 | I11: =Industria!V11 -> 141.48904 | J11: =COS(ATAN(I11/G11)) -> 0.82214877 | K11: =G11*D11 -> 38.912206 | L11: =IF((I11-G11/2)*15*106/4005>0,(I11-G11/2)*15*106/4005,0) -> 15.609856 | U11: t8 | V11: =D10 -> 0.19042896 | W11: =H10 -> 0.085516409 | X11: =#REF! -> #REF! | Y11: 0.13064242 | AB11: ='Precios Bolsa Colombia 2024'!Q$29 -> 0.15443928
C12: 10 | D12: 0.19042896 | F12: =D12*1000 -> 190.42896 | G12: =Industria!T12 -> 231.24137 | H12: =Industria!U12 -> 1 | I12: =Industria!V12 -> 95.876274 | J12: =COS(ATAN(I12/G12)) -> 0.92374818 | K12: =G12*D12 -> 44.035053 | L12: =IF((I12-G12/2)*15*106/4005>0,(I12-G12/2)*15*106/4005,0) -> 0 | U12: t9 | V12: =D11 -> 0.19042896 | W12: =H11 -> 0.88366434 | X12: =#REF! -> #REF! | Y12: 0.13763512 | AB12: ='Precios Bolsa Colombia 2024'!Q$29 -> 0.15443928
C13: 11 | D13: 0.19042896 | F13: =D13*1000 -> 190.42896 | G13: =Industria!T13 -> 223.66726 | H13: =Industria!U13 -> 0.96724587 | I13: =Industria!V13 -> 91.472521 | J13: =COS(ATAN(I13/G13)) -> 0.92558715 | K13: =G13*D13 -> 42.592723 | L13: =IF((I13-G13/2)*15*106/4005>0,(I13-G13/2)*15*106/4005,0) -> 0 | U13: t10 | V13: =D12 -> 0.19042896 | W13: =H12 -> 1 | X13: =#REF! -> #REF! | Y13: 0.14010958 | AB13: ='Precios Bolsa Colombia 2024'!Q$29 -> 0.15443928
C14: 12 | D14: 0.19042896 | F14: =D14*1000 -> 190.42896 | G14: =Industria!T14 -> 223.47403 | H14: =Industria!U14 -> 0.96641024 | I14: =Industria!V14 -> 126.74858 | J14: =COS(ATAN(I14/G14)) -> 0.86983297 | K14: =G14*D14 -> 42.555926 | L14: =IF((I14-G14/2)*15*106/4005>0,(I14-G14/2)*15*106/4005,0) -> 5.9596462 | U14: t11 | V14: =D13 -> 0.19042896 | W14: =H13 -> 0.96724587 | X14: =#REF! -> #REF! | Y14: 0.14431613 | AB14: ='Precios Bolsa Colombia 2024'!Q$29 -> 0.15443928
C15: 13 | D15: 0.19042896 | F15: =D15*1000 -> 190.42896 | G15: =Industria!T15 -> 28.407397 | H15: =Industria!U15 -> 0.12284738 | I15: =Industria!V15 -> 2.0675616 | J15: =COS(ATAN(I15/G15)) -> 0.99736183 | K15: =G15*D15 -> 5.4095911 | L15: =IF((I15-G15/2)*15*106/4005>0,(I15-G15/2)*15*106/4005,0) -> 0 | U15: t12 | V15: =D14 -> 0.19042896 | W15: =H14 -> 0.96641024 | X15: =#REF! -> #REF! | Y15: 0.14789205 | AB15: ='Precios Bolsa Colombia 2024'!Q$29 -> 0.15443928
C16: 14 | D16: 0.19042896 | F16: =D16*1000 -> 190.42896 | G16: =Industria!T16 -> 206.30877 | H16: =Industria!U16 -> 0.89217932 | I16: =Industria!V16 -> 84.879041 | J16: =COS(ATAN(I16/G16)) -> 0.9247911 | K16: =G16*D16 -> 39.287164 | L16: =IF((I16-G16/2)*15*106/4005>0,(I16-G16/2)*15*106/4005,0) -> 0 | U16: t13 | V16: =D15 -> 0.19042896 | W16: =H15 -> 0.12284738 | X16: =#REF! -> #REF! | Y16: 0.14797283 | AB16: ='Precios Bolsa Colombia 2024'!Q$29 -> 0.15443928
... C26: 24 | D26: 0.19042896 | F26: =D26*1000 -> 190.42896 | G26: =Industria!T26 -> 31.920795 | H26: =Industria!U26 -> 0.13804102 | I26: =Industria!V26 -> 27.457562 | J26: =COS(ATAN(I26/G26)) -> 0.75811852 | K26: =G26*D26 -> 6.0786436 | L26: =IF((I26-G26/2)*15*106/4005>0,(I26-G26/2)*15*106/4005,0) -> 4.5644173 | U26: t23 | V26: =D25 -> 0.19042896 | W26: =H25 -> 0.14488307 | X26: =#REF! -> #REF! | Y26: 0.14000581 | AB26: ='Precios Bolsa Colombia 2024'!Q$29 -> 0.15443928
F27: =SUM(F3:F26)/24 -> 190.42896 | G27: =SUM(G3:G26) -> 2629.1417 | I27: =SUM(I3:I26) -> 1251.3968 | J27: =COS(ATAN(I29/G29)) -> 0.90293721 | K27: =SUM(K3:K26) -> 500.66471 | L27: =SUM(L3:L26) -> 68.335259 | U27: t24 | V27: =D26 -> 0.19042896 | W27: =H26 -> 0.13804102 | X27: =#REF! -> #REF! | Y27: 0.13456529 | AB27: ='Precios Bolsa Colombia 2024'!Q$29 -> 0.15443928
A28: LF | B28: =G27/MAX(G3:G26)/24 -> 0.4737369 | G28: kWh/dia | I28: kWh/dia | K28: USD/DIA | L28: USD/DIA | Y28: =AB4 -> 0.15443928
G29: =G27*365 -> 959636.71 | I29: =I27*365 -> 456759.84
A30: CUpico | B30: ='Tarifas Colombia 2024'!P21 -> 773.6886 | C30: = | D30: =B30/'Tarifas Colombia 2024'!$C$29 -> 0.19342215 | G30: kWh/año | I30: kWh/año
A31: CUnopico | B31: ='Tarifas Colombia 2024'!P22 -> 758.58584 | C31: = | D31: =B31/'Tarifas Colombia 2024'!$C$29 -> 0.18964646 | F31: Plmax= | G31: =G27/(24*B28) -> 231.24137
A33: Wpico | B33: =SUM(G20:G25) -> 656.79123 | D33: kWh
A34: Wnopico | B34: =SUM(G3:G19,G26) -> 1972.3504 | D34: kWh
A35: Wtotal | B35: =B34+B33 -> 2629.1417 | D35: kWh | I35: ENERGIA P comprada | K35: =-K27*365 -> -182742.62 | L35: USD/AÑO
I36: Penalización Q | K36: =-L27*365 -> -24942.37 | L36: USD/AÑO
I37: Total | K37: =SUM(K35:K36) -> -207684.99 | L37: USD/AÑO
I38: POSITIVO significa saldo a favor
I39: NEGATIVO significa saldo a pagar
I40: Costo medio | K40: =-K35/G29 -> 0.19042896 | L40: USD/AÑO

Sheet 24h-ESPAÑA
B1: Periodos Horarios segun esquema de Enero 2024
A2: Peajes o | B2: Tarifas | C2: PotenciaActiva
B3: Peaje+Cargo Pot Eur/kW/año | D3: Pot Contratada kW | E3: Eur/año | G3: Energia activa | H3: Capacidad | I3: Perdidas | X3: Costes de Operación | Y3: ='Tarifas España 2024'!AM7 -> 0.001 | Z3: Eur/kWh
B4: P1 | C4: =AW44 -> 28.791866 | D4: =W104 -> 570 | E4: =-D4*C4 -> -16411.364 | G4: =AW53 -> 0.044778 | H4: =AF62 -> 0.00049 | I4: =AF71 -> 0.067 | S4: Industria Acero | T4: =MAX(D4:D9) -> 570 | V4: kW | X4: Retribucion OM+OS | Y4: ='Tarifas España 2024'!AM8 -> 0.00020949 | Z4: Eur/kWh
B5: P2 | C5: =AX44 -> 15.077643 | D5: =W105 -> 560 | E5: =-D5*C5 -> -8443.4801 | G5: =AX53 -> 0.024986 | H5: =AG62 -> 0.000225 | I5: =AG71 -> 0.068 | S5: Load factor | T5: =SUM(K12:K35)/24/MAX(K12:K35) -> 0.4737369 | X5: Bono Social | Y5: ='Tarifas España 2024'!AM9 -> 0.000358725 | Z5: Eur/kWh
B6: P3 | C6: =AY44 -> 6.55917 | D6: =W106 -> 480 | E6: =-D6*C6 -> -3148.4016 | G6: =AY53 -> 0.011795 | H6: =AH62 -> 0.00015 | I6: =AH71 -> 0.065 | S6: Power factor | T6: =P36 -> 0.90293721 | V6: lag | X6: Tasa Local | Y6: ='Tarifas España 2024'!AM10 -> 0.015 | Z6: Eur/kWh
B7: P4 | C7: =AZ44 -> 5.172085 | D7: =W107 -> 480 | E7: =-D7*C7 -> -2482.6008 | G7: =AZ53 -> 0.006274 | H7: =AI62 -> 0.000113 | I7: =AI71 -> 0.065
B8: P5 | C8: =BA44 -> 1.932805 | D8: =W108 -> 460 | E8: =-D8*C8 -> -889.0903 | G8: =BA53 -> 0.002388 | H8: =AJ62 -> 0.000113 | I8: =AJ71 -> 0.043
B9: P6 | C9: =BB44 -> 0.916088 | D9: =W109 -> 370 | E9: =-D9*C9 -> -338.95256 | G9: =BB53 -> 0.001443 | H9: =AK62 -> 0 | I9: =AK71 -> 0.077
B10: kappa = | C10: =E10/D10 -> -65.165525 | D10: =AVERAGE(D4:D9) -> 486.66667 | E10: =SUM(E4:E9) -> -31713.889 | G10: precios medios | K10: P | M10: Q | N10: psi | O10: psi adjusted | P10: fp
B11: Periodo | C11: Termino Ener | D11: Capacidad | E11: Perdidas | F11: hora | G11: Spot | H11: Restricciones | I11: Procesos OS | J11: Precio | K11: kWh | L11: Fc | M11: kVArh | R11: Pago W Tot
A12: 1 | B12: P6 | C12: =$G$9 -> 0.001443 | D12: =$H$9 -> 0 | E12: 0.077 | F12: 1 | G12: ='Precios Bolsa España 2024'!O4 -> 0.068746795 | H12: ='Precios Bolsa España 2024'!P4 -> 0.0072543014 | I12: ='Precios Bolsa España 2024'!Q4 -> 0.0025313699 | J12: =(G12)*1000 -> 68.746795 | K12: =Industria!T3 -> 31.307452 | L12: =Industria!U3 -> 0.13538863 | M12: =Industria!V3 -> 27.875151 | N12: ='24h-ESPAÑA'!R12/'24h-ESPAÑA'!K12-'24h-ESPAÑA'!J12/1000 -> 0.020202155 | O12: =AVERAGE(N12:N19) -> 0.022820505 | P12: =COS(ATAN(M12/K12)) -> 0.74686056 | Q12: =-K12*(AJ14+O12) -> -2.8667388 | R12: =K12*(C12+(G12+H12+I12+D12+$Y$5+$Y$4)*(1+E12)+$Y$3)*(1+$Y$6) -> 2.784765 | AI12: Gams Syntax
A13: 2 | B13: P6 | C13: =$G$9 -> 0.001443 | D13: =$H$9 -> 0 | E13: =$I$9 -> 0.077 | F13: 2 | G13: ='Precios Bolsa España 2024'!O5 -> 0.064382932 | H13: ='Precios Bolsa España 2024'!P5 -> 0.0081311507 | I13: ='Precios Bolsa España 2024'!Q5 -> 0.0027362192 | J13: =(G13)*1000 -> 64.382932 | K13: =Industria!T4 -> 20.898959 | L13: =Industria!U4 -> 0.090377249 | M13: =Industria!V4 -> 22.371534 | N13: ='24h-ESPAÑA'!R13/'24h-ESPAÑA'!K13-'24h-ESPAÑA'!J13/1000 -> 0.020978104 | O13: =$O$12 -> 0.022820505 | P13: =COS(ATAN(M13/K13)) -> 0.68264743 | Q13: =-K13*(AJ15+O13) -> -1.822461 | R13: =K13*(C13+(G13+H13+I13+D13+$Y$5+$Y$4)*(1+E13)+$Y$3)*(1+$Y$6) -> 1.7839568 | AJ13: lambda | AK13: psi | AL13: Ppvu | AM13: Plu | AN13: Pbmax
A14: 3 | B14: P6 | C14: =$G$9 -> 0.001443 | D14: =$H$9 -> 0 | E14: =$I$9 -> 0.077 | F14: 3 | G14: ='Precios Bolsa España 2024'!O6 -> 0.062238411 | H14: ='Precios Bolsa España 2024'!P6 -> 0.0092259726 | I14: ='Precios Bolsa España 2024'!Q6 -> 0.002448137 | J14: =(G14)*1000 -> 62.238411 | K14: =Industria!T5 -> 17.653808 | L14: =Industria!U5 -> 0.076343641 | M14: =Industria!V5 -> 20.669616 | N14: ='24h-ESPAÑA'!R14/'24h-ESPAÑA'!K14-'24h-ESPAÑA'!J14/1000 -> 0.021660223 | O14: =$O$12 -> 0.022820505 | P14: =COS(ATAN(M14/K14)) -> 0.64945418 | Q14: =-K14*(AJ16+O14) -> -1.5016138 | R14: =K14*(C14+(G14+H14+I14+D14+$Y$5+$Y$4)*(1+E14)+$Y$3)*(1+$Y$6) -> 1.4811304 | AF14: =(AJ14+AK14)*K12 -> 2.8667388 | AI14: t1 | AJ14: =G12 -> 0.068746795 | AK14: =O12 -> 0.022820505 | AL14: =#REF! -> #REF! | AM14: =L12 -> 0.13538863 | AN14: =#REF! -> #REF!
A15: 4 | B15: P6 | C15: =$G$9 -> 0.001443 | D15: =$H$9 -> 0 | E15: =$I$9 -> 0.077 | F15: 4 | G15: ='Precios Bolsa España 2024'!O7 -> 0.060464137 | H15: ='Precios Bolsa España 2024'!P7 -> 0.0097246575 | I15: ='Precios Bolsa España 2024'!Q7 -> 0.0022396712 | J15: =(G15)*1000 -> 60.464137 | K15: =Industria!T6 -> 17.394959 | L15: =Industria!U6 -> 0.075224251 | M15: =Industria!V6 -> 20.802712 | N15: ='24h-ESPAÑA'!R15/'24h-ESPAÑA'!K15-'24h-ESPAÑA'!J15/1000 -> 0.021812195 | O15: =$O$12 -> 0.022820505 | P15: =COS(ATAN(M15/K15)) -> 0.64147549 | Q15: =-K15*(AJ17+O15) -> -1.4487329 | R15: =K15*(C15+(G15+H15+I15+D15+$Y$5+$Y$4)*(1+E15)+$Y$3)*(1+$Y$6) -> 1.4311934 | AF15: =(AJ15+AK15)*K13 -> 1.822461 | AI15: t2 | AJ15: =G13 -> 0.064382932 | AK15: =O13 -> 0.022820505 | AL15: =#REF! -> #REF! | AM15: =L13 -> 0.090377249 | AN15: =#REF! -> #REF!
A16: 5 | B16: P6 | C16: =$G$9 -> 0.001443 | D16: =$H$9 -> 0 | E16: =$I$9 -> 0.077 | F16: 5 | G16: ='Precios Bolsa España 2024'!O8 -> 0.060655534 | H16: ='Precios Bolsa España 2024'!P8 -> 0.0098196438 | I16: ='Precios Bolsa España 2024'!Q8 -> 0.0022953699 | J16: =(G16)*1000 -> 60.655534 | K16: =Industria!T7 -> 17.182986 | L16: =Industria!U7 -> 0.074307579 | M16: =Industria!V7 -> 20.762822 | N16: ='24h-ESPAÑA'!R16/'24h-ESPAÑA'!K16-'24h-ESPAÑA'!J16/1000 -> 0.021994746 | O16: =$O$12 -> 0.022820505 | P16: =COS(ATAN(M16/K16)) -> 0.63756686 | Q16: =-K16*(AJ18+O16) -> -1.4343676 | R16: =K16*(C16+(G16+H16+I16+D16+$Y$5+$Y$4)*(1+E16)+$Y$3)*(1+$Y$6) -> 1.4201786 | AF16: =(AJ16+AK16)*K14 -> 1.5016138 | AI16: t3 | AJ16: =G14 -> 0.062238411 | AK16: =O14 -> 0.022820505 | AL16: =#REF! -> #REF! | AM16: =L14 -> 0.076343641 | AN16: =#REF! -> #REF!
A17: 6 | B17: P6 | C17: =$G$9 -> 0.001443 | D17: =$H$9 -> 0 | E17: =$I$9 -> 0.077 | F17: 6 | G17: ='Precios Bolsa España 2024'!O9 -> 0.065132137 | H17: ='Precios Bolsa España 2024'!P9 -> 0.010057589 | I17: ='Precios Bolsa España 2024'!Q9 -> 0.0025469041 | J17: =(G17)*1000 -> 65.132137 | K17: =Industria!T8 -> 16.905041 | L17: =Industria!U8 -> 0.073105609 | M17: =Industria!V8 -> 20.711205 | N17: ='24h-ESPAÑA'!R17/'24h-ESPAÑA'!K17-'24h-ESPAÑA'!J17/1000 -> 0.022946841 | O17: =$O$12 -> 0.022820505 | P17: =COS(ATAN(M17/K17)) -> 0.63233013 | Q17: =-K17*(AJ19+O17) -> -1.486843 | R17: =K17*(C17+(G17+H17+I17+D17+$Y$5+$Y$4)*(1+E17)+$Y$3)*(1+$Y$6) -> 1.4889787 | AF17: =(AJ17+AK17)*K15 -> 1.4487329 | AI17: t4 | AJ17: =G15 -> 0.060464137 | AK17: =O15 -> 0.022820505 | AL17: =#REF! -> #REF! | AM17: =L15 -> 0.075224251 | AN17: =#REF! -> #REF!
A18: 7 | B18: P6 | C18: =$G$9 -> 0.001443 | D18: =$H$9 -> 0 | E18: =$I$9 -> 0.077 | F18: 7 | G18: ='Precios Bolsa España 2024'!O10 -> 0.073826082 | H18: ='Precios Bolsa España 2024'!P10 -> 0.0099409041 | I18: ='Precios Bolsa España 2024'!Q10 -> 0.0041280822 | J18: =(G18)*1000 -> 73.826082 | K18: =Industria!T9 -> 16.974548 | L18: =Industria!U9 -> 0.07340619 | M18: =Industria!V9 -> 20.580986 | N18: ='24h-ESPAÑA'!R18/'24h-ESPAÑA'!K18-'24h-ESPAÑA'!J18/1000 -> 0.025357643 | O18: =$O$12 -> 0.022820505 | P18: =COS(ATAN(M18/K18)) -> 0.63627665 | Q18: =-K18*(AJ20+O18) -> -1.6405321 | R18: =K18*(C18+(G18+H18+I18+D18+$Y$5+$Y$4)*(1+E18)+$Y$3)*(1+$Y$6) -> 1.6835989 | AF18: =(AJ18+AK18)*K16 -> 1.4343676 | AI18: t5 | AJ18: =G16 -> 0.060655534 | AK18: =O16 -> 0.022820505 | AL18: =#REF! -> #REF! | AM18: =L16 -> 0.074307579 | AN18: =#REF! -> #REF!
A19: 8 | B19: P6 | C19: =$G$9 -> 0.001443 | D19: =$H$9 -> 0 | E19: =$I$9 -> 0.077 | F19: 8 | G19: ='Precios Bolsa España 2024'!O11 -> 0.076148795 | H19: ='Precios Bolsa España 2024'!P11 -> 0.010411233 | I19: ='Precios Bolsa España 2024'!Q11 -> 0.0055221918 | J19: =(G19)*1000 -> 76.148795 | K19: =Industria!T10 -> 19.774932 | L19: =Industria!U10 -> 0.085516409 | M19: =Industria!V10 -> 21.413726 | N19: ='24h-ESPAÑA'!R19/'24h-ESPAÑA'!K19-'24h-ESPAÑA'!J19/1000 -> 0.027612136 | O19: =$O$12 -> 0.022820505 | P19: =COS(ATAN(M19/K19)) -> 0.67843597 | Q19: =-K19*(AJ21+O19) -> -1.9571111 | R19: =K19*(C19+(G19+H19+I19+D19+$Y$5+$Y$4)*(1+E19)+$Y$3)*(1+$Y$6) -> 2.0518653 | AF19: =(AJ19+AK19)*K17 -> 1.486843 | AI19: t6 | AJ19: =G17 -> 0.065132137 | AK19: =O17 -> 0.022820505 | AL19: =#REF! -> #REF! | AM19: =L17 -> 0.073105609 | AN19: =#REF! -> #REF!
A20: 9 | B20: P5 | C20: =$G$8 -> 0.002388 | D20: =$H$8 -> 0.000113 | E20: =$I$8 -> 0.043 | F20: 9 | G20: ='Precios Bolsa España 2024'!O12 -> 0.069382712 | H20: ='Precios Bolsa España 2024'!P12 -> 0.0094291507 | I20: ='Precios Bolsa España 2024'!Q12 -> 0.0059585753 | J20: =(G20)*1000 -> 69.382712 | K20: =Industria!T11 -> 204.33975 | L20: =Industria!U11 -> 0.88366434 | M20: =Industria!V11 -> 141.48904 | N20: ='24h-ESPAÑA'!R20/'24h-ESPAÑA'!K20-'24h-ESPAÑA'!J20/1000 -> 0.024519073 | O20: =AVERAGE($N$20,$N$26:$N$29,$N$34:$N$35) -> 0.021074371 | P20: =COS(ATAN(M20/K20)) -> 0.82214877 | Q20: =-K20*(AJ22+O20) -> -18.483978 | R20: =K20*(C20+(G20+H20+I20+D20+$Y$5+$Y$4)*(1+E20)+$Y$3)*(1+$Y$6) -> 19.187868 | AF20: =(AJ20+AK20)*K18 -> 1.6405321 | AI20: t7 | AJ20: =G18 -> 0.073826082 | AK20: =O18 -> 0.022820505 | AL20: =#REF! -> #REF! | AM20: =L18 -> 0.07340619 | AN20: =#REF! -> #REF!
A21: 10 | B21: P3 | C21: =$G$6 -> 0.011795 | D21: =$H$6 -> 0.00015 | E21: =$I$6 -> 0.065 | F21: 10 | G21: ='Precios Bolsa España 2024'!O13 -> 0.056760082 | H21: ='Precios Bolsa España 2024'!P13 -> 0.0080707671 | I21: ='Precios Bolsa España 2024'!Q13 -> 0.0045372055 | J21: =(G21)*1000 -> 56.760082 | K21: =Industria!T12 -> 231.24137 | L21: =Industria!U12 -> 1 | M21: =Industria!V12 -> 95.876274 | N21: ='24h-ESPAÑA'!R21/'24h-ESPAÑA'!K21-'24h-ESPAÑA'!J21/1000 -> 0.031988348 | O21: =N21 -> 0.031988348 | P21: =COS(ATAN(M21/K21)) -> 0.92374818 | Q21: =-K21*(AJ23+O21) -> -20.522309 | R21: =K21*(C21+(G21+H21+I21+D21+$Y$5+$Y$4)*(1+E21)+$Y$3)*(1+$Y$6) -> 20.522309 | AF21: =(AJ21+AK21)*K19 -> 1.9571111 | AI21: t8 | AJ21: =G19 -> 0.076148795 | AK21: =O19 -> 0.022820505 | AL21: =#REF! -> #REF! | AM21: =L19 -> 0.085516409 | AN21: =#REF! -> #REF!
A22: 11 | B22: P4 | C22: =$G$7 -> 0.006274 | D22: =$H$7 -> 0.000113 | E22: =$I$7 -> 0.065 | F22: 11 | G22: ='Precios Bolsa España 2024'!O14 -> 0.04694937 | H22: ='Precios Bolsa España 2024'!P14 -> 0.0071172055 | I22: ='Precios Bolsa España 2024'!Q14 -> 0.0031848219 | J22: =(G22)*1000 -> 46.94937 | K22: =Industria!T13 -> 223.66726 | L22: =Industria!U13 -> 0.96724587 | M22: =Industria!V13 -> 91.472521 | N22: ='24h-ESPAÑA'!R22/'24h-ESPAÑA'!K22-'24h-ESPAÑA'!J22/1000 -> 0.023057446 | O22: =AVERAGE($N$22:$N$25) -> 0.022190647 | P22: =COS(ATAN(M22/K22)) -> 0.92558715 | Q22: =-K22*(AJ24+O22) -> -15.464358 | R22: =K22*(C22+(G22+H22+I22+D22+$Y$5+$Y$4)*(1+E22)+$Y$3)*(1+$Y$6) -> 15.658233 | AF22: =(AJ22+AK22)*K20 -> 18.483978 | AI22: t9 | AJ22: =G20 -> 0.069382712 | AK22: =O20 -> 0.021074371 | AL22: =#REF! -> #REF! | AM22: =L20 -> 0.88366434 | AN22: =#REF! -> #REF!
A23: 12 | B23: P4 | C23: =$G$7 -> 0.006274 | D23: =$H$7 -> 0.000113 | E23: =$I$7 -> 0.065 | F23: 12 | G23: ='Precios Bolsa España 2024'!O15 -> 0.04184674 | H23: ='Precios Bolsa España 2024'!P15 -> 0.0070680548 | I23: ='Precios Bolsa España 2024'!Q15 -> 0.0025854521 | J23: =(G23)*1000 -> 41.84674 | K23: =Industria!T14 -> 223.47403 | L23: =Industria!U14 -> 0.96641024 | M23: =Industria!V14 -> 126.74858 | N23: ='24h-ESPAÑA'!R23/'24h-ESPAÑA'!K23-'24h-ESPAÑA'!J23/1000 -> 0.021943226 | O23: =AVERAGE($N$22:$N$25) -> 0.022190647 | P23: =COS(ATAN(M23/K23)) -> 0.86983297 | Q23: =-K23*(AJ25+O23) -> -14.310693 | R23: =K23*(C23+(G23+H23+I23+D23+$Y$5+$Y$4)*(1+E23)+$Y$3)*(1+$Y$6) -> 14.2554 | AF23: =(AJ23+AK23)*K21 -> 20.522309 | AI23: t10 | AJ23: =G21 -> 0.056760082 | AK23: =O21 -> 0.031988348 | AL23: =#REF! -> #REF! | AM23: =L21 -> 1 | AN23: =#REF! -> #REF!
A24: 13 | B24: P4 | C24: =$G$7 -> 0.006274 | D24: =$H$7 -> 0.000113 | E24: =$I$7 -> 0.065 | F24: 13 | G24: ='Precios Bolsa España 2024'!O16 -> 0.039593726 | H24: ='Precios Bolsa España 2024'!P16 -> 0.0070899726 | I24: ='Precios Bolsa España 2024'!Q16 -> 0.002544274 | J24: =(G24)*1000 -> 39.593726 | K24: =Industria!T15 -> 28.407397 | L24: =Industria!U15 -> 0.12284738 | M24: =Industria!V15 -> 2.0675616 | N24: ='24h-ESPAÑA'!R24/'24h-ESPAÑA'!K24-'24h-ESPAÑA'!J24/1000 -> 0.021739968 | O24: =AVERAGE($N$22:$N$25) -> 0.022190647 | P24: =COS(ATAN(M24/K24)) -> 0.99736183 | Q24: =-K24*(AJ26+O24) -> -1.7551332 | R24: =K24*(C24+(G24+H24+I24+D24+$Y$5+$Y$4)*(1+E24)+$Y$3)*(1+$Y$6) -> 1.7423306 | AF24: =(AJ24+AK24)*K22 -> 15.464358 | AI24: t11 | AJ24: =G22 -> 0.04694937 | AK24: =O22 -> 0.022190647 | AL24: =#REF! -> #REF! | AM24: =L22 -> 0.96724587 | AN24: =#REF! -> #REF!
A25: 14 | B25: P4 | C25: =$G$7 -> 0.006274 | D25: =$H$7 -> 0.000113 | E25: =$I$7 -> 0.065 | F25: 14 | G25: ='Precios Bolsa España 2024'!O17 -> 0.037885123 | H25: ='Precios Bolsa España 2024'!P17 -> 0.0075278082 | I25: ='Precios Bolsa España 2024'!Q17 -> 0.0024952877 | J25: =(G25)*1000 -> 37.885123 | K25: =Industria!T16 -> 206.30877 | L25: =Industria!U16 -> 0.89217932 | M25: =Industria!V16 -> 84.879041 | N25: ='24h-ESPAÑA'!R25/'24h-ESPAÑA'!K25-'24h-ESPAÑA'!J25/1000 -> 0.02202195 | O25: =AVERAGE($N$22:$N$25) -> 0.022190647 | P25: =COS(ATAN(M25/K25)) -> 0.9247911 | Q25: =-K25*(AJ27+O25) -> -12.394158 | R25: =K25*(C25+(G25+H25+I25+D25+$Y$5+$Y$4)*(1+E25)+$Y$3)*(1+$Y$6) -> 12.359354 | AF25: =(AJ25+AK25)*K23 -> 14.310693 | AI25: t12 | AJ25: =G23 -> 0.04184674 | AK25: =O23 -> 0.022190647 | AL25: =#REF! -> #REF! | AM25: =L23 -> 0.96641024 | AN25: =#REF! -> #REF!
A26: 15 | B26: P5 | C26: =$G$8 -> 0.002388 | D26: =$H$8 -> 0.000113 | E26: =$I$8 -> 0.043 | F26: 15 | G26: ='Precios Bolsa España 2024'!O18 -> 0.036840932 | H26: ='Precios Bolsa España 2024'!P18 -> 0.0075245753 | I26: ='Precios Bolsa España 2024'!Q18 -> 0.0024581096 | J26: =(G26)*1000 -> 36.840932 | K26: =Industria!T17 -> 224.04178 | L26: =Industria!U17 -> 0.96886548 | M26: =Industria!V17 -> 91.807945 | N26: ='24h-ESPAÑA'!R26/'24h-ESPAÑA'!K26-'24h-ESPAÑA'!J26/1000 -> 0.016888641 | O26: =AVERAGE($N$20,$N$26:$N$29,$N$34:$N$35) -> 0.021074371 | P26: =COS(ATAN(M26/K26)) -> 0.92532319 | Q26: =-K26*(AJ28+O26) -> -12.975448 | R26: =K26*(C26+(G26+H26+I26+D26+$Y$5+$Y$4)*(1+E26)+$Y$3)*(1+$Y$6) -> 12.037669 | AF26: =(AJ26+AK26)*K24 -> 1.7551332 | AI26: t13 | AJ26: =G24 -> 0.039593726 | AK26: =O24 -> 0.022190647 | AL26: =#REF! -> #REF! | AM26: =L24 -> 0.12284738 | AN26: =#REF! -> #REF!
A27: 16 | B27: P5 | C27: =$G$8 -> 0.002388 | D27: =$H$8 -> 0.000113 | E27: =$I$8 -> 0.043 | F27: 16 | G27: ='Precios Bolsa España 2024'!O19 -> 0.038253699 | H27: ='Precios Bolsa España 2024'!P19 -> 0.0076432329 | I27: ='Precios Bolsa España 2024'!Q19 -> 0.0030550685 | J27: =(G27)*1000 -> 38.253699 | K27: =Industria!T18 -> 221.80392 | L27: =Industria!U18 -> 0.95918787 | M27: =Industria!V18 -> 91.090274 | N27: ='24h-ESPAÑA'!R27/'24h-ESPAÑA'!K27-'24h-ESPAÑA'!J27/1000 -> 0.017729076 | O27: =AVERAGE($N$20,$N$26:$N$29,$N$34:$N$35) -> 0.021074371 | P27: =COS(ATAN(M27/K27)) -> 0.9250312 | Q27: =-K27*(AJ29+O27) -> -13.159198 | R27: =K27*(C27+(G27+H27+I27+D27+$Y$5+$Y$4)*(1+E27)+$Y$3)*(1+$Y$6) -> 12.417199 | AF27: =(AJ27+AK27)*K25 -> 12.394158 | AI27: t14 | AJ27: =G25 -> 0.037885123 | AK27: =O25 -> 0.022190647 | AL27: =#REF! -> #REF! | AM27: =L25 -> 0.89217932 | AN27: =#REF! -> #REF!
A28: 17 | B28: P5 | C28: =$G$8 -> 0.002388 | D28: =$H$8 -> 0.000113 | E28: =$I$8 -> 0.043 | F28: 17 | G28: ='Precios Bolsa España 2024'!O20 -> 0.046423205 | H28: ='Precios Bolsa España 2024'!P20 -> 0.0078807123 | I28: ='Precios Bolsa España 2024'!Q20 -> 0.0042375616 | J28: =(G28)*1000 -> 46.423205 | K28: =Industria!T19 -> 219.05268 | L28: =Industria!U19 -> 0.94729021 | M28: =Industria!V19 -> 89.880685 | N28: ='24h-ESPAÑA'!R28/'24h-ESPAÑA'!K28-'24h-ESPAÑA'!J28/1000 -> 0.019711424 | O28: =AVERAGE($N$20,$N$26:$N$29,$N$34:$N$35) -> 0.021074371 | P28: =COS(ATAN(M28/K28)) -> 0.92514946 | Q28: =-K28*(AJ30+O28) -> -14.785525 | R28: =K28*(C28+(G28+H28+I28+D28+$Y$5+$Y$4)*(1+E28)+$Y$3)*(1+$Y$6) -> 14.486968 | AF28: =(AJ28+AK28)*K26 -> 12.975448 | AI28: t15 | AJ28: =G26 -> 0.036840932 | AK28: =O26 -> 0.021074371 | AL28: =#REF! -> #REF! | AM28: =L26 -> 0.96886548 | AN28: =#REF! -> #REF!
A29: 18 | B29: P5 | C29: =$G$8 -> 0.002388 | D29: =$H$8 -> 0.000113 | E29: =$I$8 -> 0.043 | F29: 18 | G29: ='Precios Bolsa España 2024'!O21 -> 0.059484767 | H29: ='Precios Bolsa España 2024'!P21 -> 0.008736274 | I29: ='Precios Bolsa España 2024'!Q21 -> 0.0056707671 | J29: =(G29)*1000 -> 59.484767 | K29: =Industria!T20 -> 149.68 | L29: =Industria!U20 -> 0.64728902 | M29: =Industria!V20 -> 43.575068 | N29: ='24h-ESPAÑA'!R29/'24h-ESPAÑA'!K29-'24h-ESPAÑA'!J29/1000 -> 0.022900411 | O29: =AVERAGE($N$20,$N$26:$N$29,$N$34:$N$35) -> 0.021074371 | P29: =COS(ATAN(M29/K29)) -> 0.96014057 | Q29: =-K29*(AJ31+O29) -> -12.058092 | R29: =K29*(C29+(G29+H29+I29+D29+$Y$5+$Y$4)*(1+E29)+$Y$3)*(1+$Y$6) -> 12.331413 | AF29: =(AJ29+AK29)*K27 -> 13.159198 | AI29: t16 | AJ29: =G27 -> 0.038253699 | AK29: =O27 -> 0.021074371 | AL29: =#REF! -> #REF! | AM29: =L27 -> 0.95918787 | AN29: =#REF! -> #REF!
A30: 19 | B30: P1 | C30: =$G$4 -> 0.044778 | D30: =$H$4 -> 0.00049 | E30: =$I$4 -> 0.067 | F30: 19 | G30: ='Precios Bolsa España 2024'!O22 -> 0.076155178 | H30: ='Precios Bolsa España 2024'!P22 -> 0.010724877 | I30: ='Precios Bolsa España 2024'!Q22 -> 0.0059901918 | J30: =(G30)*1000 -> 76.155178 | K30: =Industria!T21 -> 145.21233 | L30: =Industria!U21 -> 0.62796864 | M30: =Industria!V21 -> 64.533123 | N30: ='24h-ESPAÑA'!R30/'24h-ESPAÑA'!K30-'24h-ESPAÑA'!J30/1000 -> 0.072034485 | O30: =N30 -> 0.072034485 | P30: =COS(ATAN(M30/K30)) -> 0.91382484 | Q30: =-K30*(AJ32+O30) -> -21.518966 | R30: =K30*(C30+(G30+H30+I30+D30+$Y$5+$Y$4)*(1+E30)+$Y$3)*(1+$Y$6) -> 21.518966 | AF30: =(AJ30+AK30)*K28 -> 14.785525 | AI30: t17 | AJ30: =G28 -> 0.046423205 | AK30: =O28 -> 0.021074371 | AL30: =#REF! -> #REF! | AM30: =L28 -> 0.94729021 | AN30: =#REF! -> #REF!
A31: 20 | B31: P2 | C31: =$G$5 -> 0.024986 | D31: =$H$7 -> 0.000113 | E31: =$I$7 -> 0.065 | F31: 20 | G31: ='Precios Bolsa España 2024'!O23 -> 0.090286438 | H31: ='Precios Bolsa España 2024'!P23 -> 0.012580219 | I31: ='Precios Bolsa España 2024'!Q23 -> 0.0045248767 | J31: =(G31)*1000 -> 90.286438 | K31: =Industria!T22 -> 152.46567 | L31: =Industria!U22 -> 0.65933562 | M31: =Industria!V22 -> 54.343753 | N31: ='24h-ESPAÑA'!R31/'24h-ESPAÑA'!K31-'24h-ESPAÑA'!J31/1000 -> 0.052913292 | O31: =AVERAGE($N$31:$N$33) -> 0.051218244 | P31: =COS(ATAN(M31/K31)) -> 0.9419536 | Q31: =-K31*(AJ33+O31) -> -21.574606 | R31: =K31*(C31+(G31+H31+I31+D31+$Y$5+$Y$4)*(1+E31)+$Y$3)*(1+$Y$6) -> 21.833043 | AF31: =(AJ31+AK31)*K29 -> 12.058092 | AI31: t18 | AJ31: =G29 -> 0.059484767 | AK31: =O29 -> 0.021074371 | AL31: =#REF! -> #REF! | AM31: =L29 -> 0.64728902 | AN31: =#REF! -> #REF!
A32: 21 | B32: P2 | C32: =$G$5 -> 0.024986 | D32: =$H$7 -> 0.000113 | E32: =$I$7 -> 0.065 | F32: 21 | G32: ='Precios Bolsa España 2024'!O24 -> 0.099023507 | H32: ='Precios Bolsa España 2024'!P24 -> 0.011415753 | I32: ='Precios Bolsa España 2024'!Q24 -> 0.0031109041 | J32: =(G32)*1000 -> 99.023507 | K32: =Industria!T23 -> 134.48767 | L32: =Industria!U23 -> 0.58159001 | M32: =Industria!V23 -> 40.603753 | N32: ='24h-ESPAÑA'!R32/'24h-ESPAÑA'!K32-'24h-ESPAÑA'!J32/1000 -> 0.050833548 | O32: =AVERAGE($N$31:$N$33) -> 0.051218244 | P32: =COS(ATAN(M32/K32)) -> 0.95732042 | Q32: =-K32*(AJ34+O32) -> -20.205663 | R32: =K32*(C32+(G32+H32+I32+D32+$Y$5+$Y$4)*(1+E32)+$Y$3)*(1+$Y$6) -> 20.153926 | AF32: =(AJ32+AK32)*K30 -> 21.518966 | AI32: t19 | AJ32: =G30 -> 0.076155178 | AK32: =O30 -> 0.072034485 | AL32: =#REF! -> #REF! | AM32: =L30 -> 0.62796864 | AN32: =#REF! -> #REF!
A33: 22 | B33: P2 | C33: =$G$5 -> 0.024986 | D33: =$H$7 -> 0.000113 | E33: =$I$7 -> 0.065 | F33: 22 | G33: ='Precios Bolsa España 2024'!O25 -> 0.09037211 | H33: ='Precios Bolsa España 2024'!P25 -> 0.01131526 | I33: ='Precios Bolsa España 2024'!Q25 -> 0.0030031507 | J33: =(G33)*1000 -> 90.37211 | K33: =Industria!T24 -> 41.442603 | L33: =Industria!U24 -> 0.17921794 | M33: =Industria!V24 -> 3.4742192 | N33: ='24h-ESPAÑA'!R33/'24h-ESPAÑA'!K33-'24h-ESPAÑA'!J33/1000 -> 0.049907892 | O33: =AVERAGE($N$31:$N$33) -> 0.051218244 | P33: =COS(ATAN(M33/K33)) -> 0.99650451 | Q33: =-K33*(AJ35+O33) -> -5.8678728 | R33: =K33*(C33+(G33+H33+I33+D33+$Y$5+$Y$4)*(1+E33)+$Y$3)*(1+$Y$6) -> 5.8135684 | AF33: =(AJ33+AK33)*K31 -> 21.574606 | AI33: t20 | AJ33: =G31 -> 0.090286438 | AK33: =O31 -> 0.051218244 | AL33: =#REF! -> #REF! | AM33: =L31 -> 0.65933562 | AN33: =#REF! -> #REF!
A34: 23 | B34: P5 | C34: =$G$8 -> 0.002388 | D34: =$H$8 -> 0.000113 | E34: =$I$8 -> 0.043 | F34: 23 | G34: ='Precios Bolsa España 2024'!O26 -> 0.081188795 | H34: ='Precios Bolsa España 2024'!P26 -> 0.012232575 | I34: ='Precios Bolsa España 2024'!Q26 -> 0.0028552603 | J34: =(G34)*1000 -> 81.188795 | K34: =Industria!T25 -> 33.502959 | L34: =Industria!U25 -> 0.14488307 | M34: =Industria!V25 -> 26.909671 | N34: ='24h-ESPAÑA'!R34/'24h-ESPAÑA'!K34-'24h-ESPAÑA'!J34/1000 -> 0.024893963 | O34: =AVERAGE($N$20,$N$26:$N$29,$N$34:$N$35) -> 0.021074371 | P34: =COS(ATAN(M34/K34)) -> 0.77964924 | Q34: =-K34*(AJ36+O34) -> -3.4261186 | R34: =K34*(C34+(G34+H34+I34+D34+$Y$5+$Y$4)*(1+E34)+$Y$3)*(1+$Y$6) -> 3.5540863 | AF34: =(AJ34+AK34)*K32 -> 20.205663 | AI34: t21 | AJ34: =G32 -> 0.099023507 | AK34: =O32 -> 0.051218244 | AL34: =#REF! -> #REF! | AM34: =L32 -> 0.58159001 | AN34: =#REF! -> #REF!
A35: 24 | B35: P5 | C35: =$G$8 -> 0.002388 | D35: =$H$8 -> 0.000113 | E35: =$I$8 -> 0.043 | F35: 24 | G35: ='Precios Bolsa España 2024'!O27 -> 0.074767233 | H35: ='Precios Bolsa España 2024'!P27 -> 0.0088425753 | I35: ='Precios Bolsa España 2024'!Q27 -> 0.0028075068 | J35: =(G35)*1000 -> 74.767233 | K35: =Industria!T26 -> 31.920795 | L35: =Industria!U26 -> 0.13804102 | M35: =Industria!V26 -> 27.457562 | N35: ='24h-ESPAÑA'!R35/'24h-ESPAÑA'!K35-'24h-ESPAÑA'!J35/1000 -> 0.02087801 | O35: =O27 -> 0.021074371 | P35: =COS(ATAN(M35/K35)) -> 0.75811852 | Q35: =-K35*(AJ37+O35) -> -3.0593402 | R35: =K35*(C35+(G35+H35+I35+D35+$Y$5+$Y$4)*(1+E35)+$Y$3)*(1+$Y$6) -> 3.0530722 | AF35: =(AJ35+AK35)*K33 -> 5.8678728 | AI35: t22 | AJ35: =G33 -> 0.09037211 | AK35: =O33 -> 0.051218244 | AL35: =#REF! -> #REF! | AM35: =L33 -> 0.17921794 | AN35: =#REF! -> #REF!
G36: =SUM(G12:G35)/24 -> 0.063200352 | H36: =SUM(H12:H35)/24 -> 0.0091568527 | I36: =SUM(I12:I35)/24 -> 0.00347779 | J36: =SUM(J12:J35)/24 -> 63.200352 | K36: =SUM(K12:K35) -> 2629.1417 | M36: =SUM(M12:M35) -> 1251.3968 | P36: =COS(ATAN(M36/K36)) -> 0.90293721 | Q36: =SUM(Q12:Q35) -> -225.71986 | R36: =SUM(R12:R35) -> 225.05107 | AF36: =(AJ36+AK36)*K34 -> 3.4261186 | AI36: t23 | AJ36: =G34 -> 0.081188795 | AK36: =O34 -> 0.021074371 | AL36: =#REF! -> #REF! | AM36: =L34 -> 0.14488307 | AN36: =#REF! -> #REF!
G37: Eur/kWh | H37: Eur/kWh | I37: Eur/kWh | J37: Eur/MWh | K37: kWh/dia | M37: kVArh/dia | Q37: Eur/dia | R37: Eur/dia | AF37: =(AJ37+AK37)*K35 -> 3.0593402 | AI37: t24 | AJ37: =G35 -> 0.074767233 | AK37: =O35 -> 0.021074371 | AL37: =#REF! -> #REF! | AM37: =L35 -> 0.13804102 | AN37: =#REF! -> #REF!
K38: =K36*365 -> 959636.71 | Q38: =Q36*365 -> -82387.749 | R38: =R36*365 -> 82143.642 | AF38: =SUM(AF14:AF37)*365 -> 82387.749
K39: kWh/año | Q39: kWh/año | R39: kWh/año
S40: Reactiva P1 | W40: Tarifa 6.1 TD | AE40: Segmento tarifario | AF40: Término de potencia de los cargos (€/kW año) | AM40: Grupo tarifario | AN40: Término de potencia del peaje de transporte y distribución (€/kW año) | AU40: Tarifa de acceso | AW40: Término de potencia (€/kW año)
...

Sheet Precios Bolsa Colombia 2024
A1: 2024 | B1: min | C1: max | D1: average | E1: 2024
A2: USD/KWh | B2: USD/COP | C2: USD/COP | D2: USD/COP | E2: Enero | F2: Febrero | G2: Marzo | H2: Abril | I2: Mayo | J2: Junio | K2: Julio | L2: Agosto | M2: Septiembre | N2: Octubre | O2: Noviembre | P2: Diciembre
A3: 0.15860415 | B3: 96.364056 | C3: 2674.6989 | D3: 634.41658 | E3: 550.99785 | F3: 533.19271 | G3: 623.63596 | H3: 688.24948 | I3: 231.30511 | J3: 217.97603 | K3: 234.73863 | L3: 512.65672 | M3: 856.5216 | N3: 1557.8168 | O3: 953.40495 | P3: 651.73014
A4: 0.12171982 | B4: 97.390224 | C4: 2674.6989 | D4: 486.87926 | E4: 545.85634 | F4: 517.29054 | G4: 617.65631 | H4: 677.37182 | I4: 224.82553 | J4: 218.8062 | K4: 240.70414 | L4: 521.58253 | M4: 853.28953 | N4: 1395.3863 | O4: 827.57621 | P4: 652.11121
A5: 0.11909825 | B5: 97.390224 | C5: 2498.8041 | D5: 476.39301 | E5: 537.88473 | F5: 507.22168 | G5: 598.13354 | H5: 639.36092 | I5: 224.22098 | J5: 212.8222 | K5: 229.76398 | L5: 502.9085 | M5: 849.23 | N5: 1267.8876 | O5: 735.57585 | P5: 640.77056
A6: 0.1160119 | B6: 97.346224 | C6: 2498.8041 | D6: 464.04759 | E6: 528.06482 | F6: 496.84799 | G6: 589.22709 | H6: 639.95235 | I6: 227.97614 | J6: 211.21223 | K6: 225.28811 | L6: 488.13466 | M6: 848.65066 | N6: 1208.4758 | O6: 728.78951 | P6: 635.85037
A7: 0.1184893 | B7: 97.390224 | C7: 2498.8041 | D7: 473.95719 | E7: 533.04885 | F7: 511.19702 | G7: 595.3786 | H7: 679.53755 | I7: 233.45872 | J7: 217.3942 | K7: 234.21463 | L7: 505.30085 | M7: 849.534 | N7: 1192.0089 | O7: 709.32471 | P7: 637.59898
A8: 0.12427995 | B8: 97.390224 | C8: 2498.8041 | D8: 497.1198 | E8: 540.76515 | F8: 557.87995 | G8: 599.40654 | H8: 697.56642 | I8: 247.14759 | J8: 224.1418 | K8: 244.38163 | L8: 531.00014 | M8: 861.87826 | N8: 1225.3316 | O8: 887.63125 | P8: 663.81585
A9: 0.12433783 | B9: 97.390224 | C9: 2498.8041 | D9: 497.35133 | E9: 539.00924 | F9: 548.10471 | G9: 587.72235 | H9: 690.52142 | I9: 243.0354 | J9: 226.1308 | K9: 245.6174 | L9: 533.81559 | M9: 853.2841 | N9: 1244.7784 | O9: 894.02175 | P9: 664.13888
A10: 0.13064242 | B10: 95.851608 | C10: 2498.8041 | D10: 522.5697 | E10: 534.05076 | F10: 560.52271 | G10: 588.42022 | H10: 700.47282 | I10: 249.73546 | J10: 245.4498 | K10: 249.43721 | L10: 536.41453 | M10: 849.22626 | N10: 1210.7548 | O10: 881.52688 | P10: 646.81198
A11: 0.13763512 | B11: 95.851608 | C11: 2498.8041 | D11: 550.54046 | E11: 543.02637 | F11: 568.59847 | G11: 593.23802 | H11: 705.93688 | I11: 252.82191 | J11: 253.1756 | K11: 255.74305 | L11: 540.46133 | M11: 849.09976 | N11: 1282.5107 | O11: 884.74758 | P11: 655.8275
A12: 0.14010958 | B12: 95.851608 | C12: 2498.8041 | D12: 560.43832 | E12: 542.84556 | F12: 567.41547 | G12: 587.04373 | H12: 717.76802 | I12: 252.69353 | J12: 256.25986 | K12: 258.75918 | L12: 543.52282 | M12: 853.75106 | N12: 1320.1857 | O12: 925.04005 | P12: 677.05011
A13: 0.14431613 | B13: 95.851608 | C13: 2498.8041 | D13: 577.26454 | E13: 549.39263 | F13: 570.14395 | G13: 602.18131 | H13: 739.58045 | I13: 257.27595 | J13: 262.92646 | K13: 268.20153 | L13: 554.20217 | M13: 865.45966 | N13: 1365.8243 | O13: 1050.88 | P13: 703.02711
A14: 0.14789205 | B14: 104.0472 | C14: 2674.6989 | D14: 591.56819 | E14: 559.73782 | F14: 580.00933 | G14: 622.8618 | H14: 754.74652 | I14: 282.08437 | J14: 284.10566 | K14: 285.48972 | L14: 571.01275 | M14: 878.42793 | N14: 1502.4866 | O14: 1093.1927 | P14: 752.86888
... A27: 0.14100992 | B27: 102.98494 | C27: 2608.9478 | D27: 564.03969 | E27: 558.7222 | F27: 568.70609 | G27: 622.77357 | H27: 748.65676 | I27: 291.54985 | J27: 280.69736 | K27: 285.09281 | L27: 567.41776 | M27: 873.70695 | N27: 1530.5736 | O27: 1047.1069 | P27: 741.76218
E28: =E27/$E$31 -> 0.13968055 | F28: =F27/$E$31 -> 0.14217652 | G28: =G27/$E$31 -> 0.15569339 | H28: =H27/$E$31 -> 0.18716419 | I28: =I27/$E$31 -> 0.072887463 | J28: =J27/$E$31 -> 0.070174341 | K28: =K27/$E$31 -> 0.071273203 | L28: =L27/$E$31 -> 0.14185444 | ... P28: =P27/$E$31 -> 0.18544054
A29: Precio de Escasez | C29: =937/E31 -> 0.23425 | D29: USD/kWh | E29: =IF(E28>$C$29,$C$29,E28) -> 0.13968055 | F29: =IF(F28>$C$29,$C$29,F28) -> 0.14217652 | G29: =IF(G28>$C$29,$C$29,G28) -> 0.15569339 | H29: =IF(H28>$C$29,$C$29,H28) -> 0.18716419 | I29: =IF(I28>$C$29,$C$29,I28) -> 0.072887463 | J29: =IF(J28>$C$29,$C$29,J28) -> 0.070174341 | K29: =IF(K28>$C$29,$C$29,K28) -> 0.071273203 | L29: =IF(L28>$C$29,$C$29,L28) -> 0.14185444 | ... P29: =IF(P28>$C$29,$C$29,P28) -> 0.18544054 | Q29: =AVERAGE(E29:P29) -> 0.15443928
Q30: =Q29*4000 -> 617.75713
A31: hora | B31: spot USD/kWh | C31: spot COP/kWh | D31: TRM | E31: 4000 | F31: COP/USD
A32: 1 | B32: =C32/$E$31 -> 0.062977902 | C32: 251.91161
A33: =A32+1 -> 2 | B33: =C33/$E$31 -> 0.062977902 | C33: 251.91161
A34: =A33+1 -> 3 | B34: =C34/$E$31 -> 0.062977902 | C34: 251.91161
A35: =A34+1 -> 4 | B35: =C35/$E$31 -> 0.070477902 | C35: 281.91161
A36: =A35+1 -> 5 | B36: =C36/$E$31 -> 0.070477902 | C36: 281.91161
A37: =A36+1 -> 6 | B37: =C37/$E$31 -> 0.062977902 | C37: 251.91161
A38: =A37+1 -> 7 | B38: =C38/$E$31 -> 0.038227902 | C38: 152.91161
A39: =A38+1 -> 8 | B39: =C39/$E$31 -> 0.023962902 | C39: 95.851608
A40: =A39+1 -> 9 | B40: =C40/$E$31 -> 0.023962902 | C40: 95.851608
A41: =A40+1 -> 10 | B41: =C41/$E$31 -> 0.023962902 | C41: 95.851608
A42: =A41+1 -> 11 | B42: =C42/$E$31 -> 0.023962902 | C42: 95.851608
A43: =A42+1 -> 12 | B43: =C43/$E$31 -> 0.038227902 | C43: 152.91161
A44: =A43+1 -> 13 | B44: =C44/$E$31 -> 0.038227902 | C44: 152.91161
... A8815: =A8814+1 -> 8784 | B8815: =C8815/$E$31 -> 0.029809363 | C8815: 119.23745

Sheet Tarifas Colombia 2024
B2: Costos U Aire-Barranquilla 2024
C3: Mes | P3: Promedio 2024
C4: 1 | D4: 2 | E4: 3 | F4: 4 | G4: 5 | H4: 6 | I4: 7 | J4: 8 | K4: 9 | L4: 10 | M4: 11 | N4: 12 | P4: COP/kWh | Q4: USD/kWh
B5: G | C5: 370.84 | D5: 373.83 | E5: 377.18 | F5: 451.5 | G5: 459.64 | H5: 411.59 | I5: 371.77 | J5: 338.3 | K5: 398.58 | L5: 394.86 | M5: 418.95 | N5: 402.69 | P5: =AVERAGE(C5:N5) -> 397.4775 | Q5: =P5/$C$29 -> 0.099369375
B6: T | C6: 54.32 | D6: 49.2 | E6: 57.43 | F6: 54.26 | G6: 47.96 | H6: 52.84 | I6: 55.93 | J6: 57.14 | K6: 48.55 | L6: 52.27 | M6: 55.37 | N6: 58.19 | P6: =AVERAGE(C6:N6) -> 53.621667 | Q6: =P6/$C$29 -> 0.013405417
B7: D-N1 | C7: 189.6 | D7: 196.69 | E7: 202.47 | F7: 160.93 | G7: 148.47 | H7: 133.25 | I7: 161.62 | J7: 148.28 | K7: 154.91 | L7: 160.55 | M7: 173.6 | N7: 178.7 | P7: =AVERAGE(C7:N7) -> 167.4225 | Q7: =P7/$C$29 -> 0.041855625
B8: PR-N1 | C8: 207.64 | D8: 206.21 | E8: 211.08 | F8: 123.15 | G8: 104.36 | H8: 114.19 | I8: 104.49 | J8: 98.52 | K8: 110.35 | L8: 110.29 | M8: 114.87 | N8: 111.2 | P8: =AVERAGE(C8:N8) -> 134.69583 | Q8: =P8/$C$29 -> 0.033673958
B9: Comerc N1 | C9: 330.47 | D9: 325.79 | E9: 354.03 | F9: 147.04 | G9: 139.18 | H9: 135.95 | I9: 128.91 | J9: 125.95 | K9: 128.92 | L9: 135.29 | M9: 138.95 | N9: 147.13 | P9: =AVERAGE(C9:N9) -> 186.4675 | Q9: =P9/$C$29 -> 0.046616875
B10: D-N2 | C10: 111.87 | D10: 114.69 | E10: 118.9 | F10: 110.83 | G10: 109.96 | H10: 86.35 | I10: 106.61 | J10: 98.94 | K10: 103.26 | L10: 107.82 | M10: 113 | N10: 119.74 | P10: =AVERAGE(C10:N10) -> 108.4975 | Q10: =P10/$C$29 -> 0.027124375
B11: PR-N2 | C11: 65.3 | D11: 62.35 | E11: 66.48 | F11: 50.79 | G11: 31.95 | H11: 47.76 | I11: 43.7 | J11: 42.22 | K11: 46.39 | L11: 46.3 | M11: 47.31 | N11: 46.6 | P11: =AVERAGE(C11:N11) -> 49.7625 | Q11: =P11/$C$29 -> 0.012440625
B12: Comerc Cvmj | C12: 137.38 | D12: 136.72 | E12: 145.76 | F12: 147.04 | G12: =G9 -> 139.18 | H12: =H9 -> 135.95 | I12: =I9 -> 128.91 | J12: =J9 -> 125.95 | K12: 116.12 | L12: 123.27 | M12: 125.65 | N12: 133.83 | P12: =AVERAGE(C12:N12) -> 132.98 | Q12: =P12/$C$29 -> 0.033245
B13: Restr | C13: 12.44 | D13: 13.21 | E13: 9.1 | F13: 9.06 | G13: 50.23 | H13: 33.78 | I13: 36.52 | J13: 39.09 | K13: 13.73 | L13: 1.57 | M13: 5.49 | N13: 8.3 | P13: =AVERAGE(C13:N13) -> 19.376667 | Q13: =P13/$C$29 -> 0.0048441667
B15: CU N1 | C15: =C5+C6+C7+C8+C13+C9 -> 1165.31 | D15: =D5+D6+D7+D8+D13+D9 -> 1164.93 | E15: =E5+E6+E7+E8+E13+E9 -> 1211.29 | F15: =F5+F6+F7+F8+F13+F9 -> 945.94 | G15: =G5+G6+G7+G8+G13+G9 -> 949.84 | H15: =H5+H6+H7+H8+H13+H9 -> 881.6 | I15: =I5+I6+I7+I8+I13+I9 -> 859.24 | J15: =J5+J6+J7+J8+J13+J9 -> 807.28 | ... N15: =N5+N6+N7+N8+N13+N9 -> 906.21 | P15: =AVERAGE(C15:N15) -> 959.06167 | Q15: =P15/$C$29 -> 0.23976542
B16: CU N2 | C16: =C5+C10+C11+C12+C13+C6 -> 752.15 | D16: =D5+D10+D11+D12+D13+D6 -> 750 | E16: =E5+E10+E11+E12+E13+E6 -> 774.85 | F16: =F5+F10+F11+F12+F13+F6 -> 823.48 | G16: =G5+G10+G11+G12+G13+G6 -> 838.92 | H16: =H5+H10+H11+H12+H13+H6 -> 768.27 | I16: =I5+I10+I11+I12+I13+I6 -> 743.44 | J16: =J5+J10+J11+J12+J13+J6 -> 701.64 | ... N16: =N5+N10+N11+N12+N13+N6 -> 769.35 | P16: =AVERAGE(C16:N16) -> 761.71583 | Q16: =P16/$C$29 -> 0.19042896
B18: CU N1 | C18: =C15/$C$29 -> 0.2913275 | D18: =D15/$C$29 -> 0.2912325 | E18: =E15/$C$29 -> 0.3028225 | F18: =F15/$C$29 -> 0.236485 | G18: =G15/$C$29 -> 0.23746 | H18: =H15/$C$29 -> 0.2204 | I18: =I15/$C$29 -> 0.21481 | J18: =J15/$C$29 -> 0.20182 | ... N18: =N15/$C$29 -> 0.2265525 | P18: =Q18*$C$29 -> 959.06167 | Q18: =AVERAGE(C18:N18) -> 0.23976542
B19: CU N2 | C19: =C16/$C$29 -> 0.1880375 | D19: =D16/$C$29 -> 0.1875 | E19: =E16/$C$29 -> 0.1937125 | F19: =F16/$C$29 -> 0.20587 | G19: =G16/$C$29 -> 0.20973 | H19: =H16/$C$29 -> 0.1920675 | I19: =I16/$C$29 -> 0.18586 | J19: =J16/$C$29 -> 0.17541 | ... N19: =N16/$C$29 -> 0.1923375 | P19: =Q19*$C$29 -> 761.71583 | Q19: =AVERAGE(C19:N19) -> 0.19042896
B21: CUpico N2 | C21: =C16/$C$26 -> 763.97241 | D21: =D16/$C$26 -> 761.78861 | E21: =E16/$C$26 -> 787.02921 | F21: =F16/$C$26 -> 836.42358 | G21: =G16/$C$26 -> 852.10627 | H21: =H16/$C$26 -> 780.34578 | I21: =I16/$C$26 -> 755.1255 | J21: =J16/$C$26 -> 712.66848 | ... N21: =N16/$C$26 -> 781.44276 | P21: =P16/$C$26 -> 773.6886 | Q21: =P21/$C$29 -> 0.19342215
B22: CUnopico N2 | C22: =C16/$C$27 -> 749.05931 | D22: =D16/$C$27 -> 746.91814 | E22: =E16/$C$27 -> 771.66603 | F22: =F16/$C$27 -> 820.0962 | G22: =G16/$C$27 -> 835.47276 | H22: =H16/$C$27 -> 765.11307 | I22: =I16/$C$27 -> 740.3851 | J22: =J16/$C$27 -> 698.75686 | ... N22: =N16/$C$27 -> 766.18863 | P22: =P16/$C$27 -> 758.58584 | Q22: =P22/$C$29 -> 0.18964646
B26: 5 | C26: 0.98452509 | P26: =(B26*P21+B27*P22)/24 -> 761.73224 | Q26: =P26/$C$29 -> 0.19043306
B27: 19 | C27: 1.0041261
B29: TRM 2024 | C29: 4000 | D29: COP/USD

Sheet Tarifas España 2024
AL7: Costes de Operación | AM7: =1/1000 -> 0.001 | AN7: Eur/kWh
AD8: fp>.95 | AE8: 0 | AF8: Eur/kVARh | AL8: Retribucion OM+OS | AM8: =0.20949/1000 -> 0.00020949 | AN8: Eur/kWh
AD9: .95<fp<.8 | AE9: 0.041554 | AF9: Eur/kVARh | AL9: Bono Social | AM9: =0.358725/1000 -> 0.000358725 | AN9: Eur/kWh
AD10: fp<.8 | AE10: 0.062332 | AF10: Eur/kVARh | AL10: Tasa Local | AM10: 0.015 | AN10: Eur/kWh
AC40: Segmento tarifario | AD40: Término de potencia de los cargos (€/kW año) | AK40: Grupo tarifario | AL40: Término de potencia del peaje de transporte y distribución (€/kW año) | AS40: Tarifa de acceso | AU40: Término de potencia (€/kW año)
AD41: Periodo 1 | AE41: Periodo 2 | AF41: Periodo 3 | AG41: Periodo 4 | AH41: Periodo 5 | AI41: Periodo 6 | AL41: Periodo 1 | AM41: Periodo 2 | AN41: Periodo 3 | AO41: Periodo 4 | AP41: Periodo 5 | AQ41: Periodo 6 | AU41: Periodo 1 | AV41: Periodo 2 | AW41: Periodo 3 | AX41: Periodo 4 | AY41: Periodo 5 | AZ41: Periodo 6
AC42: 2.0 TD | AD42: 3.971618 | AE42: 0.255423 | AK42: 2.0 TD | AL42: 22.958932 | AM42: 0.442165 | AR42: 1 | AS42: 2.0 TD | AT42: Baja tensión < 15 kW | AU42: =AD42+AL42 -> 26.93055 | AV42: =AE42+AM42 -> 0.697588
AC43: 3.0 TD | AD43: 4.935064 | AE43: 2.469687 | AF43: 1.794284 | AG43: 1.794284 | AH43: 1.794284 | AI43: 0.822511 | AK43: 3.0 TD | AL43: 14.723431 | AM43: 7.781964 | AN43: 2.468252 | AO43: 1.887267 | AP43: 0.533883 | AQ43: 0.533883 | AR43: 2 | AS43: 3.0 TD | AT43: Baja tensión > 15 kW | AU43: =AD43+AL43 -> 19.658495 | AV43: =AE43+AM43 -> 10.251651 | AW43: =AF43+AN43 -> 4.262536 | AX43: =AG43+AO43 -> 3.681551 | AY43: =AH43+AP43 -> 2.328167 | AZ43: =AI43+AQ43 -> 1.356394
AC44: 6.1 TD | AD44: 5.122811 | AE44: 2.563728 | AF44: 1.86284 | AG44: 1.86284 | AH44: 1.86284 | AI44: 0.853802 | AK44: 6.1 TD | AL44: 23.669055 | AM44: 12.513915 | AN44: 4.69633 | AO44: 3.309245 | AP44: 0.069965 | AQ44: 0.062286 | AR44: 3 | AS44: 6.1 TD | AT44: 1 kV > U > 30 kV | AU44: =AD44+AL44 -> 28.791866 | AV44: =AE44+AM44 -> 15.077643 | AW44: =AF44+AN44 -> 6.55917 | AX44: =AG44+AO44 -> 5.172085 | AY44: =AH44+AP44 -> 1.932805 | AZ44: =AI44+AQ44 -> 0.916088
AC45: 6.2 TD | AD45: 3.008289 | AE45: 1.505746 | AF45: 1.093923 | AG45: 1.093923 | AH45: 1.093923 | AI45: 0.501382 | AK45: 6.2 TD | AL45: 16.620368 | AM45: 9.426053 | AN45: 2.481516 | AO45: 1.512028 | AP45: 0.059278 | AQ45: 0.052654 | AR45: 4 | AS45: 6.2 TD | AT45: 30 kV > U > 72 kV | AU45: =AD45+AL45 -> 19.628657 | AV45: =AE45+AM45 -> 10.931799 | AW45: =AF45+AN45 -> 3.575439 | AX45: =AG45+AO45 -> 2.605951 | AY45: =AH45+AP45 -> 1.153201 | AZ45: =AI45+AQ45 -> 0.554036
AC46: 6.3 TD | AD46: 2.408681 | AE46: 1.205367 | AF46: 0.875748 | AG46: 0.875748 | AH46: 0.875748 | AI46: 0.401447 | AK46: 6.3 TD | AL46: 10.791377 | AM46: 6.502236 | AN46: 2.118318 | AO46: 1.380541 | AP46: 0.045332 | AQ46: 0.039905 | AR46: 5 | AS46: 6.3 TD | AT46: 72 kV > U > 145 kV | AU46: =AD46+AL46 -> 13.200058 | AV46: =AE46+AM46 -> 7.707603 | AW46: =AF46+AN46 -> 2.994066 | AX46: =AG46+AO46 -> 2.256289 | AY46: =AH46+AP46 -> 0.92108 | AZ46: =AI46+AQ46 -> 0.441352
AC47: 6.4 TD | AD47: 1.178247 | AE47: 0.589615 | AF47: 0.428453 | AG47: 0.428453 | AH47: 0.428453 | AI47: 0.196374 | AK47: 6.4 TD | AL47: 6.590215 | AM47: 3.93998 | AN47: 0.956817 | AO47: 0.665081 | AP47: 0.019779 | AQ47: 0.013181 | AR47: 6 | AS47: 6.4 TD | AT47: U > 145 kV | AU47: =AD47+AL47 -> 7.768462 | AV47: =AE47+AM47 -> 4.529595 | AW47: =AF47+AN47 -> 1.38527 | AX47: =AG47+AO47 -> 1.093534 | AY47: =AH47+AP47 -> 0.448232 | AZ47: =AI47+AQ47 -> 0.209555
AC49: Segmento tarifario | AD49: Término de energía de los cargos (€/kWh) | AK49: Grupo tarifario | AL49: Término de energía del peaje de transporte y distribución (€/kWh) | AS49: Tarifa de acceso | AU49: Término de energía (€/kWh)
AD50: Periodo 1 | AE50: Periodo 2 | AF50: Periodo 3 | AG50: Periodo 4 | AH50: Periodo 5 | AI50: Periodo 6 | AL50: Periodo 1 | AM50: Periodo 2 | AN50: Periodo 3 | AO50: Periodo 4 | AP50: Periodo 5 | AQ50: Periodo 6 | AU50: Periodo 1 | AV50: Periodo 2 | AW50: Periodo 3 | AX50: Periodo 4 | AY50: Periodo 5 | AZ50: Periodo 6
AC51: 2.0 TD | AD51: 0.058305 | AE51: 0.011661 | AF51: 0.002915 | AK51: 2.0 TD | AL51: 0.034234 | AM51: 0.01654 | AN51: 7.9e-05 | AR51: 1 | AS51: 2.0 TD | AT51: Baja tensión < 15 kW | AU51: =AD51+AL51 -> 0.092539 | AV51: =AE51+AM51 -> 0.028201 | AW51: =AF51+AN51 -> 0.002994
AC52: 3.0 TD | AD52: 0.032503 | AE52: 0.024066 | AF52: 0.013001 | AG52: 0.006501 | AH52: 0.004167 | AI52: 0.0026 | AK52: 3.0 TD | AL52: 0.028528 | AM52: 0.012343 | AN52: 0.004673 | AO52: 0.002682 | AP52: 0.000119 | AQ52: 3.1e-05 | AR52: 2 | AS52: 3.0 TD | AT52: Baja tensión > 15 kW | AU52: =AD52+AL52 -> 0.061031 | AV52: =AE52+AM52 -> 0.036409 | AW52: =AF52+AN52 -> 0.017674 | AX52: =AG52+AO52 -> 0.009183 | AY52: =AH52+AP52 -> 0.004286 | AZ52: =AI52+AQ52 -> 0.002631
AC53: 6.1 TD | AD53: 0.017674 | AE53: 0.013092 | AF53: 0.007069 | AG53: 0.003535 | AH53: 0.002266 | AI53: 0.001414 | AK53: 6.1 TD | AL53: 0.027104 | AM53: 0.011894 | AN53: 0.004726 | AO53: 0.002739 | AP53: 0.000122 | AQ53: 2.9e-05 | AR53: 3 | AS53: 6.1 TD | AT53: 1 kV > U > 30 kV | AU53: =AD53+AL53 -> 0.044778 | AV53: =AE53+AM53 -> 0.024986 | AW53: =AF53+AN53 -> 0.011795 | AX53: =AG53+AO53 -> 0.006274 | AY53: =AH53+AP53 -> 0.002388 | AZ53: =AI53+AQ53 -> 0.001443
AC54: 6.2 TD | AD54: 0.008293 | AE54: 0.006142 | AF54: 0.003317 | AG54: 0.001659 | AH54: 0.001063 | AI54: 0.000663 | AK54: 6.2 TD | AL54: 0.01477 | AM54: 0.00684 | AN54: 0.002279 | AO54: 0.001219 | AP54: 6.3e-05 | AQ54: 2e-05 | AR54: 4 | AS54: 6.2 TD | AT54: 30 kV > U > 72 kV | AU54: =AD54+AL54 -> 0.023063 | AV54: =AE54+AM54 -> 0.012982 | AW54: =AF54+AN54 -> 0.005596 | AX54: =AG54+AO54 -> 0.002878 | AY54: =AH54+AP54 -> 0.001126 | AZ54: =AI54+AQ54 -> 0.000683
AC55: 6.3 TD | AD55: 0.006798 | AE55: 0.005035 | AF55: 0.002719 | AG55: 0.00136 | AH55: 0.000871 | AI55: 0.000544 | AK55: 6.3 TD | AL55: 0.012294 | AM55: 0.00547 | AN55: 0.001931 | AO55: 0.001063 | AP55: 5.5e-05 | AQ55: 1.5e-05 | AR55: 5 | AS55: 6.3 TD | AT55: 72 kV > U > 145 kV | AU55: =AD55+AL55 -> 0.019092 | AV55: =AE55+AM55 -> 0.010505 | AW55: =AF55+AN55 -> 0.00465 | AX55: =AG55+AO55 -> 0.002423 | AY55: =AH55+AP55 -> 0.000926 | AZ55: =AI55+AQ55 -> 0.000559
AC56: 6.4 TD | AD56: 0.002582 | AE56: 0.001913 | AF56: 0.001033 | AG56: 0.000516 | AH56: 0.000331 | AI56: 0.000207 | AK56: 6.4 TD | AL56: 0.007944 | AM56: 0.003569 | AN56: 0.001288 | AO56: 0.000681 | AP56: 3.6e-05 | AQ56: 4e-06 | AR56: 6 | AS56: 6.4 TD | AT56: U > 145 kV | AU56: =AD56+AL56 -> 0.010526 | AV56: =AE56+AM56 -> 0.005482 | AW56: =AF56+AN56 -> 0.002321 | AX56: =AG56+AO56 -> 0.001197 | AY56: =AH56+AP56 -> 0.000367 | AZ56: =AI56+AQ56 -> 0.000211 | BS56: 31
BS57: 28
AC58: Segmento tarifario | AD58: Pagos de capacidad (€/kWh) | BS58: 31
AD59: Periodo 1 | AE59: Periodo 2 | AF59: Periodo 3 | AG59: Periodo 4 | AH59: Periodo 5 | AI59: Periodo 6
AC60: 2.0 TD | AD60: 0.000844 | AE60: 0.00014
AC61: 3.0 TD | AD61: 0.001141 | AE61: 0.000527 | AF61: 0.000351 | AG61: 0.000264 | AH61: 0.000264 | AI61: 0
AC62: 6.1 TD | AD62: 0.00049 | AE62: 0.000225 | AF62: 0.00015 | AG62: 0.000113 | AH62: 0.000113 | AI62: 0
AC63: 6.2 TD | AD63: 0.00049 | AE63: 0.000225 | AF63: 0.00015 | AG63: 0.000113 | AH63: 0.000113 | AI63: 0
AC64: 6.3 TD | AD64: 0.00049 | AE64: 0.000225 | AF64: 0.00015 | AG64: 0.000113 | AH64: 0.000113 | AI64: 0
AC65: 6.4 TD | AD65: 0.00049 | AE65: 0.000225 | AF65: 0.00015 | AG65: 0.000113 | AH65: 0.000113 | AI65: 0
AC67: Segmento tarifario | AD67: Coeficientes estándar de pérdidas
AD68: Periodo 1 | AE68: Periodo 2 | AF68: Periodo 3 | AG68: Periodo 4 | AH68: Periodo 5 | AI68: Periodo 6
AC69: 2.0 TD | AD69: 0.167 | AE69: 0.163 | AF69: 0.18
C70: https://www.boe.es/diario_boe/txt.php?id=BOE-A-2024-26218 | AC70: 3.0 TD | AD70: 0.166 | AE70: 0.175 | AF70: 0.165 | AG70: 0.165 | AH70: 0.138 | AI70: 0.18
Q71: =SUM(Q59:Q70) -> 0 | AC71: 6.1 TD | AD71: 0.067 | AE71: 0.068 | AF71: 0.065 | AG71: 0.065 | AH71: 0.043 | AI71: 0.077
AC72: 6.2 TD | AD72: 0.052 | AE72: 0.054 | AF72: 0.049 | AG72: 0.05 | AH72: 0.035 | AI72: 0.054
AC73: 6.3 TD | AD73: 0.042 | AE73: 0.043 | AF73: 0.04 | AG73: 0.04 | AH73: 0.03 | AI73: 0.044
AC74: 6.4 TD | AD74: 0.016 | AE74: 0.016 | AF74: 0.016 | AG74: 0.016 | AH74: 0.015 | AI74: 0.017

Sheet Precios Bolsa España 2024
A1: % | B1: Mercado diario €/MWh | C1: Restricciones €/MWh | D1: Procesos OS €/MWh | E1: horames | F1: mes | G1: horadia | H1: DIA
A2: DBL=[ | B2: 63.33 | C2: 14.29 | D2: 1.49 | E2: 1 | F2: 1 | G2: 1 | H2: 1 | I2: ;
B3: 50.09 | C3: 15.23 | D3: 5.71 | E3: =E2+1 -> 2 | F3: =F2 -> 1 | G3: 2 | H3: 1 | I3: ; | K3: DIAS | L3: HORAS | M3: MES | O3: Spot | P3: Restricciones | Q3: Porcesos OS | R3: Total | S3: Restricciones Y Procesos OS
B4: 47.5 | C4: 16.75 | D4: 2.51 | E4: =E3+1 -> 3 | F4: =F3 -> 1 | G4: 3 | H4: 1 | I4: ; | J4: ENERO | K4: 31 | L4: =K4*24 -> 744 | M4: 1 | N4: 0 | O4: 0.068746795 | P4: 0.0072543014 | Q4: 0.0025313699 | R4: =O4+P4+Q4 -> 0.078532466 | S4: =P4+Q4 -> 0.0097856712
B5: 43.5 | C5: 18.29 | D5: 2.94 | E5: =E4+1 -> 4 | F5: =F4 -> 1 | G5: 4 | H5: 1 | I5: ; | J5: FEBRERO | K5: 28 | L5: =K5*24 -> 672 | M5: 2 | N5: 1 | O5: 0.064382932 | P5: 0.0081311507 | Q5: 0.0027362192 | R5: =O5+P5+Q5 -> 0.075250301 | S5: =P5+Q5 -> 0.01086737
B6: 42.5 | C6: 19.81 | D6: 2.8 | E6: =E5+1 -> 5 | F6: =F5 -> 1 | G6: 5 | H6: 1 | I6: ; | J6: MARZO | K6: 31 | L6: =K6*24 -> 744 | M6: 3 | N6: 2 | O6: 0.062238411 | P6: 0.0092259726 | Q6: 0.002448137 | R6: =O6+P6+Q6 -> 0.073912521 | S6: =P6+Q6 -> 0.01167411
B7: 42.09 | C7: 20.84 | D7: 3.44 | E7: =E6+1 -> 6 | F7: =F6 -> 1 | G7: 6 | H7: 1 | I7: ; | J7: ABRIL | K7: 30 | L7: =K7*24 -> 720 | M7: 4 | N7: 3 | O7: 0.060464137 | P7: 0.0097246575 | Q7: 0.0022396712 | R7: =O7+P7+Q7 -> 0.072428466 | S7: =P7+Q7 -> 0.011964329
B8: 42.5 | C8: 20.02 | D8: 4.02 | E8: =E7+1 -> 7 | F8: =F7 -> 1 | G8: 7 | H8: 1 | I8: ; | J8: MAYO | K8: 31 | L8: =K8*24 -> 744 | M8: 5 | N8: 4 | O8: 0.060655534 | P8: 0.0098196438 | Q8: 0.0022953699 | R8: =O8+P8+Q8 -> 0.072770548 | S8: =P8+Q8 -> 0.012115014
B9: 42.59 | C9: 18.67 | D9: 3.32 | E9: =E8+1 -> 8 | F9: =F8 -> 1 | G9: 8 | H9: 1 | I9: ; | J9: JUNIO | K9: 30 | L9: =K9*24 -> 720 | M9: 6 | N9: 5 | O9: 0.065132137 | P9: 0.010057589 | Q9: 0.0025469041 | R9: =O9+P9+Q9 -> 0.07773663 | S9: =P9+Q9 -> 0.012604493
B10: 43.37 | C10: 18.12 | D10: 2.79 | E10: =E9+1 -> 9 | F10: =F9 -> 1 | G10: 9 | H10: 1 | I10: ; | J10: JULIO | K10: 31 | L10: =K10*24 -> 744 | M10: 7 | N10: 6 | O10: 0.073826082 | P10: 0.0099409041 | Q10: 0.0041280822 | R10: =O10+P10+Q10 -> 0.087895068 | S10: =P10+Q10 -> 0.014068986
B11: 42.29 | C11: 17.85 | D11: 3.43 | E11: =E10+1 -> 10 | F11: =F10 -> 1 | G11: 10 | H11: 1 | I11: ; | J11: AGOSTO | K11: 31 | L11: =K11*24 -> 744 | M11: 8 | N11: 7 | O11: 0.076148795 | P11: 0.010411233 | Q11: 0.0055221918 | R11: =O11+P11+Q11 -> 0.092082219 | S11: =P11+Q11 -> 0.015933425
B12: 25 | C12: 13.52 | D12: 3.28 | E12: =E11+1 -> 11 | F12: =F11 -> 1 | G12: 11 | H12: 1 | I12: ; | J12: SEPTIEMBRE | K12: 30 | L12: =K12*24 -> 720 | M12: 9 | N12: 8 | O12: 0.069382712 | P12: 0.0094291507 | Q12: 0.0059585753 | R12: =O12+P12+Q12 -> 0.084770438 | S12: =P12+Q12 -> 0.015387726
B13: 3.9 | C13: 13.03 | D13: 2.63 | E13: =E12+1 -> 12 | F13: =F12 -> 1 | G13: 12 | H13: 1 | I13: ; | J13: OCTUBRE | K13: 31 | L13: =K13*24 -> 744 | M13: 10 | N13: 9 | O13: 0.056760082 | P13: 0.0080707671 | Q13: 0.0045372055 | R13: =O13+P13+Q13 -> 0.069368055 | S13: =P13+Q13 -> 0.012607973
B14: 3.2 | C14: 12.82 | D14: 1.92 | E14: =E13+1 -> 13 | F14: =F13 -> 1 | G14: 13 | H14: 1 | I14: ; | J14: NOVIEMBRE | K14: 30 | L14: =K14*24 -> 720 | M14: 11 | N14: 10 | O14: 0.04694937 | P14: 0.0071172055 | Q14: 0.0031848219 | R14: =O14+P14+Q14 -> 0.057251397 | S14: =P14+Q14 -> 0.010302027
B15: 2.06 | C15: 12.63 | D15: 1.89 | E15: =E14+1 -> 14 | F15: =F14 -> 1 | G15: 14 | H15: 1 | I15: ; | J15: DICIEMBRE | K15: 31 | L15: =K15*24 -> 744 | M15: 12 | N15: 11 | O15: 0.04184674 | P15: 0.0070680548 | Q15: 0.0025854521 | R15: =O15+P15+Q15 -> 0.051500247 | S15: =P15+Q15 -> 0.0096535068
B16: 1.73 | C16: 12.66 | D16: 2.41 | E16: =E15+1 -> 15 | F16: =F15 -> 1 | G16: 15 | H16: 1 | I16: ; | N16: 12 | O16: 0.039593726 | P16: 0.0070899726 | Q16: 0.002544274 | R16: =O16+P16+Q16 -> 0.049227973 | S16: =P16+Q16 -> 0.0096342466
B17: 5.72 | C17: 13.07 | D17: 2.92 | E17: =E16+1 -> 16 | F17: =F16 -> 1 | G17: 16 | H17: 1 | I17: ; | N17: 13 | O17: 0.037885123 | P17: 0.0075278082 | Q17: 0.0024952877 | R17: =O17+P17+Q17 -> 0.047908219 | S17: =P17+Q17 -> 0.010023096
B18: 18.49 | C18: 12.17 | D18: 5.19 | E18: =E17+1 -> 17 | F18: =F17 -> 1 | G18: 17 | H18: 1 | I18: ; | N18: 14 | O18: 0.036840932 | P18: 0.0075245753 | Q18: 0.0024581096 | R18: =O18+P18+Q18 -> 0.046823616 | S18: =P18+Q18 -> 0.0099826849
B19: 37 | C19: 10.28 | D19: 7.56 | E19: =E18+1 -> 18 | F19: =F18 -> 1 | G19: 18 | H19: 1 | I19: ; | N19: 15 | O19: 0.038253699 | P19: 0.0076432329 | Q19: 0.0030550685 | R19: =O19+P19+Q19 -> 0.048952 | S19: =P19+Q19 -> 0.010698301
B20: 47.5 | C20: 9.21 | D20: 2.84 | E20: =E19+1 -> 19 | F20: =F19 -> 1 | G20: 19 | H20: 1 | I20: ; | N20: 16 | O20: 0.046423205 | P20: 0.0078807123 | Q20: 0.0042375616 | R20: =O20+P20+Q20 -> 0.058541479 | S20: =P20+Q20 -> 0.012118274
B21: 54.97 | C21: 5.77 | D21: 2.6 | E21: =E20+1 -> 20 | F21: =F20 -> 1 | G21: 20 | H21: 1 | I21: ; | N21: 17 | O21: 0.059484767 | P21: 0.008736274 | Q21: 0.0056707671 | R21: =O21+P21+Q21 -> 0.073891808 | S21: =P21+Q21 -> 0.014407041
B22: 60.9 | C22: 5.27 | D22: 2.03 | E22: =E21+1 -> 21 | F22: =F21 -> 1 | G22: 21 | H22: 1 | I22: ; | N22: 18 | O22: 0.076155178 | P22: 0.010724877 | Q22: 0.0059901918 | R22: =O22+P22+Q22 -> 0.092870247 | S22: =P22+Q22 -> 0.016715068
B23: 60 | C23: 5.29 | D23: 3.17 | E23: =E22+1 -> 22 | F23: =F22 -> 1 | G23: 22 | H23: 1 | I23: ; | N23: 19 | O23: 0.090286438 | P23: 0.012580219 | Q23: 0.0045248767 | R23: =O23+P23+Q23 -> 0.10739153 | S23: =P23+Q23 -> 0.017105096
B24: 47.5 | C24: 4.52 | D24: 3.21 | E24: =E23+1 -> 23 | F24: =F23 -> 1 | G24: 23 | H24: 1 | I24: ; | N24: 20 | O24: 0.099023507 | P24: 0.011415753 | Q24: 0.0031109041 | R24: =O24+P24+Q24 -> 0.11355016 | S24: =P24+Q24 -> 0.014526658
B25: 42.09 | C25: 4.65 | D25: 2.82 | E25: =E24+1 -> 24 | F25: =F24 -> 1 | G25: 24 | H25: 1 | I25: ; | N25: 21 | O25: 0.09037211 | P25: 0.01131526 | Q25: 0.0030031507 | R25: =O25+P25+Q25 -> 0.10469052 | S25: =P25+Q25 -> 0.014318411
B26: 37.8 | C26: 12.13 | D26: 1.61 | E26: =E25+1 -> 25 | F26: =F25 -> 1 | G26: =G2 -> 1 | H26: =H2+1 -> 2 | I26: ; | N26: 22 | O26: 0.081188795 | P26: 0.012232575 | Q26: 0.0028552603 | R26: =O26+P26+Q26 -> 0.09627663 | S26: =P26+Q26 -> 0.015087836
B27: 25 | C27: 14.71 | D27: 3.79 | E27: =E26+1 -> 26 | F27: =F26 -> 1 | G27: =G3 -> 2 | H27: =H3+1 -> 2 | I27: ; | N27: 23 | O27: 0.074767233 | P27: 0.0088425753 | Q27: 0.0028075068 | R27: =O27+P27+Q27 -> 0.086417315 | S27: =P27+Q27 -> 0.011650082
B28: 3.99 | C28: 16.71 | D28: 4.71 | E28: =E27+1 -> 27 | F28: =F27 -> 1 | G28: =G4 -> 3 | H28: =H4+1 -> 2 | I28: ;
B29: 14 | C29: 16.68 | D29: 3.28 | E29: =E28+1 -> 28 | F29: =F28 -> 1 | G29: =G5 -> 4 | H29: =H5+1 -> 2 | I29: ;
B30: 10 | C30: 17 | D30: 5.39 | E30: =E29+1 -> 29 | F30: =F29 -> 1 | G30: =G6 -> 5 | H30: =H6+1 -> 2 | I30: ;
B31: 14.54 | C31: 16.05 | D31: 5.57 | E31: =E30+1 -> 30 | F31: =F30 -> 1 | G31: =G7 -> 6 | H31: =H7+1 -> 2 | I31: ;
B32: 36.29 | C32: 12.09 | D32: 4.28 | E32: =E31+1 -> 31 | F32: =F31 -> 1 | G32: =G8 -> 7 | H32: =H8+1 -> 2 | I32: ;
B33: 44.7 | C33: 8.64 | D33: 3.52 | E33: =E32+1 -> 32 | F33: =F32 -> 1 | G33: =G9 -> 8 | H33: =H9+1 -> 2 | I33: ;
B34: 53.78 | C34: 6.23 | D34: 2.84 | E34: =E33+1 -> 33 | F34: =F33 -> 1 | G34: =G10 -> 9 | H34: =H10+1 -> 2 | I34: ;
B35: 54.23 | C35: 4.62 | D35: 2.76 | E35: =E34+1 -> 34 | F35: =F34 -> 1 | G35: =G11 -> 10 | H35: =H11+1 -> 2 | I35: ;
B36: 50 | C36: 4.16 | D36: 2.28 | E36: =E35+1 -> 35 | F36: =F35 -> 1 | G36: =G12 -> 11 | H36: =H12+1 -> 2 | I36: ;
B37: 52.2 | C37: 4.37 | D37: 2.28 | E37: =E36+1 -> 36 | F37: =F36 -> 1 | G37: =G13 -> 12 | H37: =H13+1 -> 2 | I37: ;
B38: 45 | C38: 4.62 | D38: 3.34 | E38: =E37+1 -> 37 | F38: =F37 -> 1 | G38: =G14 -> 13 | H38: =H14+1 -> 2 | I38: ;
B39: 43 | C39: 4.3 | D39: 3.76 | E39: =E38+1 -> 38 | F39: =F38 -> 1 | G39: =G15 -> 14 | H39: =H15+1 -> 2 | I39: ;
... B745: 77.52 | C745: 3.34 | D745: 4.19 | E745: =E744+1 -> 744 | F745: =F744 -> 1 | G745: =G721 -> 24 | H745: =H721+1 -> 31 | I745: ;
...

Sheet Industria
A1: % | B1: Periodo | C1: P KW | D1: Q kVARr | E1: horames | F1: mes | G1: horadia | H1: DIA | T1: P | V1: ©
A2: DBP=[ | B2: 6 | C2: 13.72 | D2: 14.25 | E2: 1 | F2: 1 | G2: 1 | H2: 1 | I2: ; | T2: kWh | U2: Fc | V2: kVArh
B3: 6 | C3: 14.3 | D3: 16.48 | E3: =E2+1 -> 2 | F3: =F2 -> 1 | G3: 2 | H3: 1 | I3: ; | S3: 0 | T3: =$Q$17*U3 -> 31.307452 | U3: 0.13538863 | V3: 27.875151
B4: 6 | C4: 13.76 | D4: 16.03 | E4: =E3+1 -> 3 | F4: =F3 -> 1 | G4: 3 | H4: 1 | I4: ; | S4: 1 | T4: =$Q$17*U4 -> 20.898959 | U4: 0.090377249 | V4: 22.371534
B5: 6 | C5: 14.47 | D5: 17.56 | E5: =E4+1 -> 4 | F5: =F4 -> 1 | G5: 4 | H5: 1 | I5: ; | S5: 2 | T5: =$Q$17*U5 -> 17.653808 | U5: 0.076343641 | V5: 20.669616
B6: 6 | C6: 13.89 | D6: 16.24 | E6: =E5+1 -> 5 | F6: =F5 -> 1 | G6: 5 | H6: 1 | I6: ; | S6: 3 | T6: =$Q$17*U6 -> 17.394959 | U6: 0.075224251 | V6: 20.802712
